# Ancient Warfare Structure Template File
# Auto-generated structure template file. created on: 5/24/2026 at: 23:7:24
# Lines beginning with # denote comments

header:
version=2.11
name=portal_test
mods=
size=34,77,34
offset=16,70,16
:endheader

#### VALIDATION ####
validation:
type=ground
structureAuthor=
survival=false
worldGenEnabled=false
unique=false
preserveBlocks=false
preventNaturalHostileSpawns=false
selectionWeight=1
clusterValue=1
minDuplicateDistance=1
dimensionWhiteList=true
dimensionList=
biomeGroupList=
biomeWhiteList=true
biomeList=
leveling=0
fill=0
border=0
blockSwap=false
territoryName=
biomeReplacement=minecraft:
minGenerationHeight=0
maxGenerationHeight=255
:endvalidation

#### LAYERS ####
layer: 0
0,2,2,5,6,5,0,2,1,4,2,2,2,2,0,0,2,2,2,2,2,0,0,0,0,2,0,5,6,5,2,2,0,1
0,2,5,6,6,6,5,0,2,2,2,2,2,5,5,5,5,5,5,5,0,0,0,0,0,0,5,6,6,6,5,2,2,2
0,5,6,6,6,6,6,5,2,0,5,5,5,6,6,6,6,6,6,6,5,5,5,0,0,5,6,6,6,6,6,5,2,2
5,6,6,6,6,6,6,6,5,5,6,6,6,6,6,6,6,6,6,6,6,6,6,5,5,6,6,6,6,6,6,6,5,2
6,6,6,6,6,6,6,6,6,6,6,6,6,6,6,6,6,6,6,6,6,6,6,6,6,6,6,6,6,6,6,6,6,3
5,6,6,6,6,6,6,6,6,6,6,6,6,6,6,6,6,6,6,6,6,6,6,6,6,6,6,6,6,6,6,6,5,0
0,5,6,6,6,6,6,6,6,6,6,6,6,6,6,6,6,6,6,6,6,6,6,6,6,6,6,6,6,6,6,5,0,2
0,0,5,6,6,6,6,6,6,6,6,6,6,6,6,6,6,6,6,6,6,6,6,6,6,6,6,6,6,6,5,2,2,2
0,0,0,5,6,6,6,6,6,6,6,6,6,6,6,6,6,6,6,6,6,6,6,6,6,6,6,6,6,5,2,2,2,2
0,0,0,5,6,6,6,6,6,6,6,6,6,6,6,6,6,6,6,6,6,6,6,6,6,6,6,6,6,5,2,0,0,0
0,0,5,6,6,6,6,6,6,6,6,6,6,6,6,6,6,6,6,6,6,6,6,6,6,6,6,6,6,6,5,0,2,2
0,0,5,6,6,6,6,6,6,6,6,6,6,6,6,6,6,6,6,6,6,6,6,6,6,6,6,6,6,6,5,0,2,1
0,0,5,6,6,6,6,6,6,6,6,6,6,6,6,6,6,6,6,6,6,6,6,6,6,6,6,6,6,6,5,2,2,1
0,5,6,6,6,6,6,6,6,6,6,6,6,6,6,6,6,6,6,6,6,6,6,6,6,6,6,6,6,6,6,5,0,0
0,5,6,6,6,6,6,6,6,6,6,6,6,6,6,6,6,6,6,6,6,6,6,6,6,6,6,6,6,6,6,5,2,0
0,5,6,6,6,6,6,6,6,6,6,6,6,6,6,6,6,6,6,6,6,6,6,6,6,6,6,6,6,6,6,5,0,0
0,5,6,6,6,6,6,6,6,6,6,6,6,6,6,6,6,6,6,6,6,6,6,6,6,6,6,6,6,6,6,5,2,3
0,5,6,6,6,6,6,6,6,6,6,6,6,6,6,6,6,6,6,6,6,6,6,6,6,6,6,6,6,6,6,5,2,2
0,5,6,6,6,6,6,6,6,6,6,6,6,6,6,6,6,6,6,6,6,6,6,6,6,6,6,6,6,6,6,5,0,4
0,5,6,6,6,6,6,6,6,6,6,6,6,6,6,6,6,6,6,6,6,6,6,6,6,6,6,6,6,6,6,5,2,2
0,0,5,6,6,6,6,6,6,6,6,6,6,6,6,6,6,6,6,6,6,6,6,6,6,6,6,6,6,6,5,2,2,2
2,0,5,6,6,6,6,6,6,6,6,6,6,6,6,6,6,6,6,6,6,6,6,6,6,6,6,6,6,6,5,2,1,2
0,0,5,6,6,6,6,6,6,6,6,6,6,6,6,6,6,6,6,6,6,6,6,6,6,6,6,6,6,6,5,2,2,2
0,0,0,5,6,6,6,6,6,6,6,6,6,6,6,6,6,6,6,6,6,6,6,6,6,6,6,6,6,5,0,0,2,0
2,0,0,5,6,6,6,6,6,6,6,6,6,6,6,6,6,6,6,6,6,6,6,6,6,6,6,6,6,5,2,1,2,2
0,1,5,6,6,6,6,6,6,6,6,6,6,6,6,6,6,6,6,6,6,6,6,6,6,6,6,6,6,6,5,2,0,2
0,5,6,6,6,6,6,6,6,6,6,6,6,6,6,6,6,6,6,6,6,6,6,6,6,6,6,6,6,6,6,5,0,2
5,6,6,6,6,6,6,6,6,6,6,6,6,6,6,6,6,6,6,6,6,6,6,6,6,6,6,6,6,6,6,6,5,0
6,6,6,6,6,6,6,6,6,6,6,6,6,6,6,6,6,6,6,6,6,6,6,6,6,6,6,6,6,6,6,6,6,3
5,6,6,6,6,6,6,6,5,5,6,6,6,6,6,6,6,6,6,6,6,6,6,5,5,6,6,6,6,6,6,6,5,0
0,5,6,6,6,6,6,5,0,0,5,5,5,6,6,6,6,6,6,6,5,5,5,0,1,5,6,6,6,6,6,5,2,2
0,0,5,6,6,6,5,0,0,2,0,0,0,5,5,5,5,5,5,5,2,2,2,2,0,0,5,6,6,6,5,2,2,2
2,0,0,5,6,5,0,0,2,1,2,2,2,0,1,2,2,4,2,2,2,2,2,4,2,0,0,5,6,5,0,2,2,2
1,0,2,2,3,0,2,2,2,2,4,2,2,2,2,4,2,2,2,2,1,2,2,0,0,0,0,0,3,2,0,2,2,2
:endlayer
layer: 1
0,0,0,5,6,5,0,0,0,7,0,0,0,0,0,0,0,0,0,0,0,0,0,0,0,0,0,5,6,5,0,0,0,0
0,0,5,6,6,6,5,0,0,0,0,0,0,5,5,5,5,5,5,5,0,0,0,0,0,0,5,6,6,6,5,0,0,0
0,5,6,6,6,6,6,5,0,0,5,5,5,6,6,6,6,6,6,6,5,5,5,0,0,5,6,6,6,6,6,5,0,0
5,6,6,6,6,6,6,6,5,5,6,6,6,6,6,6,6,6,6,6,6,6,6,5,5,6,6,6,6,6,6,6,5,0
6,6,6,6,6,6,6,6,6,6,6,6,6,6,6,6,6,6,6,6,6,6,6,6,6,6,6,6,6,6,6,6,6,3
5,6,6,6,6,6,6,6,6,6,6,6,6,6,6,6,6,6,6,6,6,6,6,6,6,6,6,6,6,6,6,6,5,0
0,5,6,6,6,6,6,6,6,6,6,6,6,6,6,6,6,6,6,6,6,6,6,6,6,6,6,6,6,6,6,5,0,0
0,0,5,6,6,6,6,6,6,6,6,6,6,6,6,6,6,6,6,6,6,6,6,6,6,6,6,6,6,6,5,0,0,0
0,0,0,5,6,6,6,6,6,6,6,6,6,6,6,6,6,6,6,6,6,6,6,6,6,6,6,6,6,5,0,0,0,0
0,0,0,5,6,6,6,6,6,6,6,6,6,6,6,6,6,6,6,6,6,6,6,6,6,6,6,6,6,5,0,0,0,0
0,0,5,6,6,6,6,6,6,6,6,6,6,6,6,6,6,6,6,6,6,6,6,6,6,6,6,6,6,6,5,0,0,0
0,0,5,6,6,6,6,6,6,6,6,6,6,6,6,6,6,6,6,6,6,6,6,6,6,6,6,6,6,6,5,0,0,0
0,0,5,6,6,6,6,6,6,6,6,6,6,6,6,6,6,6,6,6,6,6,6,6,6,6,6,6,6,6,5,0,0,0
0,5,6,6,6,6,6,6,6,6,6,6,6,6,6,6,6,6,6,6,6,6,6,6,6,6,6,6,6,6,6,5,0,0
0,5,6,6,6,6,6,6,6,6,6,6,6,6,6,6,6,6,6,6,6,6,6,6,6,6,6,6,6,6,6,5,0,0
0,5,6,6,6,6,6,6,6,6,6,6,6,6,6,6,6,6,6,6,6,6,6,6,6,6,6,6,6,6,6,5,0,0
0,5,6,6,6,6,6,6,6,6,6,6,6,6,6,6,6,6,6,6,6,6,6,6,6,6,6,6,6,6,6,5,0,3
0,5,6,6,6,6,6,6,6,6,6,6,6,6,6,6,6,6,6,6,6,6,6,6,6,6,6,6,6,6,6,5,0,0
0,5,6,6,6,6,6,6,6,6,6,6,6,6,6,6,6,6,6,6,6,6,6,6,6,6,6,6,6,6,6,5,0,7
0,5,6,6,6,6,6,6,6,6,6,6,6,6,6,6,6,6,6,6,6,6,6,6,6,6,6,6,6,6,6,5,0,0
0,0,5,6,6,6,6,6,6,6,6,6,6,6,6,6,6,6,6,6,6,6,6,6,6,6,6,6,6,6,5,0,0,0
0,0,5,6,6,6,6,6,6,6,6,6,6,6,6,6,6,6,6,6,6,6,6,6,6,6,6,6,6,6,5,0,0,0
0,0,5,6,6,6,6,6,6,6,6,6,6,6,6,6,6,6,6,6,6,6,6,6,6,6,6,6,6,6,5,0,0,0
0,0,0,5,6,6,6,6,6,6,6,6,6,6,6,6,6,6,6,6,6,6,6,6,6,6,6,6,6,5,0,0,0,0
0,0,0,5,6,6,6,6,6,6,6,6,6,6,6,6,6,6,6,6,6,6,6,6,6,6,6,6,6,5,0,0,0,0
0,0,5,6,6,6,6,6,6,6,6,6,6,6,6,6,6,6,6,6,6,6,6,6,6,6,6,6,6,6,5,0,0,0
0,5,6,6,6,6,6,6,6,6,6,6,6,6,6,6,6,6,6,6,6,6,6,6,6,6,6,6,6,6,6,5,0,0
5,6,6,6,6,6,6,6,6,6,6,6,6,6,6,6,6,6,6,6,6,6,6,6,6,6,6,6,6,6,6,6,5,0
6,6,6,6,6,6,6,6,6,6,6,6,6,6,6,6,6,6,6,6,6,6,6,6,6,6,6,6,6,6,6,6,6,3
5,6,6,6,6,6,6,6,5,5,6,6,6,6,6,6,6,6,6,6,0,6,6,5,5,6,6,6,6,6,6,6,5,0
0,5,6,6,6,6,6,5,0,0,5,5,5,6,6,6,6,6,6,6,0,0,5,0,0,5,6,6,6,6,6,5,0,0
0,0,5,6,6,6,5,0,0,0,0,0,0,5,5,5,5,5,5,5,0,0,0,0,0,0,5,6,6,6,5,0,0,0
0,0,0,5,6,5,0,0,0,0,0,0,0,0,0,0,0,7,0,0,0,0,0,7,0,0,0,5,6,5,0,0,0,0
0,0,0,0,3,0,0,0,0,0,7,0,0,0,0,7,0,0,0,0,0,0,0,0,0,0,0,0,3,0,0,0,0,0
:endlayer
layer: 2
0,0,0,5,6,5,0,0,0,0,0,0,0,0,0,0,0,0,0,0,0,0,0,0,0,0,0,5,6,5,0,0,0,0
0,0,5,6,6,6,5,0,0,0,0,0,0,5,5,5,5,5,5,5,0,0,0,0,0,0,5,6,6,6,5,0,0,0
0,5,6,6,6,6,6,5,0,0,5,5,5,6,6,6,6,6,6,6,5,5,5,0,0,5,6,6,6,6,6,5,0,0
5,6,6,6,6,6,6,6,5,5,6,6,6,6,6,6,6,6,6,6,6,6,6,5,5,6,6,6,6,6,6,6,5,0
6,6,6,6,6,6,6,6,6,6,6,6,6,6,6,6,6,6,6,6,6,6,6,6,6,6,6,6,6,6,6,6,6,3
5,6,6,6,6,6,6,6,6,6,6,6,6,6,6,6,6,6,6,6,6,6,6,6,6,6,6,6,6,6,6,6,5,0
0,5,6,6,6,6,6,6,6,6,6,6,6,6,6,6,6,6,6,6,6,6,6,6,6,6,6,6,6,6,6,5,0,0
0,0,5,6,6,6,6,6,6,6,6,6,6,6,6,6,6,6,6,6,6,6,6,6,6,6,6,6,6,6,5,0,0,0
0,0,0,5,6,6,6,6,6,6,6,6,6,6,6,6,6,6,6,6,6,6,6,6,6,6,6,6,6,5,0,0,0,0
0,0,0,5,6,6,6,6,6,6,6,6,6,6,6,6,6,6,6,6,6,6,6,6,6,6,6,6,6,5,0,0,0,0
0,0,5,6,6,6,6,6,6,6,6,6,6,6,6,6,6,6,6,6,6,6,6,6,6,6,6,6,6,6,5,0,0,0
0,0,5,6,6,6,6,6,6,6,6,6,6,6,6,6,6,6,6,6,6,6,6,6,6,6,6,6,6,6,5,0,0,0
0,0,5,6,6,6,6,6,6,6,6,6,6,6,6,6,6,6,6,6,6,6,6,6,6,6,6,6,6,6,5,0,0,0
0,5,6,6,6,6,6,6,6,6,6,6,6,6,6,6,6,6,6,6,6,6,6,6,6,6,6,6,6,6,6,5,0,0
0,5,6,6,6,6,6,6,6,6,6,6,6,6,6,6,6,6,6,6,6,6,6,6,6,6,6,6,6,6,6,5,0,0
0,5,6,6,6,6,6,6,6,6,6,6,6,6,6,6,6,6,6,6,6,6,6,6,6,6,6,6,6,6,6,5,0,0
0,5,6,6,6,6,6,6,6,6,6,6,6,6,6,6,6,6,6,6,6,6,6,6,6,6,6,6,6,6,6,5,0,3
0,5,6,6,6,6,6,6,6,6,6,6,6,6,6,6,6,6,6,6,6,6,6,6,6,6,6,6,6,6,6,5,0,0
0,5,6,6,6,6,6,6,6,6,6,6,6,6,6,6,6,6,6,6,6,6,6,6,6,6,6,6,6,6,6,5,0,0
0,5,6,6,6,6,6,6,6,6,6,6,6,6,6,6,6,6,6,6,6,6,6,6,6,6,6,6,6,6,6,5,0,0
0,0,5,6,6,6,6,6,6,6,6,6,6,6,6,6,6,6,6,6,6,6,6,6,6,6,6,6,6,6,5,0,0,0
0,0,5,6,6,6,6,6,6,6,6,6,6,6,6,6,6,6,6,6,6,6,6,6,6,6,6,6,6,6,5,0,0,0
0,0,5,6,6,6,6,6,6,6,6,6,6,6,6,6,6,6,6,6,6,6,6,6,6,6,6,6,6,6,5,0,0,0
0,0,0,5,6,6,6,6,6,6,6,6,6,6,6,6,6,6,6,6,6,6,6,6,6,6,6,6,6,5,0,0,0,0
0,0,0,5,6,6,6,6,6,6,6,6,6,6,6,6,6,6,6,6,6,6,6,6,6,6,6,6,6,5,0,0,0,0
0,0,5,6,6,6,6,6,6,6,6,6,6,6,6,6,6,6,6,6,6,6,6,6,6,6,6,6,6,6,5,0,0,0
0,5,6,6,6,6,6,6,6,6,6,6,6,6,6,6,6,6,6,6,6,6,6,6,6,6,6,6,6,6,6,5,0,0
5,6,6,6,6,6,6,6,6,6,6,6,6,6,6,6,6,6,6,6,6,6,6,6,6,6,6,6,6,6,6,6,5,0
6,6,6,6,6,6,6,6,6,6,6,6,6,6,6,6,6,6,6,6,6,6,6,6,6,6,6,6,6,6,6,6,6,3
5,6,6,6,6,6,6,6,5,5,6,6,6,6,6,6,6,6,6,6,0,6,6,5,5,6,6,6,6,6,6,6,5,0
0,5,6,6,6,6,6,5,0,0,5,5,5,6,6,6,6,6,6,6,0,0,5,0,0,5,6,6,6,6,6,5,0,0
0,0,5,6,6,6,5,0,0,0,0,0,0,5,5,5,5,5,5,5,0,0,0,0,0,0,5,6,6,6,5,0,0,0
0,0,0,5,6,5,0,0,0,0,0,0,0,0,0,0,0,0,0,0,0,0,0,0,0,0,0,5,6,5,0,0,0,0
0,0,0,0,3,0,0,0,0,0,0,0,0,0,0,0,0,0,0,0,0,0,0,0,0,0,0,0,3,0,0,0,0,0
:endlayer
layer: 3
0,0,0,5,6,5,0,0,0,0,0,0,0,0,0,0,0,0,0,0,0,0,0,0,0,0,0,5,6,5,0,0,0,0
0,0,5,6,6,6,5,0,0,0,0,0,0,5,5,5,5,5,5,5,0,0,0,0,0,0,5,6,6,6,5,0,0,0
0,5,6,6,6,6,6,5,0,0,5,5,5,6,6,6,6,6,6,6,5,5,5,0,0,5,6,6,6,6,6,5,0,0
5,6,6,6,6,6,6,6,5,5,6,6,6,6,6,6,6,6,6,6,6,6,6,5,5,6,6,6,6,6,6,6,5,0
6,6,6,6,6,6,6,6,6,6,6,6,6,6,6,6,6,6,6,6,6,6,6,6,6,6,6,6,6,6,6,6,6,3
5,6,6,6,6,6,6,6,6,6,6,6,6,6,6,6,6,6,6,6,6,6,6,6,6,6,6,6,6,6,6,6,5,0
0,5,6,6,6,6,6,6,6,6,6,6,6,6,6,6,6,6,6,6,6,6,6,6,6,6,6,6,6,6,6,5,0,0
0,0,5,6,6,6,6,6,6,6,6,6,6,6,6,6,6,6,6,6,6,6,6,6,6,6,6,6,6,6,5,0,0,0
0,0,0,5,6,6,6,6,6,6,6,6,6,6,6,6,6,6,6,6,6,6,6,6,6,6,6,6,6,5,0,0,0,0
0,0,0,5,6,6,6,6,6,6,6,6,6,6,6,6,6,6,6,6,6,6,6,6,6,6,6,6,6,5,0,0,0,0
0,0,5,6,6,6,6,6,6,6,6,6,6,6,6,6,6,6,6,6,6,6,6,6,6,6,6,6,6,6,5,0,0,0
0,0,5,6,6,6,6,6,6,6,6,6,6,6,6,6,6,6,6,6,6,6,6,6,6,6,6,6,6,6,5,0,0,0
0,0,5,6,6,6,6,6,6,6,6,6,6,6,6,6,6,6,6,6,6,6,6,6,6,6,6,6,6,6,5,0,0,0
0,5,6,6,6,6,6,6,6,6,6,6,6,6,6,6,6,6,6,6,6,6,6,6,6,6,6,6,6,6,6,5,0,0
0,5,6,6,6,6,6,6,6,6,6,6,6,6,6,6,6,6,6,6,6,6,6,6,6,6,6,6,6,6,6,5,0,0
0,5,6,6,6,6,6,6,6,6,6,6,6,6,6,6,6,6,6,6,6,6,6,6,6,6,6,6,6,6,6,5,0,0
0,5,6,6,6,6,6,6,6,6,6,6,6,6,6,6,6,6,6,6,6,6,6,6,6,6,6,6,6,6,6,5,0,3
0,5,6,6,6,6,6,6,6,6,6,6,6,6,6,6,6,6,6,6,6,6,6,6,6,6,6,6,6,6,6,5,0,0
0,5,6,6,6,6,6,6,6,6,6,6,6,6,6,6,6,6,6,6,6,6,6,6,6,6,6,6,6,6,6,5,0,0
0,5,6,6,6,6,6,6,6,6,6,6,6,6,6,6,6,6,6,6,6,6,6,6,6,6,6,6,6,6,6,5,0,0
0,0,5,6,6,6,6,6,6,6,6,6,6,6,6,6,6,6,6,6,6,6,6,6,6,6,6,6,6,6,5,0,0,0
0,0,5,6,6,6,6,6,6,6,6,6,6,6,6,6,6,6,6,6,6,6,6,6,6,6,6,6,6,6,5,0,0,0
0,0,5,6,6,6,6,6,6,6,6,6,6,6,6,6,6,6,6,6,6,6,6,6,6,6,6,6,6,6,5,0,0,0
0,0,0,5,6,6,6,6,6,6,6,6,6,6,6,6,6,6,6,6,6,6,6,6,6,6,6,6,6,5,0,0,0,0
0,0,0,5,6,6,6,6,6,6,6,6,6,6,6,6,6,6,6,6,6,6,6,6,6,6,6,6,6,5,0,0,0,0
0,0,5,6,6,6,6,6,6,6,6,6,6,6,6,6,6,6,6,6,6,6,6,6,6,6,6,6,6,6,5,0,0,0
0,5,6,6,6,6,6,6,6,6,6,6,6,6,6,6,6,6,6,6,6,6,6,6,6,6,6,6,6,6,6,5,0,0
5,6,6,6,6,6,6,6,6,6,6,6,6,6,6,6,6,6,6,6,6,6,6,6,6,6,6,6,6,6,6,6,5,0
6,6,6,6,6,6,6,6,6,6,6,6,6,6,6,6,6,6,6,6,6,6,6,6,6,6,6,6,6,6,6,6,6,3
5,6,6,6,6,6,6,6,5,5,6,6,6,6,6,6,6,6,6,6,6,6,6,5,5,6,6,6,6,6,6,6,5,0
0,5,6,6,6,6,6,5,0,0,5,5,5,6,6,6,6,6,6,6,5,5,5,0,0,5,6,6,6,6,6,5,0,0
0,0,5,6,6,6,5,0,0,0,0,0,0,5,5,5,5,5,5,5,0,0,0,0,0,0,5,6,6,6,5,0,0,0
0,0,0,5,6,5,0,0,0,0,0,0,0,0,0,0,0,0,0,0,0,0,0,0,0,0,0,5,6,5,0,0,0,0
0,0,0,0,3,0,0,0,0,0,0,0,0,0,0,0,0,0,0,0,0,0,0,0,0,0,0,0,3,0,0,0,0,0
:endlayer
layer: 4
0,0,0,5,6,5,0,0,0,0,0,0,0,0,0,0,0,0,0,0,0,0,0,0,0,0,0,5,6,5,0,0,0,0
0,0,5,6,6,6,5,0,0,0,0,0,0,5,5,5,5,5,5,5,0,0,0,0,0,0,5,6,6,6,5,0,0,0
0,5,6,6,6,6,6,5,0,0,5,5,5,6,6,6,6,6,6,6,5,5,5,0,0,5,6,6,6,6,6,5,0,0
5,6,6,6,6,6,6,6,5,5,6,6,6,6,6,6,6,6,6,6,6,6,6,5,5,6,6,6,6,6,6,6,5,0
6,6,6,6,6,6,6,6,6,6,6,6,6,6,6,6,6,6,6,6,6,6,6,6,6,6,6,6,6,6,6,6,6,3
5,6,6,6,6,6,6,6,6,6,6,6,6,6,6,6,6,6,6,6,6,6,6,6,6,6,6,6,6,6,6,6,5,0
0,5,6,6,6,6,6,6,6,6,6,6,6,6,6,6,6,6,6,6,6,6,6,6,6,6,6,6,6,6,6,5,0,0
0,0,5,6,6,6,6,6,6,6,6,6,6,6,6,6,6,6,6,6,6,6,6,6,6,6,6,6,6,6,5,0,0,0
0,0,0,5,6,6,6,6,6,6,6,6,6,6,6,6,6,6,6,6,6,6,6,6,6,6,6,6,6,5,0,0,0,0
0,0,0,5,6,6,6,6,6,6,6,6,6,6,6,6,6,6,6,6,6,6,6,6,6,6,6,6,6,5,0,0,0,0
0,0,5,6,6,6,6,6,6,6,6,6,6,6,6,6,6,6,6,6,6,6,6,6,6,6,6,6,6,6,5,0,0,0
0,0,5,6,6,6,6,6,6,6,6,6,6,6,6,6,6,6,6,6,6,6,6,6,6,6,6,6,6,6,5,0,0,0
0,0,5,6,6,6,6,6,6,6,6,6,6,6,6,6,6,6,6,6,6,6,6,6,6,6,6,6,6,6,5,0,0,0
0,5,6,6,6,6,6,6,6,6,6,6,6,6,6,6,6,6,6,6,6,6,6,6,6,6,6,6,6,6,6,5,0,0
0,5,6,6,6,6,6,6,6,6,6,6,6,6,6,6,6,6,6,6,6,6,6,6,6,6,6,6,6,6,6,5,0,0
0,5,6,6,6,6,6,6,6,6,6,6,6,6,6,6,6,6,6,6,6,6,6,6,6,6,6,6,6,6,6,5,0,0
0,5,6,6,6,6,6,6,6,6,6,6,6,6,6,6,6,6,6,6,6,6,6,6,6,6,6,6,6,6,6,5,0,3
0,5,6,6,6,6,6,6,6,6,6,6,6,6,6,6,6,6,6,6,6,6,6,6,6,6,6,6,6,6,6,5,0,0
0,5,6,6,6,6,6,6,6,6,6,6,6,6,6,6,6,6,6,6,6,6,6,6,6,6,6,6,6,6,6,5,0,0
0,5,6,6,6,6,6,6,6,6,6,6,6,6,6,6,6,6,6,6,6,6,6,6,6,6,6,6,6,6,6,5,0,0
0,0,5,6,6,6,6,6,6,6,6,6,6,6,6,6,6,6,6,6,6,6,6,6,6,6,6,6,6,6,5,0,0,0
0,0,5,6,6,6,6,6,6,6,6,6,6,6,6,6,6,6,6,6,6,6,6,6,6,6,6,6,6,6,5,0,0,0
0,0,5,6,6,6,6,6,6,6,6,6,6,6,6,6,6,6,6,6,6,6,6,6,6,6,6,6,6,6,5,0,0,0
0,0,0,5,6,6,6,6,6,6,6,6,6,6,6,6,6,6,6,6,6,6,6,6,6,6,6,6,6,5,0,0,0,0
0,0,0,5,6,6,6,6,6,6,6,6,6,6,6,6,6,6,6,6,6,6,6,6,6,6,6,6,6,5,0,0,0,0
0,0,5,6,6,6,6,6,6,6,6,6,6,6,6,6,6,6,6,6,6,6,6,6,6,6,6,6,6,6,5,0,0,0
0,5,6,6,6,6,6,6,6,6,6,6,6,6,6,6,6,6,6,6,6,6,6,6,6,6,6,6,6,6,6,5,0,0
5,6,6,6,6,6,6,6,6,6,6,6,6,6,6,6,6,6,6,6,6,6,6,6,6,6,6,6,6,6,6,6,5,0
6,6,6,6,6,6,6,6,6,6,6,6,6,6,6,6,6,6,6,6,6,6,6,6,6,6,6,6,6,6,6,6,6,3
5,6,6,6,6,6,6,6,5,5,6,6,6,6,6,6,6,6,6,6,6,6,6,5,5,6,6,6,6,6,6,6,5,0
0,5,6,6,6,6,6,5,0,0,5,5,5,6,6,6,6,6,6,6,5,5,5,0,0,5,6,6,6,6,6,5,0,0
0,0,5,6,6,6,5,0,0,0,0,0,0,5,5,5,5,5,5,5,0,0,0,0,0,0,5,6,6,6,5,0,0,0
0,0,0,5,6,5,0,0,0,0,0,0,0,0,0,0,0,0,0,0,0,0,0,0,0,0,0,5,6,5,0,0,0,0
0,0,0,0,3,0,0,0,0,0,0,0,0,0,0,0,0,8,0,0,0,0,0,0,0,0,0,0,3,0,0,0,0,0
:endlayer
layer: 5
0,0,0,5,6,5,0,0,0,0,0,0,0,0,0,0,0,0,0,0,0,0,0,0,0,0,0,5,6,5,0,0,0,0
0,0,5,6,6,6,5,0,0,0,0,0,0,5,5,5,5,5,5,5,0,0,0,0,0,0,5,6,6,6,5,0,0,0
0,5,6,6,6,6,6,5,0,0,5,5,5,6,6,6,6,6,6,6,5,5,5,0,0,5,6,6,6,6,6,5,0,0
5,6,6,6,6,6,6,6,5,5,6,6,6,6,6,6,6,6,6,6,6,6,6,5,5,6,6,6,6,6,6,6,5,0
6,6,6,6,6,6,6,6,6,6,6,6,6,6,6,6,6,6,6,6,6,6,6,6,6,6,6,6,6,6,6,6,6,3
5,6,6,6,6,6,6,6,6,6,6,6,6,6,6,6,6,6,6,6,6,6,6,6,6,6,6,6,6,6,6,6,5,0
0,5,6,6,6,6,6,6,6,6,6,6,6,6,6,6,6,6,6,6,6,6,6,6,6,6,6,6,6,6,6,5,0,0
0,0,5,6,6,6,6,6,6,6,6,6,6,6,6,6,6,6,6,6,6,6,6,6,6,6,6,6,6,6,5,0,0,0
0,0,0,5,6,6,6,6,6,6,6,6,6,6,6,6,6,6,6,6,6,6,6,6,6,6,6,6,6,5,0,0,0,0
0,0,0,5,6,6,6,6,6,6,6,6,6,6,6,6,6,6,6,6,6,6,6,6,6,6,6,6,6,5,0,0,0,0
0,0,5,6,6,6,6,6,6,6,6,6,6,6,6,6,6,6,6,6,6,6,6,6,6,6,6,6,6,6,5,0,0,0
0,0,5,6,6,6,6,6,6,6,6,6,6,6,6,6,6,6,6,6,6,6,6,6,6,6,6,6,6,6,5,0,0,0
0,0,5,6,6,6,6,6,6,6,6,6,6,6,6,6,6,6,6,6,6,6,6,6,6,6,6,6,6,6,5,0,0,0
0,5,6,6,6,6,6,6,6,6,6,6,6,6,6,6,6,6,6,6,6,6,6,6,6,6,6,6,6,6,6,5,0,0
0,5,6,6,6,6,6,6,6,6,6,6,6,6,6,6,6,6,6,6,6,6,6,6,6,6,6,6,6,6,6,5,0,0
0,5,6,6,6,6,6,6,6,6,6,6,6,6,6,6,6,6,6,6,6,6,6,6,6,6,6,6,6,6,6,5,0,0
0,5,6,6,6,6,6,6,6,6,6,6,6,6,6,6,6,6,6,6,6,6,6,6,6,6,6,6,6,6,6,5,0,3
0,5,6,6,6,6,6,6,6,6,6,6,6,6,6,6,6,6,6,6,6,6,6,6,6,6,6,6,6,6,6,5,0,0
0,5,6,6,6,6,6,6,6,6,6,6,6,6,6,6,6,6,6,6,6,6,6,6,6,6,6,6,6,6,6,5,0,0
0,5,6,6,6,6,6,6,6,6,6,6,6,6,6,6,6,6,6,6,6,6,6,6,6,6,6,6,6,6,6,5,0,0
0,0,5,6,6,6,6,6,6,6,6,6,6,6,6,6,6,6,6,6,6,6,6,6,6,6,6,6,6,6,5,0,0,0
0,0,5,6,6,6,6,6,6,6,6,6,6,6,6,6,6,6,6,6,6,6,6,6,6,6,6,6,6,6,5,0,0,0
0,0,5,6,6,6,6,6,6,6,6,6,6,6,6,6,6,6,6,6,6,6,6,6,6,6,6,6,6,6,5,0,0,0
0,0,0,5,6,6,6,6,6,6,6,6,6,6,6,6,6,6,6,6,6,6,6,6,6,6,6,6,6,5,0,0,0,0
0,0,0,5,6,6,6,6,6,6,6,6,6,6,6,6,6,6,6,6,6,6,6,6,6,6,6,6,6,5,0,0,0,0
0,0,5,6,6,6,6,6,6,6,6,6,6,6,6,6,6,6,6,6,6,6,6,6,6,6,6,6,6,6,5,0,0,0
0,5,6,6,6,6,6,6,6,6,6,6,6,6,6,6,6,6,6,6,6,6,6,6,6,6,6,6,6,6,6,5,0,0
5,6,6,6,6,6,6,6,6,6,6,6,6,6,6,6,6,6,6,6,6,6,6,6,6,6,6,6,6,6,6,6,5,0
6,6,6,6,6,6,6,6,6,6,6,6,6,6,6,6,6,6,6,6,6,6,6,6,6,6,6,6,6,6,6,6,6,3
5,6,6,6,6,6,6,6,5,5,6,6,6,6,6,6,6,6,6,6,6,6,6,5,5,6,6,6,6,6,6,6,5,0
0,5,6,6,6,6,6,5,0,0,5,5,5,6,6,6,6,6,6,6,5,5,5,0,0,5,6,6,6,6,6,5,0,0
0,0,5,6,6,6,5,0,0,0,0,0,0,5,5,5,5,5,5,5,0,0,0,0,0,0,5,6,6,6,5,0,0,0
0,0,0,5,6,5,0,0,0,0,0,0,0,0,0,0,0,0,0,0,0,0,0,0,0,0,0,5,6,5,0,0,0,0
0,0,0,0,3,0,0,0,0,0,0,0,0,0,8,9,9,0,0,0,0,0,0,0,0,0,0,0,3,0,0,0,0,0
:endlayer
layer: 6
0,0,0,5,6,5,0,0,0,0,0,0,0,0,0,0,0,0,0,0,0,0,0,0,0,0,0,5,6,5,0,0,0,0
0,0,5,6,6,6,5,0,0,0,0,0,0,5,5,5,5,5,5,5,0,0,0,0,0,0,5,6,6,6,5,0,0,0
0,5,6,6,6,6,6,5,0,0,5,5,5,6,6,6,6,6,6,6,5,5,5,0,0,5,6,6,6,6,6,5,0,0
5,6,6,6,6,6,6,6,5,5,6,6,6,6,6,6,6,6,6,6,6,6,6,5,5,6,6,6,6,6,6,6,5,0
6,6,6,6,6,6,6,6,6,6,6,6,6,6,6,6,6,6,6,6,6,6,6,6,6,6,6,6,6,6,6,6,6,3
5,6,6,6,6,6,6,6,6,6,6,6,6,6,6,6,6,6,6,6,6,6,6,6,6,6,6,6,6,6,6,6,5,0
0,5,6,6,6,6,6,6,6,6,6,6,6,6,6,6,6,6,6,6,6,6,6,6,6,6,6,6,6,6,6,5,0,0
0,0,5,6,6,6,6,6,6,6,6,6,6,6,6,6,6,6,6,6,6,6,6,6,6,6,6,6,6,6,5,0,0,0
0,0,0,5,6,6,6,6,6,6,6,6,6,6,6,6,6,6,6,6,6,6,6,6,6,6,6,6,6,5,0,0,0,0
0,0,0,5,6,6,6,6,6,6,6,6,6,6,6,6,6,6,6,6,6,6,6,6,6,6,6,6,6,5,0,0,0,0
0,0,5,6,6,6,6,6,6,6,6,6,6,6,6,6,6,6,6,6,6,6,6,6,6,6,6,6,6,6,5,0,0,0
0,0,5,6,6,6,6,6,6,6,6,6,6,6,6,6,6,6,6,6,6,6,6,6,6,6,6,6,6,6,5,0,0,0
0,0,5,6,6,6,6,6,6,6,6,6,6,6,6,6,6,6,6,6,6,6,6,6,6,6,6,6,6,6,5,0,0,0
0,5,6,6,6,6,6,6,6,6,6,6,6,6,6,6,6,6,6,6,6,6,6,6,6,6,6,6,6,6,6,5,0,0
0,5,6,6,6,6,6,6,6,6,6,6,6,6,6,6,6,6,6,6,6,6,6,6,6,6,6,6,6,6,6,5,0,0
0,5,6,6,6,6,6,6,6,6,6,6,6,6,6,6,6,6,6,6,6,6,6,6,6,6,6,6,6,6,6,5,0,0
0,5,6,6,6,6,6,6,6,6,6,6,6,6,6,6,6,6,6,6,6,6,6,6,6,6,6,6,6,6,6,5,0,3
0,5,6,6,6,6,6,6,6,6,6,6,6,6,6,6,6,6,6,6,6,6,6,6,6,6,6,6,6,6,6,5,0,0
0,5,6,6,6,6,6,6,6,6,6,6,6,6,6,6,6,6,6,6,6,6,6,6,6,6,6,6,6,6,6,5,0,0
0,5,6,6,6,6,6,6,6,6,6,6,6,6,6,6,6,6,6,6,6,6,6,6,6,6,6,6,6,6,6,5,0,0
0,0,5,6,6,6,6,6,6,6,6,6,6,6,6,6,6,6,6,6,6,6,6,6,6,6,6,6,6,6,5,0,0,0
0,0,5,6,6,6,6,6,6,6,6,6,6,6,6,6,6,6,6,6,6,6,6,6,6,6,6,6,6,6,5,0,0,0
0,0,5,6,6,6,6,6,6,6,6,6,6,6,6,6,6,6,6,6,6,6,6,6,6,6,6,6,6,6,5,0,0,0
0,0,0,5,6,6,6,6,6,6,6,6,6,6,6,6,6,6,6,6,6,6,6,6,6,6,6,6,6,5,0,0,0,0
0,0,0,5,6,6,6,6,6,6,6,6,6,6,6,6,6,6,6,6,6,6,6,6,6,6,6,6,6,5,0,0,0,0
0,0,5,6,6,6,6,6,6,6,6,6,6,6,6,6,6,6,6,6,6,6,6,6,6,6,6,6,6,6,5,0,0,0
0,5,6,6,6,6,6,6,6,6,6,6,6,6,6,6,6,6,6,6,6,6,6,6,6,6,6,6,6,6,6,5,0,0
5,6,6,6,6,6,6,6,6,6,6,6,6,6,6,6,6,6,6,6,6,6,6,6,6,6,6,6,6,6,6,6,5,0
6,6,6,6,6,6,6,6,6,6,6,6,6,6,6,6,6,6,6,6,6,6,6,6,6,6,6,6,6,6,6,6,6,3
5,6,6,6,6,6,6,6,5,5,6,6,6,6,6,6,6,6,6,6,6,6,6,5,5,6,6,6,6,6,6,6,5,0
0,5,6,6,6,6,6,5,0,0,5,5,5,6,6,6,6,6,6,6,5,5,5,0,0,5,6,6,6,6,6,5,0,0
0,0,5,6,6,6,5,0,0,0,0,0,0,5,5,5,5,5,5,5,0,0,0,0,0,0,5,6,6,6,5,0,0,0
0,0,0,5,6,5,0,0,0,0,0,0,0,0,0,0,0,0,0,0,0,0,0,0,0,0,0,5,6,5,0,0,0,0
0,0,0,0,3,0,0,0,0,0,0,0,0,0,0,0,0,0,0,0,0,0,0,0,0,0,0,0,3,0,0,0,0,0
:endlayer
layer: 7
0,0,0,5,6,5,0,0,0,0,0,0,0,0,0,0,0,0,0,0,0,0,0,0,0,0,0,5,6,5,0,0,0,0
0,0,5,6,6,6,5,0,0,0,0,0,0,0,0,0,0,0,0,0,0,0,0,0,0,0,5,6,6,6,5,0,0,0
0,5,6,6,6,6,6,5,0,0,0,0,0,11,11,11,11,11,11,11,0,0,0,0,0,5,6,6,6,6,6,5,0,0
5,6,6,6,6,6,6,6,5,0,11,11,11,5,5,5,5,5,5,5,11,11,11,0,5,6,6,6,6,6,6,6,5,0
6,6,6,6,6,6,6,6,6,5,5,5,5,6,6,6,6,6,6,6,5,5,5,5,6,6,6,6,6,6,6,6,6,3
5,6,6,6,6,6,6,6,5,5,6,6,6,6,6,6,6,6,6,6,6,6,6,5,5,6,6,6,6,6,6,6,5,0
0,5,6,6,6,6,6,5,5,6,6,6,6,6,6,6,6,6,6,6,6,6,6,6,5,5,6,6,6,6,6,5,0,0
0,0,5,6,6,6,5,6,6,6,6,6,6,6,6,6,6,6,6,6,6,6,6,6,6,6,5,6,6,6,5,0,0,0
0,0,0,5,6,5,5,6,6,6,6,6,6,6,6,6,6,6,6,6,6,6,6,6,6,6,5,5,6,5,0,0,0,0
0,0,0,0,5,5,6,6,6,6,6,6,6,6,6,6,6,6,6,6,6,6,6,6,6,6,6,5,5,0,0,0,0,0
0,0,0,14,5,6,6,6,6,6,6,6,6,6,6,6,6,6,6,6,6,6,6,6,6,6,6,6,5,10,0,0,0,0
0,0,0,14,5,6,6,6,6,6,6,6,6,6,6,6,6,6,6,6,6,6,6,6,6,6,6,6,5,10,0,0,0,0
0,0,0,14,5,6,6,6,6,6,6,6,6,6,6,6,6,6,6,6,6,6,6,6,6,6,6,6,5,10,0,0,0,0
0,0,14,5,6,6,6,6,6,6,6,6,6,6,6,6,6,6,6,6,6,6,6,6,6,6,6,6,6,5,10,0,0,0
0,0,14,5,6,6,6,6,6,6,6,6,6,6,6,6,6,6,6,6,6,6,6,6,6,6,6,6,6,5,10,0,0,0
0,0,14,5,6,6,6,6,6,6,6,6,6,6,6,13,13,13,6,6,6,6,6,6,6,6,6,6,6,5,10,0,0,0
0,0,3,5,6,6,6,6,6,6,6,6,6,6,6,13,13,13,6,6,6,6,6,6,6,6,6,6,6,5,3,0,0,3
0,0,14,5,6,6,6,6,6,6,6,6,6,6,6,13,13,13,6,6,6,6,6,6,6,6,6,6,6,5,10,0,0,0
0,0,14,5,6,6,6,6,6,6,6,6,6,6,6,6,6,6,6,6,6,6,6,6,6,6,6,6,6,5,10,0,0,0
0,0,14,5,6,6,6,6,6,6,6,6,6,6,6,6,6,6,6,6,6,6,6,6,6,6,6,6,6,5,10,0,0,0
0,0,0,14,5,6,6,6,6,6,6,6,6,6,6,6,6,6,6,6,6,6,6,6,6,6,6,6,5,10,0,0,0,0
0,0,0,14,5,6,6,6,6,6,6,6,6,6,6,6,6,6,6,6,6,6,6,6,6,6,6,6,5,10,0,0,0,0
0,0,0,14,5,6,6,6,6,6,6,6,6,6,6,6,6,6,6,6,6,6,6,6,6,6,6,6,5,10,0,0,0,0
0,0,0,0,5,5,6,6,6,6,6,6,6,6,6,6,6,6,6,6,6,6,6,6,6,6,6,5,5,0,0,0,0,0
0,0,0,5,6,5,5,6,6,6,6,6,6,6,6,6,6,6,6,6,6,6,6,6,6,6,5,5,6,5,0,0,0,0
0,0,5,6,6,6,5,6,6,6,6,6,6,6,6,6,6,6,6,6,6,6,6,6,6,6,5,6,6,6,5,0,0,0
0,5,6,6,6,6,6,5,5,6,6,6,6,6,6,6,6,6,6,6,6,6,6,6,5,5,6,6,6,6,6,5,0,0
5,6,6,6,6,6,6,6,5,5,6,6,6,6,6,6,6,6,6,6,6,6,6,5,5,6,6,6,6,6,6,6,5,0
6,6,6,6,6,6,6,6,6,5,5,5,5,6,6,6,6,6,6,6,5,5,5,5,6,6,6,6,6,6,6,6,6,3
5,6,6,6,6,6,6,6,5,0,12,12,12,5,5,5,5,5,5,5,12,12,12,0,5,6,6,6,6,6,6,6,5,0
0,5,6,6,6,6,6,5,0,0,0,0,0,12,12,12,12,12,12,12,0,0,0,0,0,5,6,6,6,6,6,5,0,0
0,0,5,6,6,6,5,0,0,0,0,0,0,0,0,0,0,0,0,0,0,0,0,0,0,0,5,6,6,6,5,0,0,0
0,0,0,5,6,5,0,0,0,0,0,0,0,0,0,0,0,0,0,0,0,0,0,0,0,0,0,5,6,5,0,0,0,0
0,0,0,0,3,0,0,0,0,0,0,0,0,0,0,0,0,0,0,0,0,0,0,0,0,0,0,0,3,0,0,0,0,0
:endlayer
layer: 8
0,0,0,5,6,5,0,0,0,0,0,0,0,0,0,0,0,0,0,0,0,0,0,0,0,0,0,5,6,5,0,0,0,0
0,0,5,6,6,6,5,0,0,0,0,0,0,0,0,0,0,0,0,0,0,0,0,0,0,0,5,6,6,6,5,0,0,0
0,5,6,6,6,6,6,5,0,0,0,0,0,0,0,0,0,0,0,0,0,0,0,0,0,5,6,6,6,6,6,5,0,0
5,6,6,6,6,6,6,6,5,0,0,0,0,5,5,5,5,5,5,5,0,0,0,0,5,6,6,6,6,6,6,6,5,0
6,6,6,6,6,6,6,6,6,5,5,5,5,6,6,6,6,6,6,6,5,5,5,5,6,6,6,6,6,6,6,6,6,3
5,6,6,6,6,6,6,6,5,5,6,6,6,6,6,6,6,6,6,6,6,6,6,5,5,6,6,6,6,6,6,6,5,0
0,5,6,6,6,6,6,5,5,6,6,6,6,6,6,6,6,6,6,6,6,6,6,6,5,5,6,6,6,6,6,5,0,0
0,0,5,6,6,6,5,6,6,6,6,6,6,6,6,6,6,6,6,6,6,6,6,6,6,6,5,6,6,6,5,0,0,0
0,0,0,5,6,5,5,6,6,6,6,6,6,6,6,6,6,6,6,6,6,6,6,6,6,6,5,5,6,5,0,0,0,0
0,0,0,0,5,5,6,6,6,6,6,6,6,6,6,6,6,6,6,6,6,6,6,6,6,6,6,5,5,0,0,0,0,0
0,0,0,0,5,6,6,6,6,6,6,6,6,6,6,6,6,6,6,6,6,6,6,6,6,6,6,6,5,0,0,0,0,0
0,0,0,0,5,6,6,6,6,6,6,6,6,6,6,6,6,6,6,6,6,6,6,6,6,6,6,6,5,0,0,0,0,0
0,0,0,0,5,6,6,6,6,6,6,6,6,6,13,13,13,13,13,6,6,6,6,6,6,6,6,6,5,0,0,0,0,0
0,0,0,5,6,6,6,6,6,6,6,6,6,13,13,13,13,13,13,13,6,6,6,6,6,6,6,6,6,5,0,0,0,0
0,0,0,5,6,6,6,6,6,6,6,6,13,13,13,13,13,13,13,13,13,6,6,6,6,6,6,6,6,5,0,0,0,0
0,0,0,5,6,6,6,6,6,6,6,6,13,13,13,15,15,15,13,13,13,6,6,6,6,6,6,6,6,5,0,0,0,0
0,0,3,5,6,6,6,6,6,6,6,6,13,13,13,15,15,15,13,13,13,6,6,6,6,6,6,6,6,5,3,0,0,3
0,0,0,5,6,6,6,6,6,6,6,6,13,13,13,15,15,15,13,13,13,6,6,6,6,6,6,6,6,5,0,0,0,0
0,0,0,5,6,6,6,6,6,6,6,6,13,13,13,13,13,13,13,13,13,6,6,6,6,6,6,6,6,5,0,0,0,0
0,0,0,5,6,6,6,6,6,6,6,6,6,13,13,13,13,13,13,13,6,6,6,6,6,6,6,6,6,5,0,0,0,0
0,0,0,0,5,6,6,6,6,6,6,6,6,6,13,13,13,13,13,6,6,6,6,6,6,6,6,6,5,0,0,0,0,0
0,0,0,0,5,6,6,6,6,6,6,6,6,6,6,6,6,6,6,6,6,6,6,6,6,6,6,6,5,0,0,0,0,0
0,0,0,0,5,6,6,6,6,6,6,6,6,6,6,6,6,6,6,6,6,6,6,6,6,6,6,6,5,0,0,0,0,0
0,0,0,0,5,5,6,6,6,6,6,6,6,6,6,6,6,6,6,6,6,6,6,6,6,6,6,5,5,0,0,0,0,0
0,0,0,5,6,5,5,6,6,6,6,6,6,6,6,6,6,6,6,6,6,6,6,6,6,6,5,5,6,5,0,0,0,0
0,0,5,6,6,6,5,6,6,6,6,6,6,6,6,6,6,6,6,6,6,6,6,6,6,6,5,6,6,6,5,0,0,0
0,5,6,6,6,6,6,5,5,6,6,6,6,6,6,6,6,6,6,6,6,6,6,6,5,5,6,6,6,6,6,5,0,0
5,6,6,6,6,6,6,6,5,5,6,6,6,6,6,6,6,6,6,6,6,6,6,5,5,6,6,6,6,6,6,6,5,0
6,6,6,6,6,6,6,6,6,5,5,5,5,6,6,6,6,6,6,6,5,5,5,5,6,6,6,6,6,6,6,6,6,3
5,6,6,6,6,6,6,6,5,0,0,0,0,5,5,5,5,5,5,5,0,0,0,0,5,6,6,6,6,6,6,6,5,0
0,5,6,6,6,6,6,5,0,0,0,0,0,0,0,0,0,0,0,0,0,0,0,0,0,5,6,6,6,6,6,5,0,0
0,0,5,6,6,6,5,0,0,0,0,0,0,0,0,0,0,0,0,0,0,0,0,0,0,0,5,6,6,6,5,0,0,0
0,0,0,5,6,5,0,0,0,0,0,0,0,0,0,0,0,0,0,0,0,0,0,0,0,0,0,5,6,5,0,0,0,0
0,0,0,0,3,0,0,0,0,0,0,0,0,0,0,0,0,0,0,0,0,0,0,0,0,0,0,0,3,0,0,0,0,0
:endlayer
layer: 9
0,0,0,5,6,5,0,0,0,0,0,0,0,0,0,0,0,0,0,0,0,0,0,0,0,0,0,5,6,5,0,0,0,0
0,0,5,6,6,6,5,0,0,0,0,0,0,0,0,0,0,0,0,0,0,0,0,0,0,0,5,6,6,6,5,0,0,0
0,5,6,6,6,6,6,5,0,0,0,0,0,0,0,0,0,0,0,0,0,0,0,0,0,5,6,6,6,6,6,5,0,0
5,6,6,6,6,6,6,6,5,0,0,0,0,5,5,5,5,5,5,5,0,0,0,0,5,6,6,6,6,6,6,6,5,0
6,6,6,6,6,6,6,6,6,5,5,5,5,6,6,6,6,6,6,6,5,5,5,5,6,6,6,6,6,6,6,6,6,3
5,6,6,6,6,6,6,6,5,5,6,6,6,6,6,6,6,6,6,6,6,6,6,5,5,6,6,6,6,6,6,6,5,0
0,5,6,6,6,6,6,5,5,6,6,6,6,6,6,6,6,6,6,6,6,6,6,6,5,5,6,6,6,6,6,5,0,0
0,0,5,6,6,6,5,6,6,6,6,6,6,6,6,6,6,6,6,6,6,6,6,6,6,6,5,6,6,6,5,0,0,0
0,0,0,5,6,5,5,6,6,6,6,6,6,6,6,6,6,6,6,6,6,6,6,6,6,6,5,5,6,5,0,0,0,0
0,0,0,0,5,5,6,6,6,6,6,6,6,6,6,6,6,6,6,6,6,6,6,6,6,6,6,5,5,0,0,0,0,0
0,0,0,0,5,6,6,6,6,6,6,6,6,6,6,6,6,6,6,6,6,6,6,6,6,6,6,6,5,0,0,0,0,0
0,0,0,0,5,6,6,6,6,6,6,6,6,6,26,26,26,26,26,6,6,6,6,6,6,6,6,6,5,0,0,0,0,0
0,0,0,0,5,6,6,6,6,6,6,6,6,26,70,61,53,44,35,26,6,6,6,6,6,6,6,6,5,0,0,0,0,0
0,0,0,5,6,6,6,6,6,6,6,6,86,79,71,62,54,45,36,27,20,6,6,6,6,6,6,6,6,5,0,0,0,0
0,0,0,5,6,6,6,6,6,6,6,86,87,80,72,63,55,46,37,28,21,20,6,6,6,6,6,6,6,5,0,0,0,0
19,18,16,5,6,6,6,6,6,6,6,86,88,81,73,64,56,47,38,29,22,20,6,6,6,6,6,6,6,5,16,19,18,16
19,18,3,5,6,6,6,6,6,6,6,86,89,82,74,65,0,48,39,30,23,20,6,6,6,6,6,6,6,5,3,19,18,3
17,18,17,5,6,6,6,6,6,6,6,86,90,83,75,66,57,49,40,31,24,20,6,6,6,6,6,6,6,5,17,19,17,17
0,0,0,5,6,6,6,6,6,6,6,86,91,84,76,67,58,50,41,32,25,20,6,6,6,6,6,6,6,5,0,0,0,0
0,0,0,5,6,6,6,6,6,6,6,6,86,85,77,68,59,51,42,33,20,6,6,6,6,6,6,6,6,5,0,0,0,0
0,0,0,0,5,6,6,6,6,6,6,6,6,34,78,69,60,52,43,34,6,6,6,6,6,6,6,6,5,0,0,0,0,0
0,0,0,0,5,6,6,6,6,6,6,6,6,6,34,34,34,34,34,6,6,6,6,6,6,6,6,6,5,0,0,0,0,0
0,0,0,0,5,6,6,6,6,6,6,6,6,6,6,6,6,6,6,6,6,6,6,6,6,6,6,6,5,0,0,0,0,0
0,0,0,0,5,5,6,6,6,6,6,6,6,6,6,6,6,6,6,6,6,6,6,6,6,6,6,5,5,0,0,0,0,0
0,0,0,5,6,5,5,6,6,6,6,6,6,6,6,6,6,6,6,6,6,6,6,6,6,6,5,5,6,5,0,0,0,0
0,0,5,6,6,6,5,6,6,6,6,6,6,6,6,6,6,6,6,6,6,6,6,6,6,6,5,6,6,6,5,0,0,0
0,5,6,6,6,6,6,5,5,6,6,6,6,6,6,6,6,6,6,6,6,6,6,6,5,5,6,6,6,6,6,5,0,0
5,6,6,6,6,6,6,6,5,5,6,6,6,6,6,6,6,6,6,6,6,6,6,5,5,6,6,6,6,6,6,6,5,0
6,6,6,6,6,6,6,6,6,5,5,5,5,6,6,6,6,6,6,6,5,5,5,5,6,6,6,6,6,6,6,6,6,3
5,6,6,6,6,6,6,6,5,0,0,0,0,5,5,5,5,5,5,5,0,0,0,0,5,6,6,6,6,6,6,6,5,0
0,5,6,6,6,6,6,5,0,0,0,0,0,0,0,0,0,0,0,0,0,0,0,0,0,5,6,6,6,6,6,5,0,0
0,0,5,6,6,6,5,0,0,0,0,0,0,0,0,0,0,0,0,0,0,0,0,0,0,0,5,6,6,6,5,0,0,0
0,0,0,5,6,5,0,0,0,0,0,0,0,0,0,0,0,0,0,0,0,0,0,0,0,0,0,5,6,5,0,0,0,0
0,0,0,0,3,0,0,0,0,0,0,0,0,0,0,0,0,0,0,0,0,0,0,0,0,0,0,0,3,0,0,0,0,0
:endlayer
layer: 10
0,0,0,5,6,5,0,0,0,0,0,0,0,0,0,0,0,0,0,0,0,0,0,0,0,0,0,5,6,5,0,0,0,0
0,0,5,6,6,6,5,0,0,0,0,0,0,0,0,0,0,0,0,0,0,0,0,0,0,0,5,6,6,6,5,0,0,0
0,5,6,6,6,6,6,5,0,0,0,0,0,0,0,0,0,0,0,0,0,0,0,0,0,5,6,6,6,6,6,5,0,0
5,6,6,6,6,6,6,6,5,0,0,0,0,5,5,5,5,5,5,5,0,0,0,0,5,6,6,6,6,6,6,6,5,0
6,6,6,6,6,6,6,6,6,5,5,5,5,93,93,93,93,93,93,93,5,5,5,5,6,6,6,6,6,6,6,6,6,3
5,6,6,6,6,6,6,6,5,5,6,93,93,93,93,93,93,93,93,93,93,93,6,5,5,6,6,6,6,6,6,6,5,0
0,5,6,6,6,6,6,5,93,93,93,93,93,93,93,93,93,93,93,93,93,93,93,93,93,5,6,6,6,6,6,5,0,0
0,0,5,6,6,6,5,6,93,93,93,93,93,93,93,93,93,93,93,93,93,93,93,93,93,6,5,6,6,6,5,0,0,0
0,0,0,5,6,5,93,93,93,93,93,93,93,93,93,93,93,93,93,93,93,93,93,93,93,93,93,5,6,5,0,0,0,0
0,0,0,0,5,5,93,93,93,93,93,93,93,93,93,93,93,93,93,93,93,93,93,93,93,93,93,5,5,0,0,0,0,0
0,0,0,0,5,6,93,93,93,93,93,93,93,93,94,94,94,94,94,93,93,93,93,93,93,93,93,6,5,0,0,0,0,0
0,0,0,0,5,93,93,93,93,93,93,93,94,94,95,95,95,95,95,94,94,93,93,93,93,93,93,93,5,0,0,0,0,0
0,0,0,0,5,93,93,93,93,93,93,94,94,95,95,95,95,95,95,95,94,94,93,93,93,93,93,93,5,0,0,0,0,0
0,0,0,5,93,93,93,93,93,93,93,94,95,95,95,95,95,95,95,95,95,94,93,93,93,93,93,93,93,5,0,0,0,0
0,0,0,5,93,93,93,93,93,93,94,95,95,95,95,95,95,95,95,95,95,95,94,93,93,93,93,93,93,5,0,0,0,0
16,16,3,5,93,93,93,93,93,93,94,95,95,95,95,95,95,95,95,95,95,95,94,93,93,93,93,93,93,5,3,16,16,3
92,92,92,5,93,93,93,93,93,93,94,95,95,95,95,95,95,95,95,95,95,95,94,93,93,93,93,93,93,5,92,92,92,92
17,17,3,5,93,93,93,93,93,93,94,95,95,95,95,95,95,95,95,95,95,95,94,93,93,93,93,93,93,5,3,17,17,3
0,0,0,5,93,93,93,93,93,93,94,95,95,95,95,95,95,95,95,95,95,95,94,93,93,93,93,93,93,5,0,0,0,0
0,0,0,5,93,93,93,93,93,93,93,94,95,95,95,95,95,95,95,95,95,94,93,93,93,93,93,93,93,5,0,0,0,0
0,0,0,0,5,93,93,93,93,93,93,94,94,95,95,95,95,95,95,95,94,94,93,93,93,93,93,93,5,0,0,0,0,0
0,0,0,0,5,93,93,93,93,93,93,93,94,94,95,95,95,95,95,94,94,93,93,93,93,93,93,93,5,0,0,0,0,0
0,0,0,0,5,6,93,93,93,93,93,93,93,93,94,94,94,94,94,93,93,93,93,93,93,93,93,6,5,0,0,0,0,0
0,0,0,0,5,5,93,93,93,93,93,93,93,93,93,93,93,93,93,93,93,93,93,93,93,93,93,5,5,0,0,0,0,0
0,0,0,5,6,5,93,93,93,93,93,93,93,93,93,93,93,93,93,93,93,93,93,93,93,93,93,5,6,5,0,0,0,0
0,0,5,6,6,6,5,6,93,93,93,93,93,93,93,93,93,93,93,93,93,93,93,93,93,6,5,6,6,6,5,0,0,0
0,5,6,6,6,6,6,5,93,93,93,93,93,93,93,93,93,93,93,93,93,93,93,93,93,5,6,6,6,6,6,5,0,0
5,6,6,6,6,6,6,6,5,5,6,93,93,93,93,93,93,93,93,93,93,93,6,5,5,6,6,6,6,6,6,6,5,0
6,6,6,6,6,6,6,6,6,5,5,5,5,93,93,93,93,93,93,93,5,5,5,5,6,6,6,6,6,6,6,6,6,3
5,6,6,6,6,6,6,6,5,8,8,8,8,5,5,5,5,5,5,5,8,8,8,8,5,6,6,6,6,6,6,6,5,0
0,5,6,6,6,6,6,5,8,8,8,8,8,8,8,18,8,19,8,8,8,8,8,8,8,5,6,6,6,6,6,5,0,0
0,0,5,6,6,6,5,0,0,0,0,0,0,0,0,18,8,19,0,0,0,0,0,0,0,0,5,6,6,6,5,0,0,0
0,0,0,5,6,5,0,0,0,0,0,0,0,0,0,18,8,19,0,0,0,0,0,0,0,0,0,5,6,5,0,0,0,0
0,0,0,0,3,0,0,0,0,0,0,0,0,0,0,18,8,19,0,0,0,0,0,0,0,0,0,0,3,0,0,0,0,0
:endlayer
layer: 11
0,0,0,5,6,5,0,0,0,0,0,0,0,0,0,0,0,0,0,0,0,0,0,0,0,0,0,5,6,5,0,0,0,0
0,0,5,6,6,6,5,0,0,0,0,0,0,0,0,0,0,0,0,0,0,0,0,0,0,0,5,6,6,6,5,0,0,0
0,5,6,6,6,6,6,5,0,0,0,0,0,0,0,0,0,0,0,0,0,0,0,0,0,5,6,6,6,6,6,5,0,0
5,6,6,6,6,6,6,6,5,0,0,0,0,5,5,5,5,5,5,5,0,0,0,0,5,6,6,6,6,6,6,6,5,0
6,6,6,6,6,6,6,6,6,5,5,5,5,100,100,100,100,100,100,100,5,5,5,5,6,6,6,6,6,6,6,6,6,3
5,6,6,6,6,6,6,6,5,5,3,0,99,100,100,100,100,100,100,100,99,0,3,5,5,6,6,6,6,6,6,6,5,0
0,5,6,6,6,6,6,5,5,96,0,97,0,94,94,94,94,94,94,94,0,97,0,96,5,5,6,6,6,6,6,5,0,0
0,0,5,6,6,6,5,3,0,0,0,0,0,0,0,0,0,0,0,0,0,0,0,0,0,3,5,6,6,6,5,0,0,0
0,0,0,5,6,5,5,0,0,0,0,0,0,0,0,0,0,0,0,0,0,0,0,0,0,0,5,5,6,5,0,0,0,0
0,0,0,0,5,5,96,0,0,0,0,0,0,0,0,0,0,0,0,0,0,0,0,0,0,0,96,5,5,0,0,0,0,0
0,0,0,0,5,3,0,0,0,0,3,3,0,0,0,0,0,0,0,0,0,3,3,0,0,0,0,3,5,0,0,0,0,0
0,0,0,0,5,0,0,0,0,0,3,3,0,0,0,0,0,0,0,0,0,3,3,0,0,0,0,0,5,0,0,0,0,0
0,0,0,0,5,0,0,0,0,0,0,0,0,0,0,0,0,0,0,0,0,0,0,0,0,0,0,0,5,0,0,0,0,0
0,0,0,5,0,0,0,0,0,0,0,0,0,0,0,0,0,0,0,0,0,0,0,0,0,0,0,0,0,5,0,0,0,0
0,0,0,5,0,0,0,0,0,0,0,0,0,0,0,0,0,0,0,0,0,0,0,0,0,0,0,0,0,5,0,0,0,0
10,14,3,0,0,0,0,0,0,0,0,0,0,0,0,0,0,0,0,0,0,0,0,0,0,0,0,0,0,0,3,10,14,3
0,0,0,0,0,0,0,0,0,0,0,0,0,0,0,0,0,0,0,0,0,0,0,0,0,0,0,0,0,0,0,0,0,0
10,14,3,0,0,0,0,0,0,0,0,0,0,0,0,0,0,0,0,0,0,0,0,0,0,0,0,0,0,0,3,10,14,3
0,0,0,5,0,0,0,0,0,0,0,0,0,0,103,103,0,0,0,0,0,0,0,0,0,0,0,0,0,5,0,0,0,0
0,0,0,5,0,0,0,0,0,0,0,0,0,0,0,0,0,0,0,0,0,0,0,0,0,0,0,0,0,5,0,0,0,0
0,0,0,0,5,0,0,0,0,0,0,0,0,0,0,0,0,0,0,0,0,0,0,0,0,0,0,0,5,0,0,0,0,0
0,0,0,0,5,0,0,0,0,0,3,3,0,0,0,0,0,0,0,0,0,3,3,0,0,0,0,0,5,0,0,0,0,0
0,0,0,0,5,3,0,0,0,0,3,3,0,0,0,0,0,0,0,0,0,3,3,0,0,0,0,3,5,0,0,0,0,0
0,0,0,0,5,5,96,0,0,0,0,0,0,0,0,0,0,0,0,0,0,0,0,0,0,0,96,5,5,0,0,0,0,0
0,0,0,5,6,5,5,0,0,0,0,0,0,0,0,0,0,0,0,0,0,0,0,0,0,0,5,5,6,5,0,0,0,0
0,0,5,6,6,6,5,3,0,0,0,0,0,0,0,0,0,0,0,0,0,0,0,0,0,3,5,6,6,6,5,0,0,0
0,5,6,6,6,6,6,5,5,96,0,0,0,0,0,0,0,0,0,0,0,0,0,96,5,5,6,6,6,6,6,5,0,0
5,6,6,6,6,6,6,6,5,5,3,104,0,0,0,0,0,0,0,0,0,98,3,5,5,6,6,6,6,6,6,6,5,0
6,6,6,6,6,6,6,6,6,5,5,5,5,3,101,101,102,101,101,3,5,5,5,5,6,6,6,6,6,6,6,6,6,3
5,6,6,6,6,6,6,6,5,0,0,0,0,5,5,0,0,0,5,5,0,0,0,0,5,6,6,6,6,6,6,6,5,0
0,5,6,6,6,6,6,5,0,0,0,0,0,0,0,0,0,0,0,0,0,0,0,0,0,5,6,6,6,6,6,5,0,0
0,0,5,6,6,6,5,0,0,0,0,0,0,0,0,0,0,0,0,0,0,0,0,0,0,0,5,6,6,6,5,0,0,0
0,0,0,5,6,5,0,0,0,0,0,0,0,0,0,0,0,0,0,0,0,0,0,0,0,0,0,5,6,5,0,0,0,0
0,0,0,0,3,0,0,0,0,0,0,0,0,0,0,0,0,0,0,0,0,0,0,0,0,0,0,0,3,0,0,0,0,0
:endlayer
layer: 12
0,0,0,5,6,5,0,0,0,0,0,0,0,0,0,0,0,0,0,0,0,0,0,0,0,0,0,5,6,5,0,0,0,0
0,0,5,6,6,6,5,0,0,0,0,0,0,0,0,0,0,0,0,0,0,0,0,0,0,0,5,6,6,6,5,0,0,0
0,5,6,6,6,6,6,5,0,0,0,0,0,0,0,0,0,0,0,0,0,0,0,0,0,5,6,6,6,6,6,5,0,0
5,6,6,6,6,6,6,6,5,0,0,0,0,5,5,5,5,5,5,5,0,0,0,0,5,6,6,6,6,6,6,6,5,0
6,6,6,6,6,6,6,6,6,5,5,5,5,0,111,110,108,107,106,0,5,5,5,5,6,6,6,6,6,6,6,6,6,3
5,6,6,6,6,6,6,6,5,5,3,97,112,97,0,0,0,0,0,97,105,97,3,5,5,6,6,6,6,6,6,6,5,0
0,5,6,6,6,6,6,5,5,0,0,97,0,0,0,0,0,0,0,0,0,97,0,0,5,5,6,6,6,6,6,5,0,0
0,0,5,6,6,6,5,3,0,0,0,0,0,0,0,0,0,0,0,0,0,0,0,0,0,3,5,6,6,6,5,0,0,0
0,0,0,5,6,5,5,0,0,0,0,0,0,0,0,0,0,0,0,0,0,0,0,0,0,0,5,5,6,5,0,0,0,0
0,0,0,0,5,5,0,0,0,0,0,0,0,0,0,0,0,0,0,0,0,0,0,0,0,0,0,5,5,0,0,0,0,0
0,0,0,0,5,3,0,0,0,0,3,3,0,0,0,0,0,0,0,0,0,3,3,0,0,0,0,3,5,0,0,0,0,0
0,0,0,0,5,0,0,0,0,0,3,3,0,0,0,0,0,0,0,0,0,3,3,0,0,0,0,0,5,0,0,0,0,0
0,0,0,0,5,0,0,0,0,0,0,0,0,0,0,0,0,0,0,0,0,0,0,0,0,0,0,0,5,0,0,0,0,0
0,0,0,5,0,0,0,0,0,0,0,0,0,0,0,0,0,0,0,0,0,0,0,0,0,0,0,0,0,5,0,0,0,0
0,0,0,5,0,0,0,0,0,0,0,0,0,0,0,0,0,0,0,0,0,0,0,0,0,0,0,0,0,5,0,0,0,0
0,0,3,0,0,0,0,0,0,0,0,0,0,0,0,0,0,0,0,0,0,0,0,0,0,0,0,0,0,0,3,0,0,3
0,0,0,0,0,0,0,0,0,0,0,0,0,0,0,0,0,0,0,0,0,0,0,0,0,0,0,0,0,0,0,0,0,0
0,0,3,0,0,0,0,0,0,0,0,0,0,0,103,103,0,0,0,0,0,0,0,0,0,0,0,0,0,0,3,0,0,3
0,0,0,5,0,0,0,0,0,0,0,0,0,0,0,0,0,0,0,0,0,0,0,0,0,0,0,0,0,5,0,0,0,0
0,0,0,5,0,0,0,0,0,0,0,0,0,0,0,0,0,0,0,0,0,0,0,0,0,0,0,0,0,5,0,0,0,0
0,0,0,0,5,0,0,0,0,0,0,0,0,0,0,0,0,0,0,0,0,0,0,0,0,0,0,0,5,0,0,0,0,0
0,0,0,0,5,0,0,0,0,0,3,3,0,0,0,0,0,0,0,0,0,3,3,0,0,0,0,0,5,0,0,0,0,0
0,0,0,0,5,3,0,0,0,0,3,3,0,0,0,0,0,0,0,0,0,3,3,0,0,0,0,3,5,0,0,0,0,0
0,0,0,0,5,5,0,0,0,0,0,0,0,0,0,0,0,0,0,0,0,0,0,0,0,0,0,5,5,0,0,0,0,0
0,0,0,5,6,5,5,0,0,0,0,0,0,0,0,0,0,0,0,0,0,0,0,0,0,0,5,5,6,5,0,0,0,0
0,0,5,6,6,6,5,3,0,0,0,0,0,0,0,0,0,0,0,0,0,0,0,0,0,3,5,6,6,6,5,0,0,0
0,5,6,6,6,6,6,5,5,0,0,0,0,0,0,0,0,0,0,0,0,0,0,0,5,5,6,6,6,6,6,5,0,0
5,6,6,6,6,6,6,6,5,5,3,0,0,0,0,0,0,0,0,0,0,0,3,5,5,6,6,6,6,6,6,6,5,0
6,6,6,6,6,6,6,6,6,5,5,5,5,3,101,101,109,101,101,3,5,5,5,5,6,6,6,6,6,6,6,6,6,3
5,6,6,6,6,6,6,6,5,0,0,0,0,5,5,0,0,0,5,5,0,0,0,0,5,6,6,6,6,6,6,6,5,0
0,5,6,6,6,6,6,5,0,0,0,0,0,0,0,0,0,0,0,0,0,0,0,0,0,5,6,6,6,6,6,5,0,0
0,0,5,6,6,6,5,0,0,0,0,0,0,0,0,0,0,0,0,0,0,0,0,0,0,0,5,6,6,6,5,0,0,0
0,0,0,5,6,5,0,0,0,0,0,0,0,0,0,0,0,0,0,0,0,0,0,0,0,0,0,5,6,5,0,0,0,0
0,0,0,0,3,0,0,0,0,0,0,0,0,0,0,0,0,0,0,0,0,0,0,0,0,0,0,0,3,0,0,0,0,0
:endlayer
layer: 13
0,0,0,5,6,5,0,0,0,0,0,0,0,0,0,0,0,0,0,0,0,0,0,0,0,0,0,5,6,5,0,0,0,0
0,0,5,6,6,6,5,0,0,0,0,0,0,0,0,0,0,0,0,0,0,0,0,0,0,0,5,6,6,6,5,0,0,0
0,5,6,6,6,6,6,5,0,0,0,0,0,0,0,0,0,0,0,0,0,0,0,0,0,5,6,6,6,6,6,5,0,0
5,6,6,6,6,6,6,6,5,0,0,0,0,5,5,5,5,5,5,5,0,0,0,0,5,6,6,6,6,6,6,6,5,0
6,6,6,6,6,6,6,6,6,5,5,5,5,0,118,0,117,0,116,0,5,5,5,5,6,6,6,6,6,6,6,6,6,3
5,6,6,6,6,6,6,6,5,5,3,120,114,119,0,0,0,0,0,115,114,113,3,5,5,6,6,6,6,6,6,6,5,0
0,5,6,6,6,6,6,5,5,0,0,97,0,0,0,0,0,0,0,0,0,97,0,0,5,5,6,6,6,6,6,5,0,0
0,0,5,6,6,6,5,3,0,0,0,0,0,0,0,0,0,0,0,0,0,0,0,0,0,3,5,6,6,6,5,0,0,0
0,0,0,5,6,5,5,0,0,0,0,0,0,0,0,0,0,0,0,0,0,0,0,0,0,0,5,5,6,5,0,0,0,0
0,0,0,0,5,5,0,0,0,0,0,0,0,0,0,0,0,0,0,0,0,0,0,0,0,0,0,5,5,0,0,0,0,0
0,0,0,0,5,3,0,0,0,0,3,3,0,0,0,0,0,0,0,0,0,3,3,0,0,0,0,3,5,0,0,0,0,0
0,0,0,0,5,0,0,0,0,0,3,3,0,0,0,0,0,0,0,0,0,3,3,0,0,0,0,0,5,0,0,0,0,0
0,0,0,0,5,0,0,0,0,0,0,0,0,0,0,0,0,0,0,0,0,0,0,0,0,0,0,0,5,0,0,0,0,0
0,0,0,5,0,0,0,0,0,0,0,0,0,0,0,0,0,0,0,0,0,0,0,0,0,0,0,0,0,5,0,0,0,0
0,0,0,5,0,0,0,0,0,0,0,0,0,0,0,0,0,0,0,0,0,0,0,0,0,0,0,0,0,5,0,0,0,0
0,0,0,19,0,0,0,0,0,0,0,0,0,0,0,0,0,0,0,0,0,0,0,0,0,0,0,0,0,18,0,0,0,0
0,0,0,0,0,0,0,0,0,0,0,0,0,0,103,103,0,0,0,0,0,0,0,0,0,0,0,0,0,0,0,0,0,0
0,0,0,19,0,0,0,0,0,0,0,0,0,0,0,0,0,0,0,0,0,0,0,0,0,0,0,0,0,18,0,0,0,0
0,0,0,5,0,0,0,0,0,0,0,0,0,0,0,0,0,0,0,0,0,0,0,0,0,0,0,0,0,5,0,0,0,0
0,0,0,5,0,0,0,0,0,0,0,0,0,0,0,0,0,0,0,0,0,0,0,0,0,0,0,0,0,5,0,0,0,0
0,0,0,0,5,0,0,0,0,0,0,0,0,0,0,0,0,0,0,0,0,0,0,0,0,0,0,0,5,0,0,0,0,0
0,0,0,0,5,0,0,0,0,0,3,3,0,0,0,0,0,0,0,0,0,3,3,0,0,0,0,0,5,0,0,0,0,0
0,0,0,0,5,3,0,0,0,0,3,3,0,0,0,0,0,0,0,0,0,3,3,0,0,0,0,3,5,0,0,0,0,0
0,0,0,0,5,5,0,0,0,0,0,0,0,0,0,0,0,0,0,0,0,0,0,0,0,0,0,5,5,0,0,0,0,0
0,0,0,5,6,5,5,0,0,0,0,0,0,0,0,0,0,0,0,0,0,0,0,0,0,0,5,5,6,5,0,0,0,0
0,0,5,6,6,6,5,3,0,0,0,0,0,0,0,0,0,0,0,0,0,0,0,0,0,3,5,6,6,6,5,0,0,0
0,5,6,6,6,6,6,5,5,0,0,0,0,0,0,0,0,0,0,0,0,0,0,0,5,5,6,6,6,6,6,5,0,0
5,6,6,6,6,6,6,6,5,5,3,0,0,0,0,0,0,0,0,0,0,0,3,5,5,6,6,6,6,6,6,6,5,0
6,6,6,6,6,6,6,6,6,5,5,5,5,3,101,101,101,101,101,3,5,5,5,5,6,6,6,6,6,6,6,6,6,3
5,6,6,6,6,6,6,6,5,0,0,0,0,5,5,0,0,0,5,5,0,0,0,0,5,6,6,6,6,6,6,6,5,0
0,5,6,6,6,6,6,5,0,0,0,0,0,0,0,0,0,0,0,0,0,0,0,0,0,5,6,6,6,6,6,5,0,0
0,0,5,6,6,6,5,0,0,0,0,0,0,0,0,0,0,0,0,0,0,0,0,0,0,0,5,6,6,6,5,0,0,0
0,0,0,5,6,5,0,0,0,0,0,0,0,0,0,0,0,0,0,0,0,0,0,0,0,0,0,5,6,5,0,0,0,0
0,0,0,0,3,0,0,0,0,0,0,0,0,0,0,0,0,0,0,0,0,0,0,0,0,0,0,0,3,0,0,0,0,0
:endlayer
layer: 14
0,0,94,121,6,121,94,0,0,0,0,0,0,0,0,0,0,0,0,0,0,0,0,0,0,0,94,121,6,121,94,0,0,0
0,94,121,6,6,6,121,94,0,0,0,0,0,0,0,0,0,0,0,0,0,0,0,0,0,94,121,6,6,6,121,94,0,0
94,121,6,6,6,6,6,121,94,0,0,0,0,0,0,0,0,0,0,0,0,0,0,0,94,121,6,6,6,6,6,121,94,0
121,6,6,6,6,6,6,6,121,94,0,0,0,5,5,5,5,5,5,5,0,0,0,94,121,6,6,6,6,6,6,6,121,94
6,6,6,6,6,6,6,6,6,5,5,5,5,0,0,0,12,0,0,0,5,5,5,5,6,6,6,6,6,6,6,6,6,3
121,6,6,6,6,6,6,6,5,5,3,124,123,122,0,0,0,0,0,124,123,122,3,5,5,6,6,6,6,6,6,6,121,94
94,121,6,6,6,6,6,5,5,0,0,97,0,0,0,0,0,0,0,0,0,97,0,0,5,5,6,6,6,6,6,121,94,0
0,94,121,6,6,6,5,3,0,0,0,0,0,0,0,0,0,0,0,0,0,0,0,0,0,3,5,6,6,6,121,94,0,0
0,0,94,121,6,5,5,0,0,0,0,0,0,0,0,0,0,0,0,0,0,0,0,0,0,0,5,5,6,121,94,0,0,0
0,0,0,94,5,5,0,0,0,0,0,0,0,0,0,0,0,0,0,0,0,0,0,0,0,0,0,5,5,94,0,0,0,0
0,0,0,0,5,3,0,0,0,0,3,3,0,0,0,0,0,0,0,0,0,3,3,0,0,0,0,3,5,0,0,0,0,0
0,0,0,0,5,0,0,0,0,0,3,3,0,0,0,0,0,0,0,0,0,3,3,0,0,0,0,0,5,0,0,0,0,0
0,0,0,0,5,0,0,0,0,0,0,0,0,0,0,0,0,0,0,0,0,0,0,0,0,0,0,0,5,0,0,0,0,0
0,0,0,5,0,0,0,0,0,0,0,0,0,0,0,0,0,0,0,0,0,0,0,0,0,0,0,0,0,5,0,0,0,0
0,0,0,5,0,0,0,0,0,0,0,0,0,0,103,103,0,0,0,0,0,0,0,0,0,0,0,0,0,5,0,0,0,0
0,0,0,5,0,0,0,0,0,0,0,0,0,0,103,103,0,0,0,0,0,0,0,0,0,0,0,0,0,5,0,0,0,0
0,0,0,18,10,0,0,0,0,0,0,0,0,0,0,0,0,0,0,0,0,0,0,0,0,0,0,0,14,5,0,0,0,0
0,0,0,5,0,0,0,0,0,0,0,0,0,0,0,0,0,0,0,0,0,0,0,0,0,0,0,0,0,5,0,0,0,0
0,0,0,5,0,0,0,0,0,0,0,0,0,0,0,0,0,0,0,0,0,0,0,0,0,0,0,0,0,5,0,0,0,0
0,0,0,5,0,0,0,0,0,0,0,0,0,0,0,0,0,0,0,0,0,0,0,0,0,0,0,0,0,5,0,0,0,0
0,0,0,0,5,0,0,0,0,0,0,0,0,0,0,0,0,0,0,0,0,0,0,0,0,0,0,0,5,0,0,0,0,0
0,0,0,0,5,0,0,0,0,0,3,3,0,0,0,0,0,0,0,0,0,3,3,0,0,0,0,0,5,0,0,0,0,0
0,0,0,0,5,3,0,0,0,0,3,3,0,0,0,0,0,0,0,0,0,3,3,0,0,0,0,3,5,0,0,0,0,0
0,0,0,94,5,5,0,0,0,0,0,0,0,0,0,0,0,0,0,0,0,0,0,0,0,0,0,5,5,94,0,0,0,0
0,0,94,121,6,5,5,0,0,0,0,0,0,0,0,0,0,0,0,0,0,0,0,0,0,0,5,5,6,121,94,0,0,0
0,94,121,6,6,6,5,3,0,0,0,0,0,0,0,0,0,0,0,0,0,0,0,0,0,3,5,6,6,6,121,94,0,0
94,121,6,6,6,6,6,5,5,0,0,0,0,0,0,0,0,0,0,0,0,0,0,0,5,5,6,6,6,6,6,121,94,0
121,6,6,6,6,6,6,6,5,5,3,0,0,0,0,0,0,0,0,0,0,0,3,5,5,6,6,6,6,6,6,6,121,94
6,6,6,6,6,6,6,6,6,5,5,5,5,3,101,101,101,101,101,3,5,5,5,5,6,6,6,6,6,6,6,6,6,3
121,6,6,6,6,6,6,6,121,94,0,0,0,5,5,17,17,17,5,5,0,0,0,94,121,6,6,6,6,6,6,6,121,94
94,121,6,6,6,6,6,121,94,0,0,0,0,0,0,0,0,0,0,0,0,0,0,0,94,121,6,6,6,6,6,121,94,0
0,94,121,6,6,6,121,94,0,0,0,0,0,0,0,0,0,0,0,0,0,0,0,0,0,94,121,6,6,6,121,94,0,0
0,0,94,121,6,121,94,0,0,0,0,0,0,0,0,0,0,0,0,0,0,0,0,0,0,0,94,121,6,121,94,0,0,0
0,0,0,94,3,94,0,0,0,0,0,0,0,0,0,0,0,0,0,0,0,0,0,0,0,0,0,94,3,94,0,0,0,0
:endlayer
layer: 15
0,0,94,5,6,5,94,0,0,0,0,0,0,0,0,0,0,0,0,0,0,0,0,0,0,0,94,5,6,5,94,0,0,0
0,94,5,6,6,6,5,94,0,0,0,0,0,0,0,0,0,0,0,0,0,0,0,0,0,94,5,6,6,6,5,94,0,0
94,5,6,6,6,6,6,5,94,0,0,0,0,94,94,94,94,94,94,94,0,0,0,0,94,5,6,6,6,6,6,5,94,0
5,6,6,6,6,6,6,6,5,94,94,94,94,5,5,5,5,5,5,5,94,94,94,94,5,6,6,6,6,6,6,6,5,94
6,6,6,6,6,6,6,6,6,5,5,5,5,0,8,17,125,17,8,0,5,5,5,5,6,6,6,6,6,6,6,6,6,3
5,6,6,6,6,6,6,6,5,5,3,0,0,0,0,0,0,0,0,0,0,0,3,5,5,6,6,6,6,6,6,6,5,94
94,5,6,6,6,6,6,5,5,0,0,126,0,0,0,0,0,0,0,0,0,126,0,0,5,5,6,6,6,6,6,5,94,0
0,94,5,6,6,6,5,3,0,0,0,0,0,0,0,0,0,0,0,0,0,0,0,0,0,3,5,6,6,6,5,94,0,0
0,0,94,5,6,5,5,0,0,0,0,0,0,0,0,0,0,0,0,0,0,0,0,0,0,0,5,5,6,5,94,0,0,0
0,0,0,94,5,5,0,0,0,0,16,16,8,0,0,0,0,0,0,0,8,16,16,0,0,0,0,5,5,94,0,0,0,0
0,0,0,94,5,3,0,0,0,18,3,3,19,0,0,0,0,0,0,0,18,3,3,19,0,0,0,3,5,94,0,0,0,0
0,0,0,94,5,0,0,0,0,18,3,3,19,0,0,0,0,0,0,0,18,3,3,19,0,0,0,0,5,94,0,0,0,0
0,0,0,94,5,0,0,0,0,8,17,17,8,0,0,0,0,0,0,0,8,17,17,8,0,0,0,0,5,94,0,0,0,0
0,0,94,5,0,0,0,0,0,0,0,0,0,0,0,0,0,0,0,0,0,0,0,0,0,0,0,0,0,5,94,0,0,0
0,0,94,5,8,0,0,0,0,0,0,0,0,0,0,0,103,0,0,0,0,0,0,0,0,0,0,0,8,5,94,0,0,0
0,0,94,5,19,0,0,0,0,0,0,0,0,0,0,0,103,0,0,0,0,0,0,0,0,0,0,0,18,5,94,0,0,0
0,0,94,5,125,0,0,0,0,0,0,0,0,0,0,0,0,0,0,0,0,0,0,0,0,0,0,0,125,5,94,0,0,0
0,0,94,5,19,0,0,0,0,0,0,0,0,0,0,0,0,0,0,0,0,0,0,0,0,0,0,0,18,5,94,0,0,0
0,0,94,5,8,0,0,0,0,0,0,0,0,0,0,0,0,0,0,0,0,0,0,0,0,0,0,0,8,5,94,0,0,0
0,0,94,5,0,0,0,0,0,0,0,0,0,0,0,0,0,0,0,0,0,0,0,0,0,0,0,0,0,5,94,0,0,0
0,0,0,94,5,0,0,0,0,8,16,16,8,0,0,0,0,0,0,0,8,16,16,8,0,0,0,0,5,94,0,0,0,0
0,0,0,94,5,0,0,0,0,18,3,3,19,0,0,0,0,0,0,0,18,3,3,19,0,0,0,0,5,94,0,0,0,0
0,0,0,94,5,3,0,0,0,18,3,3,19,0,0,0,0,0,0,0,18,3,3,19,0,0,0,3,5,94,0,0,0,0
0,0,0,94,5,5,0,0,0,0,17,17,8,0,0,0,0,0,0,0,8,17,17,0,0,0,0,5,5,94,0,0,0,0
0,0,94,5,6,5,5,0,0,0,0,0,0,0,0,0,0,0,0,0,0,0,0,0,0,0,5,5,6,5,94,0,0,0
0,94,5,6,6,6,5,3,0,0,0,0,0,0,0,0,0,0,0,0,0,0,0,0,0,3,5,6,6,6,5,94,0,0
94,5,6,6,6,6,6,5,5,0,0,0,0,0,0,0,0,0,0,0,0,0,0,0,5,5,6,6,6,6,6,5,94,0
5,6,6,6,6,6,6,6,5,5,3,0,0,0,0,0,0,0,0,0,0,0,3,5,5,6,6,6,6,6,6,6,5,94
6,6,6,6,6,6,6,6,6,5,5,5,5,3,19,16,125,16,18,3,5,5,5,5,6,6,6,6,6,6,6,6,6,3
5,6,6,6,6,6,6,6,5,94,94,94,94,5,5,5,5,5,5,5,94,94,94,94,5,6,6,6,6,6,6,6,5,94
94,5,6,6,6,6,6,5,94,0,0,0,0,94,94,94,94,94,94,94,0,0,0,0,94,5,6,6,6,6,6,5,94,0
0,94,5,6,6,6,5,94,0,0,0,0,0,0,0,0,0,0,0,0,0,0,0,0,0,94,5,6,6,6,5,94,0,0
0,0,94,5,6,5,94,0,0,0,0,0,0,0,0,0,0,0,0,0,0,0,0,0,0,0,94,5,6,5,94,0,0,0
0,0,0,94,3,94,0,0,0,0,0,0,0,0,0,0,0,0,0,0,0,0,0,0,0,0,0,94,3,94,0,0,0,0
:endlayer
layer: 16
0,0,127,5,6,5,127,0,0,0,0,0,0,0,0,0,0,0,0,0,0,0,0,0,0,0,127,5,6,5,127,0,0,0
0,127,5,6,6,6,5,127,0,0,0,0,0,0,0,0,0,0,0,0,0,0,0,0,0,127,5,6,6,6,5,127,0,0
127,5,6,6,6,6,6,5,127,0,0,0,0,127,127,127,127,127,127,127,0,0,0,0,127,5,6,6,6,6,6,5,127,0
5,6,6,6,6,6,6,6,5,127,127,127,127,5,5,5,5,5,5,5,127,127,127,127,5,6,6,6,6,6,6,6,5,127
6,6,6,6,6,6,6,6,6,5,5,5,5,5,5,5,5,5,5,5,5,5,5,5,6,6,6,6,6,6,6,6,6,5
5,6,6,6,6,6,6,6,5,5,5,5,5,5,5,5,5,5,5,5,5,5,5,5,5,6,6,6,6,6,6,6,5,127
127,5,6,6,6,6,6,5,5,5,5,5,5,5,5,5,5,5,5,5,5,5,5,5,5,5,6,6,6,6,6,5,127,0
0,127,5,6,6,6,5,5,5,5,5,5,5,5,5,5,5,5,5,5,5,5,5,5,5,5,5,6,6,6,5,127,0,0
0,0,127,5,6,5,5,5,5,5,5,5,5,5,5,5,5,5,5,5,5,5,5,5,5,5,5,5,6,5,127,0,0,0
0,0,0,127,5,5,5,5,5,5,5,5,5,5,5,5,5,5,5,5,5,5,5,5,5,5,5,5,5,127,0,0,0,0
0,0,0,127,5,5,5,5,5,5,3,3,5,5,5,5,5,5,5,5,5,5,5,5,5,5,5,5,5,127,0,0,0,0
0,0,0,127,5,5,5,5,5,5,3,3,5,5,5,5,5,5,5,5,5,5,5,5,5,5,5,5,5,127,0,0,0,0
0,0,0,127,5,5,5,5,5,5,5,5,5,5,5,8,8,8,5,5,5,5,5,5,5,5,5,5,5,127,0,0,0,0
0,0,127,5,5,5,5,5,5,5,5,5,5,5,8,129,129,129,8,5,5,5,5,5,5,5,5,5,5,5,127,0,0,0
0,0,127,5,5,5,5,5,5,5,5,5,5,8,0,0,0,103,103,8,5,5,5,5,5,5,5,5,5,5,127,0,0,0
0,0,127,5,5,5,5,5,5,5,5,5,8,131,0,0,0,103,103,128,8,5,5,5,5,5,5,5,5,5,127,0,0,0
0,0,127,5,5,5,5,5,5,5,5,5,8,131,0,0,0,0,0,128,8,5,5,5,5,5,5,5,5,5,127,0,0,0
0,0,127,5,5,5,5,5,5,5,5,5,8,131,0,0,0,0,0,128,8,5,5,5,5,5,5,5,5,5,127,0,0,0
0,0,127,5,5,5,5,5,5,5,5,5,5,8,0,0,0,0,0,8,5,5,5,5,5,5,5,5,5,5,127,0,0,0
0,0,127,5,5,5,5,5,5,5,5,5,5,5,8,130,130,130,8,5,5,5,5,5,5,5,5,5,5,5,127,0,0,0
0,0,0,127,5,5,5,5,5,5,5,5,5,5,5,8,8,8,5,5,5,5,5,5,5,5,5,5,5,127,0,0,0,0
0,0,0,127,5,5,5,5,5,5,5,5,5,5,5,5,5,5,5,5,5,5,5,5,5,5,5,5,5,127,0,0,0,0
0,0,0,127,5,5,5,5,5,5,5,5,5,5,5,5,5,5,5,5,5,5,5,5,5,5,5,5,5,127,0,0,0,0
0,0,0,127,5,5,5,5,5,5,5,5,5,5,5,5,5,5,5,5,5,5,5,5,5,5,5,5,5,127,0,0,0,0
0,0,127,5,6,5,5,5,5,5,5,5,5,5,5,5,5,5,5,5,5,5,5,5,5,5,5,5,6,5,127,0,0,0
0,127,5,6,6,6,5,5,5,5,5,5,5,5,5,5,5,5,5,5,5,5,5,5,5,5,5,6,6,6,5,127,0,0
127,5,6,6,6,6,6,5,5,5,5,5,5,5,5,5,5,5,5,5,5,5,5,5,5,5,6,6,6,6,6,5,127,0
5,6,6,6,6,6,6,6,5,5,5,5,5,5,5,5,5,5,5,5,5,5,5,5,5,6,6,6,6,6,6,6,5,127
6,6,6,6,6,6,6,6,6,5,5,5,5,5,5,5,5,5,5,5,5,5,5,5,6,6,6,6,6,6,6,6,6,5
5,6,6,6,6,6,6,6,5,127,127,127,127,5,5,5,5,5,5,5,127,127,127,127,5,6,6,6,6,6,6,6,5,127
127,5,6,6,6,6,6,5,127,0,0,0,0,127,127,127,127,127,127,127,0,0,0,0,127,5,6,6,6,6,6,5,127,0
0,127,5,6,6,6,5,127,0,0,0,0,0,0,0,0,0,0,0,0,0,0,0,0,0,127,5,6,6,6,5,127,0,0
0,0,127,5,6,5,127,0,0,0,0,0,0,0,0,0,0,0,0,0,0,0,0,0,0,0,127,5,6,5,127,0,0,0
0,0,0,127,5,127,0,0,0,0,0,0,0,0,0,0,0,0,0,0,0,0,0,0,0,0,0,127,5,127,0,0,0,0
:endlayer
layer: 17
0,0,0,127,127,127,0,0,0,0,0,0,0,0,0,0,0,0,0,0,0,0,0,0,0,0,0,127,127,127,0,0,0,0
0,127,127,127,127,127,127,0,0,0,0,0,0,0,0,0,0,0,0,0,0,0,0,0,0,0,127,127,127,127,127,0,0,0
0,127,127,127,127,127,127,127,0,0,0,0,0,0,0,0,0,0,0,0,0,0,0,0,0,127,127,127,127,127,127,127,0,0
127,127,127,127,127,127,127,127,127,0,0,0,127,127,127,127,127,127,127,127,127,0,0,0,127,127,127,127,127,127,127,127,127,0
127,127,127,127,127,127,127,127,127,3,127,127,127,127,127,127,127,127,127,127,127,127,127,3,127,127,127,127,127,127,127,127,127,127
127,127,127,127,127,127,127,127,5,0,5,127,127,127,127,127,127,127,127,127,127,127,5,0,5,127,127,127,127,127,127,127,127,0
0,127,127,127,127,127,127,5,0,0,0,5,127,127,127,127,127,127,127,127,127,5,0,0,0,5,127,127,127,127,127,127,0,0
0,0,127,127,127,127,5,0,0,0,0,0,5,5,5,5,5,5,5,5,5,0,0,0,0,0,5,127,127,127,127,0,0,0
0,0,0,127,127,5,0,0,0,0,0,0,0,93,93,93,93,93,93,93,0,0,0,0,0,0,0,5,127,127,0,0,0,0
0,0,0,0,3,0,0,0,0,0,0,0,0,93,93,93,93,93,93,93,0,0,0,0,0,0,0,0,3,0,0,0,0,0
0,0,0,0,127,5,0,0,0,0,3,3,0,93,93,93,93,93,93,93,0,3,3,0,0,0,0,5,127,0,0,0,0,0
0,0,0,0,127,127,5,0,0,0,3,3,139,93,93,138,138,138,93,93,135,3,3,0,0,0,5,127,127,0,0,0,0,0
0,0,0,127,127,127,127,5,0,0,0,140,0,96,94,94,0,94,94,96,0,134,0,0,0,5,127,127,127,127,0,0,0,0
0,0,0,127,127,127,127,5,0,0,0,0,0,0,0,0,0,0,0,0,0,0,0,0,0,5,127,127,127,127,0,0,0,0
0,0,0,127,127,127,127,5,0,132,133,132,0,0,0,0,0,0,0,0,0,132,133,132,0,5,127,127,127,127,0,0,0,0
0,0,0,127,127,127,127,5,0,132,133,132,0,0,0,0,0,0,0,0,0,132,133,132,0,5,127,127,127,127,0,0,0,0
0,0,0,127,127,127,127,5,0,132,133,132,0,0,0,0,0,103,103,0,0,132,133,132,0,5,127,127,127,127,0,0,0,0
0,0,0,127,127,127,127,5,0,132,133,132,0,0,0,0,0,0,0,0,0,132,133,132,0,5,127,127,127,127,0,0,0,0
0,0,0,127,127,127,127,5,0,132,133,132,0,0,0,0,0,0,0,0,0,132,133,132,0,5,127,127,127,127,0,0,0,0
0,0,0,127,127,127,127,5,0,0,0,0,0,0,0,0,0,0,0,0,0,0,0,0,0,5,127,127,127,127,0,0,0,0
0,0,0,127,127,127,127,5,0,141,0,0,0,0,0,0,0,0,0,0,0,0,0,0,0,5,127,127,127,127,0,0,0,0
0,0,0,0,127,127,5,0,0,0,3,3,0,0,137,137,137,137,137,136,0,3,3,0,0,0,5,127,127,0,0,0,0,0
0,0,0,0,127,5,0,0,0,0,3,3,0,0,133,133,133,133,133,0,0,3,3,0,0,0,0,5,127,0,0,0,0,0
0,0,0,0,3,0,0,0,0,0,0,0,0,0,137,137,137,137,137,0,0,0,0,0,0,0,0,0,3,0,0,0,0,0
0,0,0,127,127,5,0,0,0,0,0,0,0,0,0,0,0,0,0,0,0,0,0,0,0,0,0,5,127,127,0,0,0,0
0,0,127,127,127,127,5,0,0,0,0,0,5,5,5,5,5,5,5,5,5,0,0,0,0,0,5,127,127,127,127,0,0,0
0,127,127,127,127,127,127,5,0,0,0,5,127,127,127,127,127,127,127,127,127,5,0,0,0,5,127,127,127,127,127,127,0,0
127,127,127,127,127,127,127,127,5,0,5,127,127,127,127,127,127,127,127,127,127,127,5,0,5,127,127,127,127,127,127,127,127,0
127,127,127,127,127,127,127,127,127,3,127,127,127,127,127,127,127,127,127,127,127,127,127,3,127,127,127,127,127,127,127,127,127,127
127,127,127,127,127,127,127,127,127,0,0,0,127,127,127,127,127,127,127,127,127,0,0,0,127,127,127,127,127,127,127,127,127,0
0,127,127,127,127,127,127,127,0,0,0,0,0,0,0,0,0,0,0,0,0,0,0,0,0,127,127,127,127,127,127,127,0,0
0,0,127,127,127,127,127,0,0,0,0,0,0,0,0,0,0,0,0,0,0,0,0,0,0,0,127,127,127,127,127,0,0,0
0,0,0,127,127,127,0,0,0,0,0,0,0,0,0,0,0,0,0,0,0,0,0,0,0,0,0,127,127,127,0,0,0,0
0,0,0,0,127,0,0,0,0,0,0,0,0,0,0,0,0,0,0,0,0,0,0,0,0,0,0,0,127,0,0,0,0,0
:endlayer
layer: 18
0,0,0,127,127,0,0,0,0,0,0,0,0,0,0,0,0,0,0,0,0,0,0,0,0,0,0,0,127,0,0,0,0,0
0,127,0,127,127,127,0,0,0,0,0,0,0,0,0,0,0,0,0,0,0,0,0,0,0,0,0,127,127,127,0,0,0,0
0,0,127,127,127,127,127,0,0,0,0,0,0,0,0,0,0,0,0,0,0,0,0,0,0,0,127,127,127,127,127,0,0,0
0,127,127,127,127,127,127,127,0,0,0,0,0,0,0,0,0,0,0,0,0,0,0,0,0,127,127,127,127,127,127,127,127,0
127,127,127,127,127,127,127,127,127,3,0,127,127,127,127,127,127,127,127,127,127,127,0,3,127,127,127,127,127,127,127,127,127,0
0,127,127,127,127,127,127,127,5,0,5,127,127,127,127,127,127,127,127,127,127,127,5,0,5,127,127,127,127,127,127,127,0,0
0,0,127,127,127,127,127,5,0,0,0,5,127,127,127,127,127,127,127,127,127,5,0,0,0,5,127,127,127,127,127,0,0,0
0,0,0,127,127,127,5,0,0,0,0,0,5,5,5,5,5,5,5,5,5,0,0,0,0,0,5,127,127,127,0,0,0,0
0,0,0,0,127,5,0,0,0,0,0,0,0,93,93,93,5,93,93,93,0,0,0,0,0,0,0,5,127,0,0,0,0,0
0,0,0,0,3,0,0,0,0,0,0,0,0,93,93,5,143,5,93,93,0,0,0,0,0,0,0,0,3,0,0,0,0,0
0,0,0,0,0,5,0,0,0,0,3,3,0,94,94,94,94,94,94,94,0,3,3,0,0,0,0,5,0,0,0,0,0,0
0,0,0,0,127,127,5,0,0,0,3,3,0,0,0,0,0,0,0,0,0,3,3,0,0,0,5,127,127,0,0,0,0,0
0,0,0,0,127,127,127,5,0,0,0,0,0,0,0,0,0,0,0,0,0,0,0,0,0,5,127,127,127,0,0,0,0,0
0,0,0,0,127,127,127,5,0,0,0,0,0,0,0,0,0,0,0,0,0,0,0,0,0,5,127,127,127,0,0,0,0,0
0,0,0,0,127,127,127,5,0,0,0,0,0,0,0,0,0,0,0,0,0,0,0,0,0,5,127,127,127,0,0,0,0,0
0,0,0,0,127,127,127,5,0,0,0,0,0,0,0,0,0,0,0,0,0,0,142,0,0,5,127,127,127,0,0,0,0,0
0,0,0,0,127,127,127,5,0,0,145,0,0,0,0,0,0,0,0,0,0,0,0,0,0,5,127,127,127,0,0,0,0,0
0,0,0,0,127,127,127,5,0,0,0,0,0,0,0,0,0,103,103,0,0,0,0,0,0,5,127,127,127,0,0,0,0,0
0,0,0,0,127,127,127,5,0,0,0,0,0,0,0,0,0,103,103,0,0,0,0,0,0,5,127,127,127,0,0,0,0,0
0,0,0,0,127,127,127,5,0,0,0,0,0,0,0,0,0,0,0,0,0,0,0,0,0,5,127,127,127,0,0,0,0,0
0,0,0,0,127,127,127,5,0,0,0,0,0,0,0,0,0,0,0,0,0,0,0,0,0,5,127,127,127,0,0,0,0,0
0,0,0,0,127,127,5,0,0,0,3,3,0,0,0,0,0,0,0,0,0,3,3,0,0,0,5,127,127,0,0,0,0,0
0,0,0,0,0,5,0,0,0,0,3,3,0,0,0,0,144,0,0,0,0,3,3,0,0,0,0,5,0,0,0,0,0,0
0,0,0,0,3,0,0,0,0,0,0,0,0,0,0,0,0,0,0,0,0,0,0,0,0,0,0,0,3,0,0,0,0,0
0,0,0,0,127,5,0,0,0,0,0,0,0,0,0,0,0,0,0,0,0,0,0,0,0,0,0,5,127,0,0,0,0,0
0,0,0,127,127,127,5,0,0,0,0,0,5,5,5,5,5,5,5,5,5,0,0,0,0,0,5,127,127,127,0,0,0,0
0,0,127,127,127,127,127,5,0,0,0,5,127,127,127,127,127,127,127,127,127,5,0,0,0,5,127,127,127,127,127,0,0,0
0,127,127,127,127,127,127,127,5,0,5,127,127,127,127,127,127,127,127,127,127,127,5,0,5,127,127,127,127,127,127,127,0,0
127,127,127,127,127,127,127,127,127,3,0,127,127,127,127,127,127,127,127,127,127,127,0,3,127,127,127,127,127,127,127,127,127,0
127,127,127,127,127,127,127,127,0,0,0,0,0,0,0,0,0,0,0,0,0,0,0,0,0,127,127,127,127,127,127,127,0,0
0,0,127,127,127,127,127,0,0,0,0,0,0,0,0,0,0,0,0,0,0,0,0,0,0,0,127,127,127,127,127,0,0,0
0,0,0,127,127,127,0,0,0,0,0,0,0,0,0,0,0,0,0,0,0,0,0,0,0,0,0,127,127,127,0,0,0,0
0,0,0,0,127,0,0,0,0,0,0,0,0,0,0,0,0,0,0,0,0,0,0,0,0,0,0,0,127,127,0,0,0,0
0,0,0,0,0,0,0,0,0,0,0,0,0,0,0,0,0,0,0,0,0,0,0,0,0,0,0,0,0,0,0,0,0,0
:endlayer
layer: 19
0,0,0,0,127,0,0,0,0,0,0,0,0,0,0,0,0,0,0,0,0,0,0,0,0,0,0,0,0,0,0,0,0,0
0,127,0,0,127,0,0,0,0,0,0,0,0,0,0,0,0,0,0,0,0,0,0,0,0,0,0,0,127,0,0,0,0,0
0,0,0,127,127,127,0,0,0,0,0,0,0,0,0,0,0,0,0,0,0,0,0,0,0,0,0,127,127,127,0,0,0,0
0,0,127,127,127,127,127,0,0,0,0,0,0,0,0,0,0,0,0,0,0,0,0,0,0,0,127,127,127,127,127,0,0,0
0,127,127,127,127,127,127,127,0,3,0,0,0,0,0,0,0,0,0,0,0,0,0,3,0,127,127,127,127,127,127,127,127,0
0,0,127,127,127,127,127,127,5,0,5,127,127,127,127,127,127,127,127,127,127,127,5,0,5,127,127,127,127,127,127,0,0,0
0,0,0,127,127,127,127,5,0,0,0,5,127,127,127,127,127,127,127,127,127,5,0,0,0,5,127,127,127,127,0,0,0,0
0,0,0,0,127,127,5,0,0,0,0,0,5,5,5,5,5,5,5,5,5,0,0,0,0,0,5,127,127,0,0,0,0,0
0,0,0,0,0,5,0,0,0,0,0,0,0,0,0,5,5,5,0,0,0,0,0,0,0,0,0,5,0,0,0,0,0,0
0,0,0,0,3,0,0,0,0,0,0,0,0,149,0,10,147,14,0,146,0,0,0,0,0,0,0,0,3,0,0,0,0,0
0,0,0,0,0,5,0,0,0,0,3,3,0,0,0,0,148,0,0,0,0,3,3,0,0,0,0,5,0,0,0,0,0,0
0,0,0,0,0,127,5,0,0,0,3,3,0,0,0,0,0,0,0,0,0,3,3,0,0,0,5,127,0,0,0,0,0,0
0,0,0,0,0,127,127,5,0,0,0,0,0,0,0,0,0,0,0,0,0,0,0,0,0,5,127,127,0,0,0,0,0,0
0,0,0,0,0,127,127,5,0,0,0,0,0,0,0,0,0,0,0,0,0,0,0,0,0,5,127,127,0,0,0,0,0,0
0,0,0,0,0,127,127,5,0,0,0,0,0,0,0,0,0,0,0,0,0,0,0,0,0,5,127,127,0,0,0,0,0,0
0,0,0,0,0,127,127,5,0,0,0,0,0,0,0,0,0,0,0,0,0,0,0,0,0,5,127,127,0,0,0,0,0,0
0,0,0,0,0,127,127,5,0,0,0,0,0,0,0,0,0,0,0,0,0,0,0,0,0,5,127,127,0,0,0,0,0,0
0,0,0,0,0,127,127,5,0,0,0,0,0,0,0,0,103,0,0,0,0,0,0,0,0,5,127,127,0,0,0,0,0,0
0,0,0,0,0,127,127,5,0,0,0,0,0,0,0,0,103,0,0,0,0,0,0,0,0,5,127,127,0,0,0,0,0,0
0,0,0,0,0,127,127,5,0,0,0,0,0,0,0,0,0,0,0,0,0,0,0,0,0,5,127,127,0,0,0,0,0,0
0,0,0,0,0,127,127,5,0,0,0,0,0,0,0,0,0,0,0,0,0,0,0,0,0,5,127,127,0,0,0,0,0,0
0,0,0,0,0,127,5,0,0,0,3,3,0,0,0,0,0,0,0,0,0,3,3,0,0,0,5,127,0,0,0,0,0,0
0,0,0,0,0,5,0,0,0,0,3,3,0,0,0,0,0,0,0,0,0,3,3,0,0,0,0,5,0,0,0,0,0,0
0,0,0,0,3,0,0,0,0,0,0,0,0,0,0,0,0,0,0,0,0,0,0,0,0,0,0,0,3,0,0,0,0,0
0,0,0,0,0,5,0,0,0,0,0,0,0,0,0,0,0,0,0,0,0,0,0,0,0,0,0,5,0,0,0,0,0,0
0,0,0,0,127,127,5,0,0,0,0,0,5,5,5,5,5,5,5,5,5,0,0,0,0,0,5,127,127,0,0,0,0,0
0,0,0,127,127,127,127,5,0,0,0,5,127,127,127,127,127,127,127,127,127,5,0,0,0,5,127,127,127,127,0,0,0,0
0,0,127,127,127,127,127,127,5,0,5,127,127,127,127,127,127,127,127,127,127,127,5,0,5,127,127,127,127,127,127,0,0,0
127,127,127,127,127,127,127,127,0,3,0,0,0,0,0,0,0,0,0,0,0,0,0,3,0,127,127,127,127,127,127,127,0,0
0,0,127,127,127,127,127,0,0,0,0,0,0,0,0,0,0,0,0,0,0,0,0,0,0,0,127,127,127,127,127,0,0,0
0,0,0,127,127,127,0,0,0,0,0,0,0,0,0,0,0,0,0,0,0,0,0,0,0,0,0,127,127,127,0,0,0,0
0,0,0,0,127,0,0,0,0,0,0,0,0,0,0,0,0,0,0,0,0,0,0,0,0,0,0,0,127,0,0,0,0,0
0,0,0,0,0,0,0,0,0,0,0,0,0,0,0,0,0,0,0,0,0,0,0,0,0,0,0,0,127,0,0,0,0,0
0,0,0,0,0,0,0,0,0,0,0,0,0,0,0,0,0,0,0,0,0,0,0,0,0,0,0,0,0,0,0,0,0,0
:endlayer
layer: 20
0,0,0,0,0,0,0,0,0,0,0,0,0,0,0,0,0,0,0,0,0,0,0,0,0,0,0,0,0,0,0,0,0,0
0,127,0,0,0,0,0,0,0,0,0,0,0,0,0,0,0,0,0,0,0,0,0,0,0,0,0,0,0,0,0,0,0,0
0,0,0,0,127,0,0,0,0,0,0,0,0,0,0,0,0,0,0,0,0,0,0,0,0,0,0,0,127,0,0,0,0,0
0,0,0,127,127,127,0,0,0,0,0,0,0,0,0,0,0,0,0,0,0,0,0,0,0,0,0,127,127,127,0,0,0,0
0,0,127,127,127,127,127,0,0,3,0,0,0,0,0,0,0,0,0,0,0,0,0,3,0,0,127,127,127,127,127,0,0,0
0,0,0,127,127,127,127,127,5,0,5,0,0,0,0,0,0,0,0,0,0,0,5,0,5,127,127,127,127,127,0,0,0,0
0,0,0,0,127,127,127,5,0,0,0,5,11,11,11,11,11,11,11,11,11,5,0,0,0,5,127,127,127,0,0,0,0,0
0,0,0,0,0,127,5,0,0,0,0,0,5,5,5,5,5,5,5,5,5,0,0,0,0,0,5,127,0,0,0,0,0,0
0,0,0,0,0,5,0,0,0,0,0,0,0,0,19,18,5,19,18,0,0,0,0,0,0,0,0,5,0,0,0,0,0,0
0,0,0,0,3,0,0,0,0,0,0,0,0,0,0,0,0,0,0,0,0,0,0,0,0,0,0,0,3,0,0,0,0,0
0,0,0,0,0,5,0,0,0,0,3,3,0,0,0,0,0,0,0,0,0,3,3,0,0,0,0,5,0,0,0,0,0,0
0,0,0,0,0,0,5,0,0,0,3,3,0,0,0,0,0,0,0,0,0,3,3,0,0,0,5,0,0,0,0,0,0,0
0,0,0,0,0,0,14,5,0,0,0,0,0,0,0,0,0,0,0,0,0,0,0,0,0,5,10,0,0,0,0,0,0,0
0,0,0,0,0,0,14,5,0,0,0,0,0,0,0,0,0,0,0,0,0,0,0,0,0,5,10,0,0,0,0,0,0,0
0,0,0,0,0,0,14,5,0,0,0,0,0,0,0,0,0,0,0,0,0,0,0,0,0,5,10,0,0,0,0,0,0,0
0,0,0,0,0,0,14,5,0,0,0,0,0,0,0,0,0,0,0,0,0,0,0,0,0,5,10,0,0,0,0,0,0,0
0,0,0,0,0,0,14,5,0,0,0,0,0,0,0,0,0,0,0,0,0,0,0,0,0,5,10,0,0,0,0,0,0,0
0,0,0,0,0,0,14,5,0,0,0,0,0,0,103,103,0,0,0,0,0,0,0,0,0,5,10,0,0,0,0,0,0,0
0,0,0,0,0,0,14,5,0,0,0,0,0,0,103,103,0,0,0,0,0,0,0,0,0,5,10,0,0,0,0,0,0,0
0,0,0,0,0,0,14,5,0,0,0,0,0,0,0,0,0,0,0,0,0,0,0,0,0,5,10,0,0,0,0,0,0,0
0,0,0,0,0,0,14,5,0,0,0,0,0,0,0,0,0,0,0,0,0,0,0,0,0,5,10,0,0,0,0,0,0,0
0,0,0,0,0,0,5,0,0,0,3,3,0,0,0,0,0,0,0,0,0,3,3,0,0,0,5,0,0,0,0,0,0,0
0,0,0,0,0,5,0,0,0,0,3,3,0,0,0,0,0,0,0,0,0,3,3,0,0,0,0,5,0,0,0,0,0,0
0,0,0,0,3,0,0,0,0,0,0,0,0,0,0,0,0,0,0,0,0,0,0,0,0,0,0,0,3,0,0,0,0,0
0,0,0,0,0,5,0,0,0,0,0,0,0,0,0,0,0,0,0,0,0,0,0,0,0,0,0,5,0,0,0,0,0,0
0,0,0,0,0,127,5,0,0,0,0,0,5,5,5,5,5,5,5,5,5,0,0,0,0,0,5,127,0,0,0,0,0,0
0,0,0,0,127,127,127,5,0,0,0,5,12,12,12,12,12,12,12,12,12,5,0,0,0,5,127,127,127,0,0,0,0,0
0,0,0,127,127,127,127,127,5,0,5,0,0,0,0,0,0,0,0,0,0,0,5,0,5,127,127,127,127,127,0,0,0,0
0,0,127,127,127,127,127,0,0,3,0,0,0,0,0,0,0,0,0,0,0,0,0,3,0,0,127,127,127,127,127,0,0,0
0,0,0,127,127,127,0,0,0,0,0,0,0,0,0,0,0,0,0,0,0,0,0,0,0,0,0,127,127,127,0,0,0,0
0,0,0,0,127,0,0,0,0,0,0,0,0,0,0,0,0,0,0,0,0,0,0,0,0,0,0,0,127,0,0,0,0,0
0,0,0,0,0,0,0,0,0,0,0,0,0,0,0,0,0,0,0,0,0,0,0,0,0,0,0,0,0,0,0,0,0,0
0,0,0,0,0,0,0,0,0,0,0,0,0,0,0,0,0,0,0,0,0,0,0,0,0,0,0,0,0,0,0,0,0,0
0,0,0,0,0,0,0,0,0,0,0,0,0,0,0,0,0,0,0,0,0,0,0,0,0,0,0,0,0,0,0,0,0,0
:endlayer
layer: 21
127,127,0,0,0,0,0,0,0,0,0,0,0,0,0,0,0,0,0,0,0,0,0,0,0,0,0,0,0,0,0,0,0,0
127,127,0,0,0,0,0,0,0,0,0,0,0,0,0,0,0,0,0,0,0,0,0,0,0,0,0,0,0,0,0,0,0,0
0,0,0,0,0,0,0,0,0,0,0,0,0,0,0,0,0,0,0,0,0,0,0,0,0,0,0,0,0,0,0,0,0,0
0,0,0,0,0,0,0,0,0,0,0,0,0,0,0,0,0,0,0,0,0,0,0,0,0,0,0,0,0,0,0,0,0,0
0,0,0,0,0,0,0,150,150,3,150,150,0,0,0,0,0,0,0,0,0,150,150,3,150,150,0,0,0,0,0,0,0,0
0,0,0,0,0,0,150,150,5,0,5,150,150,0,0,0,0,0,0,0,150,150,5,0,5,150,150,0,0,0,0,0,0,0
0,0,0,0,0,150,150,5,0,0,0,5,16,3,16,3,16,3,16,3,16,5,0,0,0,5,150,150,0,0,0,0,0,0
0,0,0,0,150,150,5,0,0,0,0,0,5,5,5,5,5,5,5,5,5,0,0,0,0,0,5,150,150,0,0,0,0,0
0,0,0,0,150,5,0,0,0,0,0,0,0,0,18,9,0,9,19,0,0,0,0,0,0,0,0,5,150,0,0,0,0,0
0,0,0,0,3,0,0,0,0,0,0,0,0,0,0,0,0,0,0,0,0,0,0,0,0,0,0,0,3,0,0,0,0,0
0,0,0,0,150,5,0,0,0,0,3,3,0,0,0,0,0,0,0,0,0,3,3,0,0,0,0,5,150,0,0,0,0,0
0,0,0,0,150,150,5,0,0,0,3,3,0,0,0,0,0,0,0,0,0,3,3,0,0,0,5,150,150,0,0,0,0,0
0,0,0,0,0,150,18,5,0,0,0,0,0,0,0,0,0,0,0,0,0,0,0,0,0,5,19,150,0,0,0,0,0,0
0,0,0,0,0,0,3,5,0,0,0,0,0,0,0,0,0,0,0,0,0,0,0,0,0,5,3,0,0,0,0,0,0,0
0,0,0,0,0,0,18,5,0,0,0,0,0,0,0,0,0,0,0,0,0,0,0,0,0,5,19,0,0,0,0,0,0,0
0,0,0,0,0,0,3,5,0,0,0,0,0,0,0,0,0,0,0,0,0,0,0,0,0,5,3,0,0,0,0,0,0,0
0,0,0,0,0,0,18,5,0,0,0,0,0,0,103,103,0,0,0,0,0,0,0,0,0,5,19,0,0,0,0,0,0,0
0,0,0,0,0,0,3,5,0,0,0,0,0,0,0,0,0,0,0,0,0,0,0,0,0,5,3,0,0,0,0,0,0,0
0,0,0,0,0,0,18,5,0,0,0,0,0,0,0,0,0,0,0,0,0,0,0,0,0,5,19,0,0,0,0,0,0,0
0,0,0,0,0,0,3,5,0,0,0,0,0,0,0,0,0,0,0,0,0,0,0,0,0,5,3,0,0,0,0,0,0,0
0,0,0,0,0,150,18,5,0,0,0,0,0,0,0,0,0,0,0,0,0,0,0,0,0,5,19,150,0,0,0,0,0,0
0,0,0,0,150,150,5,0,0,0,3,3,0,0,0,0,0,0,0,0,0,3,3,0,0,0,5,150,150,0,0,0,0,0
0,0,0,0,150,5,0,0,0,0,3,3,0,0,0,0,0,0,0,0,0,3,3,0,0,0,0,5,150,0,0,0,0,0
0,0,0,0,3,0,0,0,0,0,0,0,0,0,0,0,0,0,0,0,0,0,0,0,0,0,0,0,3,0,0,0,0,0
0,0,0,0,150,5,0,0,0,0,0,0,0,0,0,0,0,0,0,0,0,0,0,0,0,0,0,5,150,0,0,0,0,0
0,0,0,0,150,150,5,0,0,0,0,0,5,5,5,5,5,5,5,5,5,0,0,0,0,0,5,150,150,0,0,0,0,0
0,0,0,0,0,150,150,5,0,0,0,5,17,3,17,3,17,3,17,3,17,5,0,0,0,5,150,150,0,0,0,0,0,0
0,0,0,0,0,0,150,150,5,0,5,150,150,0,0,0,0,0,0,0,150,150,5,0,5,150,150,0,0,0,0,0,0,0
0,0,0,0,0,0,0,150,150,3,150,150,0,0,0,0,0,0,0,0,0,150,150,3,150,150,0,0,0,0,0,0,0,0
0,0,0,0,0,0,0,0,0,0,0,0,0,0,0,0,0,0,0,0,0,0,0,0,0,0,0,0,0,0,0,0,0,0
0,0,0,0,0,0,0,0,0,0,0,0,0,0,0,0,0,0,0,0,0,0,0,0,0,0,0,0,0,0,0,0,0,0
0,0,0,0,0,0,0,0,0,0,0,0,0,0,0,0,0,0,0,0,0,0,0,0,0,0,0,0,0,0,0,0,0,0
0,0,0,0,0,0,0,0,0,0,0,0,0,0,0,0,0,0,0,0,0,0,0,0,0,0,0,0,0,0,0,0,0,0
0,0,0,0,0,0,0,0,0,0,0,0,0,0,0,0,0,0,0,0,0,0,0,0,0,0,0,0,0,0,0,0,0,0
:endlayer
layer: 22
127,0,0,0,0,0,0,0,0,0,0,0,0,0,0,0,0,0,0,0,0,0,0,0,0,0,0,0,0,0,0,0,0,0
0,127,0,0,0,0,0,0,0,0,0,0,0,0,0,0,0,0,0,0,0,0,0,0,0,0,0,0,0,0,0,0,0,0
0,0,0,0,0,0,0,0,0,0,0,0,0,0,0,0,0,0,0,0,0,0,0,0,0,0,0,0,0,0,0,0,0,0
0,0,0,0,0,0,0,0,0,0,0,0,0,0,0,0,0,0,0,0,0,0,0,0,0,0,0,0,0,0,0,0,0,0
0,0,0,0,0,0,0,151,0,3,0,151,0,0,0,0,0,0,0,0,0,151,0,3,0,151,0,0,0,0,0,0,0,0
0,0,0,0,0,0,16,16,5,0,5,0,0,0,0,0,0,0,0,0,0,0,5,0,5,16,19,0,0,0,0,0,0,0
0,0,0,0,0,16,18,5,0,0,0,5,0,3,0,3,0,3,0,3,0,5,0,0,0,5,16,19,0,0,0,0,0,0
0,0,0,0,151,18,5,0,0,0,0,0,5,5,5,5,5,5,5,5,5,0,0,0,0,0,5,19,151,0,0,0,0,0
0,0,0,0,0,5,0,0,0,0,0,0,0,12,8,8,12,8,8,12,0,0,0,0,0,0,0,5,0,0,0,0,0,0
0,0,0,0,3,0,0,0,0,0,0,0,0,0,0,0,0,0,0,0,0,0,0,0,0,0,0,0,3,0,0,0,0,0
0,0,0,0,0,5,0,0,0,0,3,3,0,0,0,0,0,0,0,0,0,3,3,0,0,0,0,5,0,0,0,0,0,0
0,0,0,0,151,0,5,0,0,0,3,3,0,0,0,0,0,0,0,0,0,3,3,0,0,0,5,0,151,0,0,0,0,0
0,0,0,0,0,0,0,5,0,0,0,0,0,0,0,0,0,0,0,0,0,0,0,0,0,5,0,0,0,0,0,0,0,0
0,0,0,0,0,0,3,5,10,0,0,0,0,0,0,0,0,0,0,0,0,0,0,0,14,5,3,0,0,0,0,0,0,0
0,0,0,0,0,0,0,5,8,0,0,0,0,0,103,103,0,0,0,0,0,0,0,0,8,5,0,0,0,0,0,0,0,0
0,0,0,0,0,0,3,5,8,0,0,0,0,0,103,103,0,0,0,0,0,0,0,0,8,5,3,0,0,0,0,0,0,0
0,0,0,0,0,0,0,5,10,0,0,0,0,0,0,0,0,0,0,0,0,0,0,0,14,5,0,0,0,0,0,0,0,0
0,0,0,0,0,0,3,5,8,0,0,0,0,0,0,0,0,0,0,0,0,0,0,0,8,5,3,0,0,0,0,0,0,0
0,0,0,0,0,0,0,5,8,0,0,0,0,0,0,0,0,0,0,0,0,0,0,0,8,5,0,0,0,0,0,0,0,0
0,0,0,0,0,0,3,5,10,0,0,0,0,0,0,0,0,0,0,0,0,0,0,0,14,5,3,0,0,0,0,0,0,0
0,0,0,0,0,0,0,5,0,0,0,0,0,0,0,0,0,0,0,0,0,0,0,0,0,5,0,0,0,0,0,0,0,0
0,0,0,0,151,0,5,0,0,0,3,3,0,0,0,0,0,0,0,0,0,3,3,0,0,0,5,0,151,0,0,0,0,0
0,0,0,0,0,5,0,0,0,0,3,3,0,0,0,0,0,0,0,0,0,3,3,0,0,0,0,5,0,0,0,0,0,0
0,0,0,0,3,0,0,0,0,0,0,0,0,0,0,0,0,0,0,0,0,0,0,0,0,0,0,0,3,0,0,0,0,0
0,0,0,0,0,5,0,0,0,0,0,0,0,11,8,8,11,8,8,11,0,0,0,0,0,0,0,5,0,0,0,0,0,0
0,0,0,0,151,18,5,0,0,0,0,0,5,5,5,5,5,5,5,5,5,0,0,0,0,0,5,19,151,0,0,0,0,0
0,0,0,0,0,18,17,5,0,0,0,5,0,3,0,3,0,3,0,3,0,5,0,0,0,5,19,17,0,0,0,0,0,0
0,0,0,0,0,0,18,17,5,0,5,0,0,0,0,0,0,0,0,0,0,0,5,0,5,17,17,0,0,0,0,0,0,0
0,0,0,0,0,0,0,151,0,3,0,151,0,0,0,0,0,0,0,0,0,151,0,3,0,151,0,0,0,0,0,0,0,0
0,0,0,0,0,0,0,0,0,0,0,0,0,0,0,0,0,0,0,0,0,0,0,0,0,0,0,0,0,0,0,0,0,0
0,0,0,0,0,0,0,0,0,0,0,0,0,0,0,0,0,0,0,0,0,0,0,0,0,0,0,0,0,0,0,0,0,0
0,0,0,0,0,0,0,0,0,0,0,0,0,0,0,0,0,0,0,0,0,0,0,0,0,0,0,0,0,0,0,0,0,0
0,0,0,0,0,0,0,0,0,0,0,0,0,0,0,0,0,0,0,0,0,0,0,0,0,0,0,0,0,0,0,0,0,0
0,0,0,0,0,0,0,0,0,0,0,0,0,0,0,0,0,0,0,0,0,0,0,0,0,0,0,0,0,0,0,0,0,0
:endlayer
layer: 23
127,0,0,0,0,0,0,0,0,0,0,0,0,0,0,0,0,0,0,0,0,0,0,0,0,0,0,0,0,0,0,0,0,0
0,0,0,0,0,0,0,0,0,0,0,0,0,0,0,0,0,0,0,0,0,0,0,0,0,0,0,0,0,0,0,0,0,0
0,0,0,0,0,0,0,0,0,0,0,0,0,0,0,0,0,0,0,0,0,0,0,0,0,0,0,0,0,0,0,0,0,0
0,0,0,0,0,0,0,0,0,0,0,0,0,0,0,0,0,0,0,0,0,0,0,0,0,0,0,0,0,0,0,0,0,0
0,0,0,0,0,0,0,151,0,3,0,151,0,0,0,0,0,0,0,0,0,151,0,3,0,151,0,0,0,0,0,0,0,0
0,0,0,0,0,0,0,157,5,0,5,0,0,0,0,0,0,0,0,0,0,0,5,0,5,155,0,0,0,0,0,0,0,0
0,0,0,0,0,0,0,154,0,0,0,5,0,3,0,3,0,3,0,3,0,5,0,0,0,154,0,0,0,0,0,0,0,0
0,0,0,0,151,159,154,0,0,0,0,0,5,5,11,5,11,5,11,5,5,0,0,0,0,0,154,152,151,0,0,0,0,0
0,0,0,0,0,5,0,0,0,0,0,0,0,17,8,8,125,8,8,17,0,0,0,0,0,0,0,5,0,0,0,0,0,0
0,0,0,0,3,0,0,0,0,0,0,0,0,0,0,0,0,0,0,0,0,0,0,0,0,0,0,0,3,0,0,0,0,0
0,0,0,0,0,5,0,0,0,0,3,3,0,0,0,0,0,0,0,0,0,3,3,0,0,0,0,5,0,0,0,0,0,0
0,0,0,0,151,0,5,0,0,0,3,3,0,0,0,0,0,0,0,0,0,3,3,0,0,0,5,0,151,0,0,0,0,0
0,0,0,0,0,0,0,5,0,0,0,0,0,0,0,0,0,0,0,0,0,0,0,0,0,5,0,0,0,0,0,0,0,0
0,0,0,0,0,0,3,5,19,0,0,0,0,0,0,0,0,0,0,0,0,0,0,0,18,5,3,0,0,0,0,0,0,0
0,0,0,0,0,0,0,14,8,0,0,0,0,0,0,0,103,0,0,0,0,0,0,0,8,10,0,0,0,0,0,0,0,0
0,0,0,0,0,0,3,5,8,0,0,0,0,0,0,0,103,0,0,0,0,0,0,0,8,5,3,0,0,0,0,0,0,0
0,0,0,0,0,0,0,14,125,0,0,0,0,0,0,0,0,0,0,0,0,0,0,0,125,10,0,0,0,0,0,0,0,0
0,0,0,0,0,0,3,5,8,0,0,0,0,0,0,0,0,0,0,0,0,0,0,0,8,5,3,0,0,0,0,0,0,0
0,0,0,0,0,0,0,14,8,0,0,0,0,0,0,0,0,0,0,0,0,0,0,0,8,10,0,0,0,0,0,0,0,0
0,0,0,0,0,0,3,5,19,0,0,0,0,0,0,0,0,0,0,0,0,0,0,0,18,5,3,0,0,0,0,0,0,0
0,0,0,0,0,0,0,5,0,0,0,0,0,0,0,0,0,0,0,0,0,0,0,0,0,5,0,0,0,0,0,0,0,0
0,0,0,0,151,0,5,0,0,0,3,3,0,0,0,0,0,0,0,0,0,3,3,0,0,0,5,0,151,0,0,0,0,0
0,0,0,0,0,5,0,0,0,0,3,3,0,0,0,0,0,0,0,0,0,3,3,0,0,0,0,5,0,0,0,0,0,0
0,0,0,0,3,0,0,0,0,0,0,0,0,0,0,0,0,0,0,0,0,0,0,0,0,0,0,0,3,0,0,0,0,0
0,0,0,0,0,5,0,0,0,0,0,0,0,16,8,8,125,8,8,16,0,0,0,0,0,0,0,5,0,0,0,0,0,0
0,0,0,0,151,160,154,0,0,0,0,0,5,5,12,5,12,5,12,5,5,0,0,0,0,0,154,153,151,0,0,0,0,0
0,0,0,0,0,0,0,154,0,0,0,5,0,3,0,3,0,3,0,3,0,5,0,0,0,154,0,0,0,0,0,0,0,0
0,0,0,0,0,0,0,158,5,0,5,0,0,0,0,0,0,0,0,0,0,0,5,0,5,156,0,0,0,0,0,0,0,0
0,0,0,0,0,0,0,151,0,3,0,151,0,0,0,0,0,0,0,0,0,151,0,3,0,151,0,0,0,0,0,0,0,0
0,0,0,0,0,0,0,0,0,0,0,0,0,0,0,0,0,0,0,0,0,0,0,0,0,0,0,0,0,0,0,0,0,0
0,0,0,0,0,0,0,0,0,0,0,0,0,0,0,0,0,0,0,0,0,0,0,0,0,0,0,0,0,0,0,0,0,0
0,0,0,0,0,0,0,0,0,0,0,0,0,0,0,0,0,0,0,0,0,0,0,0,0,0,0,0,0,0,0,0,0,0
0,0,0,0,0,0,0,0,0,0,0,0,0,0,0,0,0,0,0,0,0,0,0,0,0,0,0,0,0,0,0,0,0,0
0,0,0,0,0,0,0,0,0,0,0,0,0,0,0,0,0,0,0,0,0,0,0,0,0,0,0,0,0,0,0,0,0,0
:endlayer
layer: 24
127,0,0,0,0,0,0,0,0,0,0,0,0,0,0,0,0,0,0,0,0,0,0,0,0,0,0,0,0,0,0,0,0,0
0,0,0,0,0,0,0,0,0,0,0,0,0,0,0,0,0,0,0,0,0,0,0,0,0,0,0,0,0,0,0,0,0,0
0,0,0,0,0,0,0,0,0,0,0,0,0,0,0,0,0,0,0,0,0,0,0,0,0,0,0,0,0,0,0,0,0,0
0,0,0,0,0,0,0,0,0,0,0,0,0,0,0,0,0,0,0,0,0,0,0,0,0,0,0,0,0,0,0,0,0,0
0,0,0,0,0,0,0,151,0,3,0,151,0,0,0,0,0,0,0,0,0,151,0,3,0,151,0,0,0,0,0,0,0,0
0,0,0,0,0,0,0,161,5,0,5,0,0,0,0,0,0,0,0,0,0,0,5,0,5,161,0,0,0,0,0,0,0,0
0,0,0,0,0,0,0,154,0,0,0,5,0,3,0,3,0,3,0,3,0,5,0,0,0,154,0,0,0,0,0,0,0,0
0,0,0,0,151,161,154,0,0,0,0,0,5,5,154,5,154,5,154,5,5,0,0,0,0,0,154,161,151,0,0,0,0,0
0,0,0,0,0,5,0,0,0,0,0,0,0,151,0,0,0,0,0,151,0,0,0,0,0,0,0,5,0,0,0,0,0,0
0,0,0,0,3,0,0,0,0,0,0,0,0,0,0,0,0,0,0,0,0,0,0,0,0,0,0,0,3,0,0,0,0,0
0,0,0,0,0,5,0,0,0,0,3,3,0,0,0,0,0,0,0,0,0,3,3,0,0,0,0,5,0,0,0,0,0,0
0,0,0,0,151,0,5,0,0,0,3,3,0,0,0,0,0,0,0,0,0,3,3,0,0,0,5,0,151,0,0,0,0,0
0,0,0,0,0,0,0,5,0,0,0,0,0,0,0,0,0,0,0,0,0,0,0,0,0,5,0,0,0,0,0,0,0,0
0,0,0,0,0,0,3,5,151,0,0,0,0,0,0,0,0,0,0,0,0,0,0,0,151,5,3,0,0,0,0,0,0,0
0,0,0,0,0,0,0,154,0,0,0,0,0,0,0,0,0,103,103,0,0,0,0,0,0,154,0,0,0,0,0,0,0,0
0,0,0,0,0,0,3,5,0,0,0,0,0,0,0,0,0,103,103,0,0,0,0,0,0,5,3,0,0,0,0,0,0,0
0,0,0,0,0,0,0,154,0,0,0,0,0,0,0,0,0,0,0,0,0,0,0,0,0,154,0,0,0,0,0,0,0,0
0,0,0,0,0,0,3,5,0,0,0,0,0,0,0,0,0,0,0,0,0,0,0,0,0,5,3,0,0,0,0,0,0,0
0,0,0,0,0,0,0,154,0,0,0,0,0,0,0,0,0,0,0,0,0,0,0,0,0,154,0,0,0,0,0,0,0,0
0,0,0,0,0,0,3,5,151,0,0,0,0,0,0,0,0,0,0,0,0,0,0,0,151,5,3,0,0,0,0,0,0,0
0,0,0,0,0,0,0,5,0,0,0,0,0,0,0,0,0,0,0,0,0,0,0,0,0,5,0,0,0,0,0,0,0,0
0,0,0,0,151,0,5,0,0,0,3,3,0,0,0,0,0,0,0,0,0,3,3,0,0,0,5,0,151,0,0,0,0,0
0,0,0,0,0,5,0,0,0,0,3,3,0,0,0,0,0,0,0,0,0,3,3,0,0,0,0,5,0,0,0,0,0,0
0,0,0,0,3,0,0,0,0,0,0,0,0,0,0,0,0,0,0,0,0,0,0,0,0,0,0,0,3,0,0,0,0,0
0,0,0,0,0,5,0,0,0,0,0,0,0,151,0,0,0,0,0,151,0,0,0,0,0,0,0,5,0,0,0,0,0,0
0,0,0,0,151,161,154,0,0,0,0,0,5,5,154,5,154,5,154,5,5,0,0,0,0,0,154,161,151,0,0,0,0,0
0,0,0,0,0,0,0,154,0,0,0,5,0,3,0,3,0,3,0,3,0,5,0,0,0,154,0,0,0,0,0,0,0,0
0,0,0,0,0,0,0,161,5,0,5,0,0,0,0,0,0,0,0,0,0,0,5,0,5,161,0,0,0,0,0,0,0,0
0,0,0,0,0,0,0,151,0,3,0,151,0,0,0,0,0,0,0,0,0,151,0,3,0,151,0,0,0,0,0,0,0,0
0,0,0,0,0,0,0,0,0,0,0,0,0,0,0,0,0,0,0,0,0,0,0,0,0,0,0,0,0,0,0,0,0,0
0,0,0,0,0,0,0,0,0,0,0,0,0,0,0,0,0,0,0,0,0,0,0,0,0,0,0,0,0,0,0,0,0,0
0,0,0,0,0,0,0,0,0,0,0,0,0,0,0,0,0,0,0,0,0,0,0,0,0,0,0,0,0,0,0,0,0,0
0,0,0,0,0,0,0,0,0,0,0,0,0,0,0,0,0,0,0,0,0,0,0,0,0,0,0,0,0,0,0,0,0,0
0,0,0,0,0,0,0,0,0,0,0,0,0,0,0,0,0,0,0,0,0,0,0,0,0,0,0,0,0,0,0,0,0,0
:endlayer
layer: 25
127,0,0,0,0,0,0,0,0,0,0,0,0,0,0,0,0,0,0,0,0,0,0,0,0,0,0,0,0,0,0,0,0,0
0,0,0,0,0,0,0,0,0,0,0,0,0,0,0,0,0,0,0,0,0,0,0,0,0,0,0,0,0,0,0,0,0,0
0,0,0,0,0,0,0,0,0,0,0,0,0,0,0,0,0,0,0,0,0,0,0,0,0,0,0,0,0,0,0,0,0,0
0,0,0,0,0,0,0,0,0,0,0,0,0,0,0,0,0,0,0,0,0,0,0,0,0,0,0,0,0,0,0,0,0,0
0,0,0,0,0,0,0,151,0,3,0,151,0,0,0,0,0,0,0,0,0,151,0,3,0,151,0,0,0,0,0,0,0,0
0,0,0,0,0,0,0,0,5,0,5,0,0,0,0,0,0,0,0,0,0,0,5,0,5,0,0,0,0,0,0,0,0,0
0,0,0,0,0,0,162,5,0,0,0,5,0,3,0,3,0,3,0,3,0,5,0,0,0,5,162,0,0,0,0,0,0,0
0,0,0,0,151,0,5,0,0,0,0,0,5,5,154,5,154,5,154,5,5,0,0,0,0,0,5,0,151,0,0,0,0,0
0,0,0,0,0,5,0,0,0,0,0,0,0,151,0,0,0,0,0,151,0,0,0,0,0,0,0,5,0,0,0,0,0,0
0,0,0,0,3,0,0,0,0,0,0,0,0,0,0,0,0,0,0,0,0,0,0,0,0,0,0,0,3,0,0,0,0,0
0,0,0,0,0,5,0,0,0,0,3,3,0,0,0,0,0,0,0,0,0,3,3,0,0,0,0,5,0,0,0,0,0,0
0,0,0,0,151,0,5,0,0,0,3,3,0,0,0,0,0,0,0,0,0,3,3,0,0,0,5,0,151,0,0,0,0,0
0,0,0,0,0,0,0,5,0,0,0,0,0,0,0,0,0,0,0,0,0,0,0,0,0,5,0,0,0,0,0,0,0,0
0,0,0,0,0,0,3,5,151,0,0,0,0,0,0,0,0,0,0,0,0,0,0,0,151,5,3,0,0,0,0,0,0,0
0,0,0,0,0,0,0,154,0,0,0,0,0,0,0,0,0,0,0,0,0,0,0,0,0,154,0,0,0,0,0,0,0,0
0,0,0,0,0,0,3,5,0,0,0,0,0,0,0,0,0,0,0,0,0,0,0,0,0,5,3,0,0,0,0,0,0,0
0,0,0,0,0,0,0,154,0,0,0,0,0,0,0,0,0,103,103,0,0,0,0,0,0,154,0,0,0,0,0,0,0,0
0,0,0,0,0,0,3,5,0,0,0,0,0,0,0,0,0,0,0,0,0,0,0,0,0,5,3,0,0,0,0,0,0,0
0,0,0,0,0,0,0,154,0,0,0,0,0,0,0,0,0,0,0,0,0,0,0,0,0,154,0,0,0,0,0,0,0,0
0,0,0,0,0,0,3,5,151,0,0,0,0,0,0,0,0,0,0,0,0,0,0,0,151,5,3,0,0,0,0,0,0,0
0,0,0,0,0,0,0,5,0,0,0,0,0,0,0,0,0,0,0,0,0,0,0,0,0,5,0,0,0,0,0,0,0,0
0,0,0,0,151,0,5,0,0,0,3,3,0,0,0,0,0,0,0,0,0,3,3,0,0,0,5,0,151,0,0,0,0,0
0,0,0,0,0,5,0,0,0,0,3,3,0,0,0,0,0,0,0,0,0,3,3,0,0,0,0,5,0,0,0,0,0,0
0,0,0,0,3,0,0,0,0,0,0,0,0,0,0,0,0,0,0,0,0,0,0,0,0,0,0,0,3,0,0,0,0,0
0,0,0,0,0,5,0,0,0,0,0,0,0,151,0,0,0,0,0,151,0,0,0,0,0,0,0,5,0,0,0,0,0,0
0,0,0,0,151,0,5,0,0,0,0,0,5,5,154,5,154,5,154,5,5,0,0,0,0,0,5,0,151,0,0,0,0,0
0,0,0,0,0,0,162,5,0,0,0,5,0,3,0,3,0,3,0,3,0,5,0,0,0,5,162,0,0,0,0,0,0,0
0,0,0,0,0,0,0,0,5,0,5,0,0,0,0,0,0,0,0,0,0,0,5,0,5,0,0,0,0,0,0,0,0,0
0,0,0,0,0,0,0,151,0,3,0,151,0,0,0,0,0,0,0,0,0,151,0,3,0,151,0,0,0,0,0,0,0,0
0,0,0,0,0,0,0,0,0,0,0,0,0,0,0,0,0,0,0,0,0,0,0,0,0,0,0,0,0,0,0,0,0,0
0,0,0,0,0,0,0,0,0,0,0,0,0,0,0,0,0,0,0,0,0,0,0,0,0,0,0,0,0,0,0,0,0,0
0,0,0,0,0,0,0,0,0,0,0,0,0,0,0,0,0,0,0,0,0,0,0,0,0,0,0,0,0,0,0,0,0,0
0,0,0,0,0,0,0,0,0,0,0,0,0,0,0,0,0,0,0,0,0,0,0,0,0,0,0,0,0,0,0,0,0,0
0,0,0,0,0,0,0,0,0,0,0,0,0,0,0,0,0,0,0,0,0,0,0,0,0,0,0,0,0,0,0,0,0,0
:endlayer
layer: 26
127,0,0,0,0,0,0,0,0,0,0,0,0,0,0,0,0,0,0,0,0,0,0,0,0,0,0,0,0,0,0,0,0,0
0,0,0,0,0,0,0,0,0,0,0,0,0,0,0,0,0,0,0,0,0,0,0,0,0,0,0,0,0,0,0,0,0,0
0,0,0,0,0,0,0,0,0,0,0,0,0,0,0,0,0,0,0,0,0,0,0,0,0,0,0,0,0,0,0,0,0,0
0,0,0,0,0,0,0,0,0,0,0,0,0,0,0,0,0,0,0,0,0,0,0,0,0,0,0,0,0,0,0,0,0,0
0,0,0,0,0,0,0,94,94,3,94,94,0,0,0,0,0,0,0,0,0,94,94,3,94,94,0,0,0,0,0,0,0,0
0,0,0,0,0,0,94,94,5,0,5,94,94,0,0,0,0,0,0,0,94,94,5,0,5,94,94,0,0,0,0,0,0,0
0,0,0,0,0,94,94,5,0,0,0,5,94,3,0,3,0,3,0,3,94,5,0,0,0,5,94,94,0,0,0,0,0,0
0,0,0,0,94,94,5,151,151,151,0,0,5,5,154,5,154,5,154,5,5,0,0,151,151,151,5,94,94,0,0,0,0,0
0,0,0,0,94,5,0,151,0,151,0,0,0,151,0,0,0,0,0,151,0,0,0,151,0,151,0,5,94,0,0,0,0,0
0,0,0,0,3,0,0,151,151,151,0,0,0,0,0,0,0,0,0,0,0,0,0,151,151,151,0,0,3,0,0,0,0,0
0,0,0,0,94,5,0,0,0,0,3,3,0,0,0,0,0,0,0,0,0,3,3,0,0,0,0,5,94,0,0,0,0,0
0,0,0,0,94,94,5,0,0,0,3,3,0,0,0,0,0,0,0,0,0,3,3,0,0,0,5,94,94,0,0,0,0,0
0,0,0,0,0,94,94,5,0,0,0,0,0,0,0,0,0,0,0,0,0,0,0,0,0,5,94,94,0,0,0,0,0,0
0,0,0,0,0,0,3,5,151,0,0,0,0,0,0,0,0,0,0,0,0,0,0,0,151,5,3,0,0,0,0,0,0,0
0,0,0,0,0,0,0,154,0,0,0,0,0,0,0,0,0,0,0,0,0,0,0,0,0,154,0,0,0,0,0,0,0,0
0,0,0,0,0,0,3,5,0,0,0,0,0,0,0,0,0,0,0,0,0,0,0,0,0,5,3,0,0,0,0,0,0,0
0,0,0,0,0,0,0,154,0,0,0,0,0,0,0,0,0,0,0,0,0,0,0,0,0,154,0,0,0,0,0,0,0,0
0,0,0,0,0,0,3,5,0,0,0,0,0,0,0,0,0,103,103,0,0,0,0,0,0,5,3,0,0,0,0,0,0,0
0,0,0,0,0,0,0,154,0,0,0,0,0,0,0,0,0,103,103,0,0,0,0,0,0,154,0,0,0,0,0,0,0,0
0,0,0,0,0,0,3,5,151,0,0,0,0,0,0,0,0,0,0,0,0,0,0,0,151,5,3,0,0,0,0,0,0,0
0,0,0,0,0,94,94,5,0,0,0,0,0,0,0,0,0,0,0,0,0,0,0,0,0,5,94,94,0,0,0,0,0,0
0,0,0,0,94,94,5,0,0,0,3,3,0,0,0,0,0,0,0,0,0,3,3,0,0,0,5,94,94,0,0,0,0,0
0,0,0,0,94,5,0,0,0,0,3,3,0,0,0,0,0,0,0,0,0,3,3,0,0,0,0,5,94,0,0,0,0,0
0,0,0,0,3,0,0,151,151,151,0,0,0,0,0,0,0,0,0,0,0,0,0,151,151,151,0,0,3,0,0,0,0,0
0,0,0,0,94,5,0,151,0,151,0,0,0,151,0,0,0,0,0,151,0,0,0,151,0,151,0,5,94,0,0,0,0,0
0,0,0,0,94,94,5,151,151,151,0,0,5,5,154,5,154,5,154,5,5,0,0,151,151,151,5,94,94,0,0,0,0,0
0,0,0,0,0,94,94,5,0,0,0,5,94,3,0,3,0,3,0,3,94,5,0,0,0,5,94,94,0,0,0,0,0,0
0,0,0,0,0,0,94,94,5,0,5,94,94,0,0,0,0,0,0,0,94,94,5,0,5,94,94,0,0,0,0,0,0,0
0,0,0,0,0,0,0,94,94,3,94,94,0,0,0,0,0,0,0,0,0,94,94,3,94,94,0,0,0,0,0,0,0,0
0,0,0,0,0,0,0,0,0,0,0,0,0,0,0,0,0,0,0,0,0,0,0,0,0,0,0,0,0,0,0,0,0,0
0,0,0,0,0,0,0,0,0,0,0,0,0,0,0,0,0,0,0,0,0,0,0,0,0,0,0,0,0,0,0,0,0,0
0,0,0,0,0,0,0,0,0,0,0,0,0,0,0,0,0,0,0,0,0,0,0,0,0,0,0,0,0,0,0,0,0,0
0,0,0,0,0,0,0,0,0,0,0,0,0,0,0,0,0,0,0,0,0,0,0,0,0,0,0,0,0,0,0,0,0,0
0,0,0,0,0,0,0,0,0,0,0,0,0,0,0,0,0,0,0,0,0,0,0,0,0,0,0,0,0,0,0,0,0,0
:endlayer
layer: 27
127,0,0,0,0,0,0,0,0,0,0,0,0,0,0,0,0,0,0,0,0,0,0,0,0,0,0,0,0,0,0,0,0,0
0,0,0,0,0,0,0,0,0,0,0,0,0,0,0,0,0,0,0,0,0,0,0,0,0,0,0,0,0,0,0,0,0,0
0,0,0,0,0,0,0,0,0,175,0,0,0,0,0,0,0,0,0,0,0,0,0,169,0,0,0,0,0,0,0,0,0,0
0,0,0,0,0,0,0,0,0,0,0,0,0,0,0,0,0,0,0,0,0,0,0,0,0,0,0,0,0,0,0,0,0,0
0,0,0,0,0,0,0,0,0,3,0,0,0,0,0,0,0,0,0,0,0,0,0,3,0,0,0,0,0,0,0,0,0,0
0,0,0,0,0,0,0,0,5,0,5,0,0,0,0,0,0,0,0,0,0,0,5,0,5,0,0,0,0,0,0,0,0,0
0,0,0,0,0,0,0,5,0,0,0,5,0,3,0,3,0,3,0,3,0,5,0,0,0,5,0,0,0,0,0,0,0,0
0,0,0,0,0,0,5,181,151,176,0,0,5,5,154,5,154,5,154,5,5,0,0,170,151,165,5,0,0,0,0,0,0,0
0,0,0,0,0,5,0,151,151,151,0,0,0,10,0,0,0,0,0,14,0,0,0,151,151,151,0,5,0,0,0,0,0,0
0,0,185,0,3,0,0,182,151,177,0,0,0,0,0,0,0,0,0,0,0,0,0,171,151,166,0,0,3,0,163,0,0,0
0,0,0,0,0,5,0,0,0,0,3,3,0,0,0,0,0,0,0,0,0,3,3,0,0,0,0,5,0,0,0,0,0,0
0,0,0,0,0,0,5,0,0,0,3,3,0,0,0,0,0,0,0,0,0,3,3,0,0,0,5,0,0,0,0,0,0,0
0,0,0,0,0,0,0,5,0,0,0,0,0,0,0,0,0,0,0,0,0,0,0,0,0,5,0,0,0,0,0,0,0,0
0,0,0,0,0,0,3,5,12,0,0,0,0,0,0,0,0,0,0,0,0,0,0,0,12,5,3,0,0,0,0,0,0,0
0,0,0,0,0,0,0,154,0,0,0,0,0,0,0,0,0,0,0,0,0,0,0,0,0,154,0,0,0,0,0,0,0,0
0,0,0,0,0,0,3,5,0,0,0,0,0,0,0,0,0,0,0,0,0,0,0,0,0,5,3,0,0,0,0,0,0,0
0,0,0,0,0,0,0,154,0,0,0,0,0,0,0,0,0,0,0,0,0,0,0,0,0,154,0,0,0,0,0,0,0,0
0,0,0,0,0,0,3,5,0,0,0,0,0,0,0,0,103,0,0,0,0,0,0,0,0,5,3,0,0,0,0,0,0,0
0,0,0,0,0,0,0,154,0,0,0,0,0,0,0,0,103,0,0,0,0,0,0,0,0,154,0,0,0,0,0,0,0,0
0,0,0,0,0,0,3,5,11,0,0,0,0,0,0,0,0,0,0,0,0,0,0,0,11,5,3,0,0,0,0,0,0,0
0,0,0,0,0,0,0,5,0,0,0,0,0,0,0,0,0,0,0,0,0,0,0,0,0,5,0,0,0,0,0,0,0,0
0,0,0,0,0,0,5,0,0,0,3,3,0,0,0,0,0,0,0,0,0,3,3,0,0,0,5,0,0,0,0,0,0,0
0,0,0,0,0,5,0,0,0,0,3,3,0,0,0,0,0,0,0,0,0,3,3,0,0,0,0,5,0,0,0,0,0,0
0,0,186,0,3,0,0,183,151,178,0,0,0,0,0,0,0,0,0,0,0,0,0,172,151,167,0,0,3,0,164,0,0,0
0,0,0,0,0,5,0,151,151,151,0,0,0,10,0,0,0,0,0,14,0,0,0,151,151,151,0,5,0,0,0,0,0,0
0,0,0,0,0,0,5,184,151,179,0,0,5,5,154,5,154,5,154,5,5,0,0,173,151,168,5,0,0,0,0,0,0,0
0,0,0,0,0,0,0,5,0,0,0,5,0,3,0,3,0,3,0,3,0,5,0,0,0,5,0,0,0,0,0,0,0,0
0,0,0,0,0,0,0,0,5,0,5,0,0,0,0,0,0,0,0,0,0,0,5,0,5,0,0,0,0,0,0,0,0,0
0,0,0,0,0,0,0,0,0,3,0,0,0,0,0,0,0,0,0,0,0,0,0,3,0,0,0,0,0,0,0,0,0,0
0,0,0,0,0,0,0,0,0,0,0,0,0,0,0,0,0,0,0,0,0,0,0,0,0,0,0,0,0,0,0,0,0,0
0,0,0,0,0,0,0,0,0,180,0,0,0,0,0,0,0,0,0,0,0,0,0,174,0,0,0,0,0,0,0,0,0,0
0,0,0,0,0,0,0,0,0,0,0,0,0,0,0,0,0,0,0,0,0,0,0,0,0,0,0,0,0,0,0,0,0,0
0,0,0,0,0,0,0,0,0,0,0,0,0,0,0,0,0,0,0,0,0,0,0,0,0,0,0,0,0,0,0,0,0,0
0,0,0,0,0,0,0,0,0,0,0,0,0,0,0,0,0,0,0,0,0,0,0,0,0,0,0,0,0,0,0,0,0,0
:endlayer
layer: 28
127,0,0,0,0,0,0,0,0,0,0,0,0,0,0,0,0,0,0,0,0,0,0,0,0,0,0,0,0,0,0,0,0,0
0,0,0,0,0,0,0,0,0,188,0,0,0,0,0,0,0,0,0,0,0,0,0,188,0,0,0,0,0,0,0,0,0,0
0,0,0,0,0,0,0,0,190,125,187,0,0,0,0,0,0,0,0,0,0,0,190,125,187,0,0,0,0,0,0,0,0,0
0,0,0,0,0,0,0,0,0,189,0,0,0,0,0,0,0,0,0,0,0,0,0,189,0,0,0,0,0,0,0,0,0,0
0,0,0,0,0,0,0,150,150,3,150,150,0,0,0,0,0,0,0,0,0,150,150,3,150,150,0,0,0,0,0,0,0,0
0,0,0,0,0,0,150,150,5,0,5,150,150,0,0,0,0,0,0,0,150,150,5,0,5,150,150,0,0,0,0,0,0,0
0,0,0,0,0,150,150,5,0,0,0,5,150,3,0,3,0,3,0,3,150,5,0,0,0,5,150,150,0,0,0,0,0,0
0,0,0,0,150,150,5,0,201,0,0,0,5,5,154,5,154,5,154,5,5,0,0,0,193,0,5,150,150,0,0,0,0,0
0,0,188,0,150,5,0,205,126,199,0,0,8,19,0,0,0,0,0,18,0,0,0,197,126,191,0,5,150,0,188,0,0,0
0,190,125,187,3,0,0,0,202,0,0,0,0,0,0,0,0,0,0,0,0,0,0,0,194,0,0,0,3,190,125,187,0,0
0,0,189,0,150,5,0,0,0,0,3,3,0,0,0,0,0,0,0,0,0,3,3,0,0,0,0,5,150,0,189,0,0,0
0,0,0,0,150,150,5,0,0,0,3,3,0,0,0,0,0,0,0,0,0,3,3,0,0,0,5,150,150,0,0,0,0,0
0,0,0,0,0,150,150,5,8,0,0,0,0,0,0,0,0,0,0,0,0,0,0,0,8,5,150,150,0,0,0,0,0,0
0,0,0,0,0,0,3,5,17,0,0,0,0,0,0,0,0,0,0,0,0,0,0,0,17,5,3,0,0,0,0,0,0,0
0,0,0,0,0,0,0,154,0,0,0,0,0,0,0,0,0,0,0,0,0,0,0,0,0,154,0,0,0,0,0,0,0,0
0,0,0,0,0,0,3,5,0,0,0,0,0,0,0,0,0,0,0,0,0,0,0,0,0,5,3,0,0,0,0,0,0,0
0,0,0,0,0,0,0,154,0,0,0,0,0,0,0,0,0,0,0,0,0,0,0,0,0,154,0,0,0,0,0,0,0,0
0,0,0,0,0,0,3,5,0,0,0,0,0,0,103,103,0,0,0,0,0,0,0,0,0,5,3,0,0,0,0,0,0,0
0,0,0,0,0,0,0,154,0,0,0,0,0,0,103,103,0,0,0,0,0,0,0,0,0,154,0,0,0,0,0,0,0,0
0,0,0,0,0,0,3,5,16,0,0,0,0,0,0,0,0,0,0,0,0,0,0,0,16,5,3,0,0,0,0,0,0,0
0,0,0,0,0,150,150,5,8,0,0,0,0,0,0,0,0,0,0,0,0,0,0,0,0,5,150,150,0,0,0,0,0,0
0,0,0,0,150,150,5,0,0,0,3,3,0,0,0,0,0,0,0,0,0,3,3,0,0,0,5,150,150,0,0,0,0,0
0,0,188,0,150,5,0,0,0,0,3,3,0,0,0,0,0,0,0,0,0,3,3,0,0,0,0,5,150,0,188,0,0,0
0,190,125,187,3,0,0,0,203,0,0,0,0,0,0,0,0,0,0,0,0,0,0,0,195,0,0,0,3,190,125,187,0,0
0,0,189,0,150,5,0,206,126,200,0,0,0,19,0,0,0,0,0,18,8,0,0,198,126,192,0,5,150,0,189,0,0,0
0,0,0,0,150,150,5,0,204,0,0,0,5,5,154,5,154,5,154,5,5,0,0,0,196,0,5,150,150,0,0,0,0,0
0,0,0,0,0,150,150,5,0,0,0,5,150,3,0,3,0,3,0,3,150,5,0,0,0,5,150,150,0,0,0,0,0,0
0,0,0,0,0,0,150,150,5,0,5,150,150,0,0,0,0,0,0,0,150,150,5,0,5,150,150,0,0,0,0,0,0,0
0,0,0,0,0,0,0,150,150,3,150,150,0,0,0,0,0,0,0,0,0,150,150,3,150,150,0,0,0,0,0,0,0,0
0,0,0,0,0,0,0,0,0,188,0,0,0,0,0,0,0,0,0,0,0,0,0,188,0,0,0,0,0,0,0,0,0,0
0,0,0,0,0,0,0,0,190,125,187,0,0,0,0,0,0,0,0,0,0,0,190,125,187,0,0,0,0,0,0,0,0,0
0,0,0,0,0,0,0,0,0,189,0,0,0,0,0,0,0,0,0,0,0,0,0,189,0,0,0,0,0,0,0,0,0,0
0,0,0,0,0,0,0,0,0,0,0,0,0,0,0,0,0,0,0,0,0,0,0,0,0,0,0,0,0,0,0,0,0,0
0,0,0,0,0,0,0,0,0,0,0,0,0,0,0,0,0,0,0,0,0,0,0,0,0,0,0,0,0,0,0,0,0,0
:endlayer
layer: 29
127,0,0,0,0,0,0,0,0,0,0,0,0,0,0,0,0,0,0,0,0,0,0,0,0,0,0,0,0,0,0,0,0,0
0,0,0,0,0,0,0,0,0,0,0,0,0,0,0,0,0,0,0,0,0,0,0,0,0,0,0,0,0,0,0,0,0,0
0,0,0,0,0,0,0,0,0,126,0,0,0,0,0,0,0,0,0,0,0,0,0,126,0,0,0,0,0,0,0,0,0,0
0,0,0,0,0,0,0,0,0,0,0,0,0,0,0,0,0,0,0,0,0,0,0,0,0,0,0,0,0,0,0,0,0,0
0,0,0,0,0,0,0,151,0,3,0,151,0,0,0,0,0,0,0,0,0,151,0,3,0,151,0,0,0,0,0,0,0,0
0,0,0,0,0,0,16,16,5,0,5,0,0,0,0,0,0,0,0,0,0,0,5,0,5,16,19,0,0,0,0,0,0,0
0,0,0,0,0,16,18,5,0,0,0,5,0,3,0,3,0,3,0,3,0,5,0,0,0,5,16,19,0,0,0,0,0,0
0,0,0,0,151,18,5,0,0,0,0,0,5,5,16,17,16,17,16,5,5,0,0,0,0,0,5,19,151,0,0,0,0,0
0,0,0,0,0,5,0,0,126,0,0,17,0,14,17,0,0,0,17,10,0,17,0,0,126,0,0,5,0,0,0,0,0,0
0,0,126,0,3,0,0,0,0,0,0,0,0,0,0,0,0,0,0,0,0,0,0,0,0,0,0,0,3,0,126,0,0,0
0,0,0,0,0,5,0,0,0,0,3,3,0,0,0,0,0,0,0,0,0,3,3,0,0,0,0,5,0,0,0,0,0,0
0,0,0,0,151,0,5,0,19,0,3,3,0,0,0,0,0,0,0,0,0,3,3,0,18,0,5,0,151,0,0,0,0,0
0,0,0,0,0,0,0,5,0,0,0,0,0,0,0,0,0,0,0,0,0,0,0,0,0,5,0,0,0,0,0,0,0,0
0,0,0,0,0,0,3,5,11,0,0,0,0,0,0,0,0,0,0,0,0,0,0,0,11,5,3,0,0,0,0,0,0,0
0,0,0,0,0,0,0,18,19,0,0,0,0,0,0,0,0,0,0,0,0,0,0,0,18,19,0,0,0,0,0,0,0,0
0,0,0,0,0,0,3,19,0,0,0,0,0,0,0,0,0,0,0,0,0,0,0,0,0,18,3,0,0,0,0,0,0,0
0,0,0,0,0,0,0,18,0,0,0,0,0,0,103,103,0,0,0,0,0,0,0,0,0,19,0,0,0,0,0,0,0,0
0,0,0,0,0,0,3,19,0,0,0,0,0,0,0,0,0,0,0,0,0,0,0,0,0,18,3,0,0,0,0,0,0,0
0,0,0,0,0,0,0,18,19,0,0,0,0,0,0,0,0,0,0,0,0,0,0,0,18,19,0,0,0,0,0,0,0,0
0,0,0,0,0,0,3,5,12,0,0,0,0,0,0,0,0,0,0,0,0,0,0,0,12,5,3,0,0,0,0,0,0,0
0,0,0,0,0,0,0,5,0,0,0,0,0,0,0,0,0,0,0,0,0,0,0,0,0,5,0,0,0,0,0,0,0,0
0,0,0,0,151,0,5,0,19,0,3,3,0,0,0,0,0,0,0,0,0,3,3,0,18,0,5,0,151,0,0,0,0,0
0,0,0,0,0,5,0,0,0,0,3,3,0,0,0,0,0,0,0,0,0,3,3,0,0,0,0,5,0,0,0,0,0,0
0,0,126,0,3,0,0,0,0,0,0,0,0,0,0,0,0,0,0,0,0,0,0,0,0,0,0,0,3,0,126,0,0,0
0,0,0,0,0,5,0,0,126,0,0,16,0,14,16,0,0,0,16,10,0,16,0,0,126,0,0,5,0,0,0,0,0,0
0,0,0,0,151,18,5,0,0,0,0,0,5,5,17,16,17,16,17,5,5,0,0,0,0,0,5,19,151,0,0,0,0,0
0,0,0,0,0,18,17,5,0,0,0,5,0,3,0,3,0,3,0,3,0,5,0,0,0,5,19,17,0,0,0,0,0,0
0,0,0,0,0,0,18,17,5,0,5,0,0,0,0,0,0,0,0,0,0,0,5,0,5,17,17,0,0,0,0,0,0,0
0,0,0,0,0,0,0,151,0,3,0,151,0,0,0,0,0,0,0,0,0,151,0,3,0,151,0,0,0,0,0,0,0,0
0,0,0,0,0,0,0,0,0,0,0,0,0,0,0,0,0,0,0,0,0,0,0,0,0,0,0,0,0,0,0,0,0,0
0,0,0,0,0,0,0,0,0,126,0,0,0,0,0,0,0,0,0,0,0,0,0,126,0,0,0,0,0,0,0,0,0,0
0,0,0,0,0,0,0,0,0,0,0,0,0,0,0,0,0,0,0,0,0,0,0,0,0,0,0,0,0,0,0,0,0,0
0,0,0,0,0,0,0,0,0,0,0,0,0,0,0,0,0,0,0,0,0,0,0,0,0,0,0,0,0,0,0,0,0,0
0,0,0,0,0,0,0,0,0,0,0,0,0,0,0,0,0,0,0,0,0,0,0,0,0,0,0,0,0,0,0,0,0,0
:endlayer
layer: 30
127,0,0,0,0,0,0,0,0,0,0,0,0,0,0,0,0,0,0,0,0,0,0,0,0,0,0,0,0,0,0,0,0,0
0,0,0,0,0,0,0,0,0,0,0,0,0,0,0,0,0,0,0,0,0,0,0,0,0,0,0,0,0,0,0,0,0,0
0,0,0,0,0,0,0,0,0,126,0,0,0,0,0,0,0,0,0,0,0,0,0,126,0,0,0,0,0,0,0,0,0,0
0,0,0,0,0,0,0,0,0,0,0,0,0,0,0,0,0,0,0,0,0,0,0,0,0,0,0,0,0,0,0,0,0,0
0,0,0,0,0,0,0,151,0,3,0,151,0,0,0,0,0,0,0,0,0,151,0,3,0,151,0,0,0,0,0,0,0,0
0,0,0,0,0,0,0,211,5,0,5,0,0,0,0,0,0,0,0,0,0,0,5,0,5,209,0,0,0,0,0,0,0,0
0,0,0,0,0,0,0,154,0,0,0,5,0,3,0,3,0,3,0,3,0,5,0,0,0,154,0,0,0,0,0,0,0,0
0,0,0,0,151,213,154,0,0,0,0,0,5,5,5,5,5,5,5,5,5,0,0,0,0,0,154,207,151,0,0,0,0,0
0,0,0,0,0,5,0,0,126,0,0,92,0,0,18,8,0,8,19,0,0,92,0,0,126,0,0,5,0,0,0,0,0,0
0,0,126,0,3,0,0,0,0,0,0,0,0,0,0,0,0,0,0,0,0,0,0,0,0,0,0,0,3,0,126,0,0,0
0,0,0,0,0,5,0,0,0,0,3,3,0,0,0,0,0,0,0,0,0,3,3,0,0,0,0,5,0,0,0,0,0,0
0,0,0,0,151,0,5,0,92,0,3,3,0,0,0,0,0,0,0,0,0,3,3,0,92,0,5,0,151,0,0,0,0,0
0,0,0,0,0,0,0,5,0,0,0,0,0,0,0,0,0,0,0,0,0,0,0,0,0,5,0,0,0,0,0,0,0,0
0,0,0,0,0,0,3,5,0,0,0,0,0,0,0,0,0,0,0,0,0,0,0,0,0,5,3,0,0,0,0,0,0,0
0,0,0,0,0,0,0,5,16,0,0,0,0,0,103,103,0,0,0,0,0,0,0,0,16,5,0,0,0,0,0,0,0,0
0,0,0,0,0,0,3,5,8,0,0,0,0,0,103,103,0,0,0,0,0,0,0,0,8,5,3,0,0,0,0,0,0,0
0,0,0,0,0,0,0,5,0,0,0,0,0,0,0,0,0,0,0,0,0,0,0,0,0,5,0,0,0,0,0,0,0,0
0,0,0,0,0,0,3,5,8,0,0,0,0,0,0,0,0,0,0,0,0,0,0,0,8,5,3,0,0,0,0,0,0,0
0,0,0,0,0,0,0,5,17,0,0,0,0,0,0,0,0,0,0,0,0,0,0,0,17,5,0,0,0,0,0,0,0,0
0,0,0,0,0,0,3,5,0,0,0,0,0,0,0,0,0,0,0,0,0,0,0,0,0,5,3,0,0,0,0,0,0,0
0,0,0,0,0,0,0,5,0,0,0,0,0,0,0,0,0,0,0,0,0,0,0,0,0,5,0,0,0,0,0,0,0,0
0,0,0,0,151,0,5,0,92,0,3,3,0,0,0,0,0,0,0,0,0,3,3,0,92,0,5,0,151,0,0,0,0,0
0,0,0,0,0,5,0,0,0,0,3,3,0,0,0,0,0,0,0,0,0,3,3,0,0,0,0,5,0,0,0,0,0,0
0,0,126,0,3,0,0,0,0,0,0,0,0,0,0,0,0,0,0,0,0,0,0,0,0,0,0,0,3,0,126,0,0,0
0,0,0,0,0,5,0,0,126,0,0,92,0,0,18,8,0,8,19,0,0,92,0,0,126,0,0,5,0,0,0,0,0,0
0,0,0,0,151,214,154,0,0,0,0,0,5,5,5,5,5,5,5,5,5,0,0,0,0,0,154,208,151,0,0,0,0,0
0,0,0,0,0,0,0,154,0,0,0,5,0,3,0,3,0,3,0,3,0,5,0,0,0,154,0,0,0,0,0,0,0,0
0,0,0,0,0,0,0,212,5,0,5,0,0,0,0,0,0,0,0,0,0,0,5,0,5,210,0,0,0,0,0,0,0,0
0,0,0,0,0,0,0,151,0,3,0,151,0,0,0,0,0,0,0,0,0,151,0,3,0,151,0,0,0,0,0,0,0,0
0,0,0,0,0,0,0,0,0,0,0,0,0,0,0,0,0,0,0,0,0,0,0,0,0,0,0,0,0,0,0,0,0,0
0,0,0,0,0,0,0,0,0,126,0,0,0,0,0,0,0,0,0,0,0,0,0,126,0,0,0,0,0,0,0,0,0,0
0,0,0,0,0,0,0,0,0,0,0,0,0,0,0,0,0,0,0,0,0,0,0,0,0,0,0,0,0,0,0,0,0,0
0,0,0,0,0,0,0,0,0,0,0,0,0,0,0,0,0,0,0,0,0,0,0,0,0,0,0,0,0,0,0,0,0,0
0,0,0,0,0,0,0,0,0,0,0,0,0,0,0,0,0,0,0,0,0,0,0,0,0,0,0,0,0,0,0,0,0,0
:endlayer
layer: 31
127,0,0,0,0,0,0,0,0,0,0,0,0,0,0,0,0,0,0,0,0,0,0,0,0,0,0,0,0,0,0,0,0,0
0,0,0,0,0,0,0,0,0,0,0,0,0,0,0,0,0,0,0,0,0,0,0,0,0,0,0,0,0,0,0,0,0,0
0,0,0,0,0,0,0,0,0,126,0,0,0,0,0,0,0,0,0,0,0,0,0,126,0,0,0,0,0,0,0,0,0,0
0,0,0,0,0,0,0,0,0,0,0,0,0,0,0,0,0,0,0,0,0,0,0,0,0,0,0,0,0,0,0,0,0,0
0,0,0,0,0,0,0,151,0,3,0,151,0,0,0,0,0,0,0,0,0,151,0,3,0,151,0,0,0,0,0,0,0,0
0,0,0,0,0,0,0,161,5,0,5,0,0,0,0,0,0,0,0,0,0,0,5,0,5,161,0,0,0,0,0,0,0,0
0,0,0,0,0,0,0,154,0,0,0,5,11,3,11,3,11,3,11,3,11,5,0,0,0,154,0,0,0,0,0,0,0,0
0,0,0,0,151,161,154,0,0,0,0,0,5,5,5,5,5,5,5,5,5,0,0,0,0,0,154,161,151,0,0,0,0,0
0,0,0,0,0,5,0,0,126,0,0,92,0,9,14,19,125,18,10,9,0,92,0,0,126,0,0,5,0,0,0,0,0,0
0,0,126,0,3,0,0,0,0,0,17,0,0,0,0,0,0,0,0,0,0,0,17,0,0,0,0,0,3,0,126,0,0,0
0,0,0,0,0,5,0,0,0,19,3,3,0,0,0,0,0,0,0,0,0,3,3,18,0,0,0,5,0,0,0,0,0,0
0,0,0,0,151,0,5,0,92,0,3,3,0,0,0,0,0,0,0,0,0,3,3,0,92,0,5,0,151,0,0,0,0,0
0,0,0,0,0,0,14,5,0,0,0,0,0,0,0,0,0,0,0,0,0,0,0,0,0,5,10,0,0,0,0,0,0,0
0,0,0,0,0,0,3,5,9,0,0,0,0,0,0,0,0,0,0,0,0,0,0,0,9,5,3,0,0,0,0,0,0,0
0,0,0,0,0,0,14,5,11,0,0,0,0,0,0,0,103,0,0,0,0,0,0,0,11,5,10,0,0,0,0,0,0,0
0,0,0,0,0,0,3,5,17,0,0,0,0,0,0,0,103,0,0,0,0,0,0,0,17,5,3,0,0,0,0,0,0,0
0,0,0,0,0,0,14,5,125,0,0,0,0,0,0,0,0,0,0,0,0,0,0,0,125,5,10,0,0,0,0,0,0,0
0,0,0,0,0,0,3,5,16,0,0,0,0,0,0,0,0,0,0,0,0,0,0,0,16,5,3,0,0,0,0,0,0,0
0,0,0,0,0,0,14,5,12,0,0,0,0,0,0,0,0,0,0,0,0,0,0,0,12,5,10,0,0,0,0,0,0,0
0,0,0,0,0,0,3,5,9,0,0,0,0,0,0,0,0,0,0,0,0,0,0,0,9,5,3,0,0,0,0,0,0,0
0,0,0,0,0,0,14,5,0,0,0,0,0,0,0,0,0,0,0,0,0,0,0,0,0,5,10,0,0,0,0,0,0,0
0,0,0,0,151,0,5,0,92,0,3,3,0,0,0,0,0,0,0,0,0,3,3,0,92,0,5,0,151,0,0,0,0,0
0,0,0,0,0,5,0,0,0,19,3,3,0,0,0,0,0,0,0,0,0,3,3,18,0,0,0,5,0,0,0,0,0,0
0,0,126,0,3,0,0,0,0,0,16,0,0,0,0,0,0,0,0,0,0,0,16,0,0,0,0,0,3,0,126,0,0,0
0,0,0,0,0,5,0,0,126,0,0,92,0,9,14,19,125,18,10,9,0,92,0,0,126,0,0,5,0,0,0,0,0,0
0,0,0,0,151,161,154,0,0,0,0,0,5,5,5,5,5,5,5,5,5,0,0,0,0,0,154,161,151,0,0,0,0,0
0,0,0,0,0,0,0,154,0,0,0,5,12,3,12,3,12,3,12,3,12,5,0,0,0,154,0,0,0,0,0,0,0,0
0,0,0,0,0,0,0,161,5,0,5,0,0,0,0,0,0,0,0,0,0,0,5,0,5,161,0,0,0,0,0,0,0,0
0,0,0,0,0,0,0,151,0,3,0,151,0,0,0,0,0,0,0,0,0,151,0,3,0,151,0,0,0,0,0,0,0,0
0,0,0,0,0,0,0,0,0,0,0,0,0,0,0,0,0,0,0,0,0,0,0,0,0,0,0,0,0,0,0,0,0,0
0,0,0,0,0,0,0,0,0,126,0,0,0,0,0,0,0,0,0,0,0,0,0,126,0,0,0,0,0,0,0,0,0,0
0,0,0,0,0,0,0,0,0,0,0,0,0,0,0,0,0,0,0,0,0,0,0,0,0,0,0,0,0,0,0,0,0,0
0,0,0,0,0,0,0,0,0,0,0,0,0,0,0,0,0,0,0,0,0,0,0,0,0,0,0,0,0,0,0,0,0,0
0,0,0,0,0,0,0,0,0,0,0,0,0,0,0,0,0,0,0,0,0,0,0,0,0,0,0,0,0,0,0,0,0,0
:endlayer
layer: 32
127,0,0,0,0,0,0,0,0,0,0,0,0,0,0,0,0,0,0,0,0,0,0,0,0,0,0,0,0,0,0,0,0,0
0,0,0,0,0,0,0,0,0,0,0,0,0,0,0,0,0,0,0,0,0,0,0,0,0,0,0,0,0,0,0,0,0,0
0,0,0,0,0,0,0,0,0,126,0,0,0,0,0,0,0,0,0,0,0,0,0,126,0,0,0,0,0,0,0,0,0,0
0,0,0,0,0,0,0,0,0,0,0,0,0,0,0,0,0,0,0,0,0,0,0,0,0,0,0,0,0,0,0,0,0,0
0,0,0,0,0,0,0,151,0,3,0,151,0,0,0,0,0,0,0,0,0,151,0,3,0,151,0,0,0,0,0,0,0,0
0,0,0,0,0,0,0,0,5,0,5,0,0,0,0,0,0,0,0,0,0,0,5,0,5,0,0,0,0,0,0,0,0,0
0,0,0,0,0,0,162,5,0,0,0,5,16,16,16,16,16,16,16,16,16,5,0,0,0,5,162,0,0,0,0,0,0,0
0,0,0,0,151,0,5,0,0,0,0,0,5,5,5,5,5,5,5,5,5,0,0,0,0,0,5,0,151,0,0,0,0,0
0,0,0,0,0,5,0,0,126,0,0,92,0,0,8,18,17,19,8,0,0,92,0,0,126,0,0,5,0,0,0,0,0,0
0,0,126,0,3,0,0,0,0,0,92,8,0,0,0,0,0,0,0,0,0,8,92,0,0,0,0,0,3,0,126,0,0,0
0,0,0,0,0,5,0,0,0,92,3,3,8,0,0,0,0,0,0,0,8,3,3,92,0,0,0,5,0,0,0,0,0,0
0,0,0,0,151,0,5,0,92,8,3,3,8,0,0,0,0,0,0,0,8,3,3,8,92,0,5,0,151,0,0,0,0,0
0,0,0,0,0,0,18,5,0,0,8,8,0,0,0,0,0,0,0,0,0,8,8,0,0,5,19,0,0,0,0,0,0,0
0,0,0,0,0,0,18,5,0,0,0,0,0,0,0,0,0,0,0,0,0,0,0,0,0,5,19,0,0,0,0,0,0,0
0,0,0,0,0,0,18,5,8,0,0,0,0,0,0,0,0,103,103,0,0,0,0,0,8,5,19,0,0,0,0,0,0,0
0,0,0,0,0,0,18,5,16,0,0,0,0,0,0,0,0,103,103,0,0,0,0,0,16,5,19,0,0,0,0,0,0,0
0,0,0,0,0,0,18,5,19,0,0,0,0,0,0,0,0,0,0,0,0,0,0,0,18,5,19,0,0,0,0,0,0,0
0,0,0,0,0,0,18,5,17,0,0,0,0,0,0,0,0,0,0,0,0,0,0,0,17,5,19,0,0,0,0,0,0,0
0,0,0,0,0,0,18,5,8,0,0,0,0,0,0,0,0,0,0,0,0,0,0,0,8,5,19,0,0,0,0,0,0,0
0,0,0,0,0,0,18,5,0,0,0,0,0,0,0,0,0,0,0,0,0,0,0,0,0,5,19,0,0,0,0,0,0,0
0,0,0,0,0,0,18,5,0,0,8,8,0,0,0,0,0,0,0,0,0,8,8,0,0,5,19,0,0,0,0,0,0,0
0,0,0,0,151,0,5,0,92,8,3,3,8,0,0,0,0,0,0,0,8,3,3,8,92,0,5,0,151,0,0,0,0,0
0,0,0,0,0,5,0,0,0,92,3,3,8,0,0,0,0,0,0,0,8,3,3,92,0,0,0,5,0,0,0,0,0,0
0,0,126,0,3,0,0,0,0,0,92,8,0,0,0,0,0,0,0,0,0,8,92,0,0,0,0,0,3,0,126,0,0,0
0,0,0,0,0,5,0,0,126,0,0,92,0,0,8,18,16,19,8,0,0,92,0,0,126,0,0,5,0,0,0,0,0,0
0,0,0,0,151,0,5,0,0,0,0,0,5,5,5,5,5,5,5,5,5,0,0,0,0,0,5,0,151,0,0,0,0,0
0,0,0,0,0,0,162,5,0,0,0,5,17,17,17,17,17,17,17,17,17,5,0,0,0,5,162,0,0,0,0,0,0,0
0,0,0,0,0,0,0,0,5,0,5,0,0,0,0,0,0,0,0,0,0,0,5,0,5,0,0,0,0,0,0,0,0,0
0,0,0,0,0,0,0,151,0,3,0,151,0,0,0,0,0,0,0,0,0,151,0,3,0,151,0,0,0,0,0,0,0,0
0,0,0,0,0,0,0,0,0,0,0,0,0,0,0,0,0,0,0,0,0,0,0,0,0,0,0,0,0,0,0,0,0,0
0,0,0,0,0,0,0,0,0,126,0,0,0,0,0,0,0,0,0,0,0,0,0,126,0,0,0,0,0,0,0,0,0,0
0,0,0,0,0,0,0,0,0,0,0,0,0,0,0,0,0,0,0,0,0,0,0,0,0,0,0,0,0,0,0,0,0,0
0,0,0,0,0,0,0,0,0,0,0,0,0,0,0,0,0,0,0,0,0,0,0,0,0,0,0,0,0,0,0,0,0,0
0,0,0,0,0,0,0,0,0,0,0,0,0,0,0,0,0,0,0,0,0,0,0,0,0,0,0,0,0,0,0,0,0,0
:endlayer
layer: 33
127,0,0,0,0,0,0,0,0,0,0,0,0,0,0,0,0,0,0,0,0,0,0,0,0,0,0,0,0,0,0,0,0,0
0,0,0,0,0,0,0,0,0,0,0,0,0,0,0,0,0,0,0,0,0,0,0,0,0,0,0,0,0,0,0,0,0,0
0,0,0,0,0,0,0,0,0,126,0,0,0,0,0,0,0,0,0,0,0,0,0,126,0,0,0,0,0,0,0,0,0,0
0,0,0,0,0,0,0,0,0,11,0,0,0,0,0,0,0,0,0,0,0,0,0,11,0,0,0,0,0,0,0,0,0,0
0,0,0,0,0,0,0,94,94,3,94,94,0,0,0,0,0,0,0,0,0,94,94,3,94,94,0,0,0,0,0,0,0,0
0,0,0,0,0,0,94,94,5,0,5,94,94,0,0,0,0,0,0,0,94,94,5,0,5,94,94,0,0,0,0,0,0,0
0,0,0,0,0,94,94,5,0,0,0,5,94,3,94,3,94,3,94,3,94,5,0,0,0,5,94,94,0,0,0,0,0,0
0,0,0,0,94,94,5,0,0,0,0,0,5,5,5,5,5,5,5,5,5,0,0,0,0,0,5,94,94,0,0,0,0,0
0,0,0,0,94,5,0,0,151,0,0,92,0,0,0,0,0,0,0,0,0,92,0,0,151,0,0,5,94,0,0,0,0,0
0,0,126,14,3,0,0,0,0,0,92,16,8,0,0,0,0,0,0,0,8,16,92,0,0,0,0,0,3,10,126,0,0,0
0,0,0,0,94,5,0,0,0,92,3,3,19,0,0,0,0,0,0,0,18,3,3,92,0,0,0,5,94,0,0,0,0,0
0,0,0,0,94,94,5,0,92,18,3,3,19,0,0,0,0,0,0,0,18,3,3,19,92,0,5,94,94,0,0,0,0,0
0,0,0,0,0,94,94,5,0,8,17,17,8,0,0,0,0,0,0,0,8,17,17,8,0,5,94,94,0,0,0,0,0,0
0,0,0,0,0,0,3,5,0,0,0,0,0,0,0,0,0,0,0,0,0,0,0,0,0,5,3,0,0,0,0,0,0,0
0,0,0,0,0,0,94,5,0,0,0,0,0,0,0,0,0,0,0,0,0,0,0,0,0,5,94,0,0,0,0,0,0,0
0,0,0,0,0,0,3,5,0,0,0,0,0,0,0,0,0,0,0,0,0,0,0,0,0,5,3,0,0,0,0,0,0,0
0,0,0,0,0,0,94,5,0,0,0,0,0,0,0,0,0,103,103,0,0,0,0,0,0,5,94,0,0,0,0,0,0,0
0,0,0,0,0,0,3,5,0,0,0,0,0,0,0,0,0,0,0,0,0,0,0,0,0,5,3,0,0,0,0,0,0,0
0,0,0,0,0,0,94,5,0,0,0,0,0,0,0,0,0,0,0,0,0,0,0,0,0,5,94,0,0,0,0,0,0,0
0,0,0,0,0,0,3,5,0,0,0,0,0,0,0,0,0,0,0,0,0,0,0,0,0,5,3,0,0,0,0,0,0,0
0,0,0,0,0,94,94,5,0,8,16,16,16,0,0,0,0,0,0,0,8,16,16,8,0,5,94,94,0,0,0,0,0,0
0,0,0,0,94,94,5,0,92,18,3,3,19,0,0,0,0,0,0,0,18,3,3,19,92,0,5,94,94,0,0,0,0,0
0,0,0,0,94,5,0,0,0,92,3,3,19,0,0,0,0,0,0,0,18,3,3,92,0,0,0,5,94,0,0,0,0,0
0,0,126,14,3,0,0,0,0,0,92,17,8,0,0,0,0,0,0,0,8,17,92,0,0,0,0,0,3,10,126,0,0,0
0,0,0,0,94,5,0,0,151,0,0,92,0,0,0,0,0,0,0,0,0,92,0,0,151,0,0,5,94,0,0,0,0,0
0,0,0,0,94,94,5,0,0,0,0,0,5,5,5,5,5,5,5,5,5,0,0,0,0,0,5,94,94,0,0,0,0,0
0,0,0,0,0,94,94,5,0,0,0,5,94,3,94,3,94,3,94,3,94,5,0,0,0,5,94,94,0,0,0,0,0,0
0,0,0,0,0,0,94,94,5,0,5,94,94,0,0,0,0,0,0,0,94,94,5,0,5,94,94,0,0,0,0,0,0,0
0,0,0,0,0,0,0,94,94,3,94,94,0,0,0,0,0,0,0,0,0,94,94,3,94,94,0,0,0,0,0,0,0,0
0,0,0,0,0,0,0,0,0,12,0,0,0,0,0,0,0,0,0,0,0,0,0,12,0,0,0,0,0,0,0,0,0,0
0,0,0,0,0,0,0,0,0,126,0,0,0,0,0,0,0,0,0,0,0,0,0,126,0,0,0,0,0,0,0,0,0,0
0,0,0,0,0,0,0,0,0,0,0,0,0,0,0,0,0,0,0,0,0,0,0,0,0,0,0,0,0,0,0,0,0,0
0,0,0,0,0,0,0,0,0,0,0,0,0,0,0,0,0,0,0,0,0,0,0,0,0,0,0,0,0,0,0,0,0,0
0,0,0,0,0,0,0,0,0,0,0,0,0,0,0,0,0,0,0,0,0,0,0,0,0,0,0,0,0,0,0,0,0,0
:endlayer
layer: 34
127,0,0,0,0,0,0,0,0,0,0,0,0,0,0,0,0,0,0,0,0,0,0,0,0,0,0,0,0,0,0,0,0,0
0,0,0,0,0,0,0,0,0,0,0,0,0,0,0,0,0,0,0,0,0,0,0,0,0,0,0,0,0,0,0,0,0,0
0,0,0,0,0,0,0,0,0,151,0,0,0,0,0,0,0,0,0,0,0,0,0,151,0,0,0,0,0,0,0,0,0,0
0,0,0,0,0,0,0,0,0,16,0,0,0,0,0,0,0,0,0,0,0,0,0,16,0,0,0,0,0,0,0,0,0,0
0,0,0,0,0,0,0,0,127,5,127,0,0,0,0,0,0,0,0,0,0,0,127,5,127,0,0,0,0,0,0,0,0,0
0,0,0,0,0,0,0,127,5,5,5,127,0,0,0,0,0,0,0,0,0,127,5,5,5,127,0,0,0,0,0,0,0,0
0,0,0,0,0,0,127,5,5,5,5,5,127,3,127,3,127,3,127,3,127,5,5,5,5,5,127,0,0,0,0,0,0,0
0,0,0,0,0,127,5,5,5,5,5,5,5,5,5,5,5,5,5,5,5,5,5,5,5,5,5,127,0,0,0,0,0,0
0,0,0,0,127,5,5,5,5,5,5,5,5,5,5,5,5,5,5,5,5,5,5,5,5,5,5,5,127,0,0,0,0,0
0,0,151,18,5,5,5,5,5,5,5,5,5,5,5,5,5,5,5,5,5,5,5,5,5,5,5,5,5,19,151,0,0,0
0,0,0,0,127,5,5,5,5,5,5,5,5,5,5,5,5,5,5,5,5,5,5,5,5,5,5,5,127,0,0,0,0,0
0,0,0,0,0,127,5,5,5,5,5,5,5,5,5,5,5,5,5,5,5,5,5,5,5,5,5,127,0,0,0,0,0,0
0,0,0,0,0,0,127,5,5,5,5,5,5,5,5,8,8,8,5,5,5,5,5,5,5,5,127,0,0,0,0,0,0,0
0,0,0,0,0,0,3,5,5,5,5,5,5,5,8,129,129,129,8,5,5,5,5,5,5,5,3,0,0,0,0,0,0,0
0,0,0,0,0,0,127,5,5,5,5,5,5,8,0,0,0,0,0,8,5,5,5,5,5,5,127,0,0,0,0,0,0,0
0,0,0,0,0,0,3,5,5,5,5,5,8,131,0,0,0,0,0,128,8,5,5,5,5,5,3,0,0,0,0,0,0,0
0,0,0,0,0,0,127,5,5,5,5,5,8,131,0,0,0,0,0,128,8,5,5,5,5,5,127,0,0,0,0,0,0,0
0,0,0,0,0,0,3,5,5,5,5,5,8,131,0,0,0,103,103,128,8,5,5,5,5,5,3,0,0,0,0,0,0,0
0,0,0,0,0,0,127,5,5,5,5,5,5,8,0,0,0,103,103,8,5,5,5,5,5,5,127,0,0,0,0,0,0,0
0,0,0,0,0,0,3,5,5,5,5,5,5,5,8,130,130,130,8,5,5,5,5,5,5,5,3,0,0,0,0,0,0,0
0,0,0,0,0,0,127,5,5,5,5,5,5,5,5,8,8,8,5,5,5,5,5,5,5,5,127,0,0,0,0,0,0,0
0,0,0,0,0,127,5,5,5,5,5,5,5,5,5,5,5,5,5,5,5,5,5,5,5,5,5,127,0,0,0,0,0,0
0,0,0,0,127,5,5,5,5,5,5,5,5,5,5,5,5,5,5,5,5,5,5,5,5,5,5,5,127,0,0,0,0,0
0,0,151,18,5,5,5,5,5,5,5,5,5,5,5,5,5,5,5,5,5,5,5,5,5,5,5,5,5,19,151,0,0,0
0,0,0,0,127,5,5,5,5,5,5,5,5,5,5,5,5,5,5,5,5,5,5,5,5,5,5,5,127,0,0,0,0,0
0,0,0,0,0,127,5,5,5,5,5,5,5,5,5,5,5,5,5,5,5,5,5,5,5,5,5,127,0,0,0,0,0,0
0,0,0,0,0,0,127,5,5,5,5,5,127,3,127,3,127,3,127,3,127,5,5,5,5,5,127,0,0,0,0,0,0,0
0,0,0,0,0,0,0,127,5,5,5,127,0,0,0,0,0,0,0,0,0,127,5,5,5,127,0,0,0,0,0,0,0,0
0,0,0,0,0,0,0,0,127,5,127,0,0,0,0,0,0,0,0,0,0,0,127,5,127,0,0,0,0,0,0,0,0,0
0,0,0,0,0,0,0,0,0,17,0,0,0,0,0,0,0,0,0,0,0,0,0,17,0,0,0,0,0,0,0,0,0,0
0,0,0,0,0,0,0,0,0,151,0,0,0,0,0,0,0,0,0,0,0,0,0,151,0,0,0,0,0,0,0,0,0,0
0,0,0,0,0,0,0,0,0,0,0,0,0,0,0,0,0,0,0,0,0,0,0,0,0,0,0,0,0,0,0,0,0,0
0,0,0,0,0,0,0,0,0,0,0,0,0,0,0,0,0,0,0,0,0,0,0,0,0,0,0,0,0,0,0,0,0,0
0,0,0,0,0,0,0,0,0,0,0,0,0,0,0,0,0,0,0,0,0,0,0,0,0,0,0,0,0,0,0,0,0,0
:endlayer
layer: 35
127,0,0,0,0,0,0,0,0,0,0,0,0,0,0,0,0,0,0,0,0,0,0,0,0,0,0,0,0,0,0,0,0,0
0,0,0,0,0,0,0,0,0,0,0,0,0,0,0,0,0,0,0,0,0,0,0,0,0,0,0,0,0,0,0,0,0,0
0,0,0,0,0,0,0,0,0,16,0,0,0,0,0,0,0,0,0,0,0,0,0,16,0,0,0,0,0,0,0,0,0,0
0,0,0,0,0,0,0,0,0,12,0,0,0,0,0,0,0,0,0,0,0,0,0,12,0,0,0,0,0,0,0,0,0,0
0,0,0,0,0,0,0,0,0,127,0,0,0,0,0,0,0,0,0,0,0,0,0,127,0,0,0,0,0,0,0,0,0,0
0,0,0,0,0,0,0,0,127,127,127,0,0,0,0,0,0,0,0,0,0,0,127,127,127,0,0,0,0,0,0,0,0,0
0,0,0,0,0,0,0,127,127,127,127,127,0,16,0,16,0,16,0,16,0,127,127,127,127,127,0,0,0,0,0,0,0,0
0,0,0,0,0,0,127,127,127,127,127,127,127,127,127,127,127,127,127,127,127,127,127,127,127,127,127,0,0,0,0,0,0,0
0,0,0,0,0,127,127,127,127,127,127,127,127,127,127,127,127,127,127,127,127,127,127,127,127,127,127,127,0,0,0,0,0,0
0,0,18,10,127,127,127,127,127,127,127,127,127,127,5,5,5,5,5,0,127,127,127,127,127,127,127,127,127,14,19,0,0,0
0,0,0,0,0,127,127,127,127,127,127,127,5,5,215,215,215,215,226,5,5,127,127,127,127,127,127,127,0,0,0,0,0,0
0,0,0,0,0,0,127,127,127,127,127,5,230,229,0,0,228,0,0,225,215,5,127,127,127,127,127,0,0,0,0,0,0,0
0,0,0,0,0,0,0,127,127,127,5,0,0,0,0,0,0,0,0,0,0,219,5,127,127,127,0,0,0,0,0,0,0,0
0,0,0,0,0,0,18,127,127,0,5,0,231,0,0,0,0,0,0,0,221,220,5,127,127,127,19,0,0,0,0,0,0,0
0,0,0,0,0,0,0,127,127,5,231,231,231,0,0,0,0,0,0,0,0,215,215,5,127,127,0,0,0,0,0,0,0,0
0,0,0,0,0,0,18,127,127,5,231,0,0,0,0,0,0,0,0,0,0,0,216,5,127,127,19,0,0,0,0,0,0,0
0,0,0,0,0,0,0,127,127,5,231,0,232,0,0,0,0,0,0,0,222,0,217,5,127,127,0,0,0,0,0,0,0,0
0,0,0,0,0,0,18,127,127,5,231,0,0,0,0,0,103,0,0,0,0,0,218,5,127,127,19,0,0,0,0,0,0,0
0,0,0,0,0,0,0,127,127,5,231,231,231,0,0,0,103,0,0,0,0,215,215,5,127,127,0,0,0,0,0,0,0,0
0,0,0,0,0,0,18,127,127,127,5,0,231,0,0,0,0,0,0,0,0,0,5,127,127,127,19,0,0,0,0,0,0,0
0,0,0,0,0,0,0,127,127,127,5,0,0,0,0,0,0,0,0,0,223,0,5,127,127,127,0,0,0,0,0,0,0,0
0,0,0,0,0,0,127,127,127,127,127,5,233,14,11,11,11,11,11,10,224,5,127,127,127,127,127,0,0,0,0,0,0,0
0,0,0,0,0,127,127,127,127,127,127,127,5,5,227,227,227,227,227,5,5,127,127,127,127,127,127,127,0,0,0,0,0,0
0,0,18,10,127,127,127,127,127,127,127,127,127,0,5,5,5,5,5,127,127,127,127,127,127,127,127,127,127,14,19,0,0,0
0,0,0,0,0,127,127,127,127,127,127,127,127,127,127,127,127,127,127,127,127,127,127,127,127,127,127,127,0,0,0,0,0,0
0,0,0,0,0,0,127,127,127,127,127,127,127,127,127,127,127,127,127,127,127,127,127,127,127,127,127,0,0,0,0,0,0,0
0,0,0,0,0,0,0,127,127,127,127,127,0,17,0,17,0,17,0,17,0,127,127,127,127,127,0,0,0,0,0,0,0,0
0,0,0,0,0,0,0,0,127,127,127,0,0,0,0,0,0,0,0,0,0,0,127,127,127,0,0,0,0,0,0,0,0,0
0,0,0,0,0,0,0,0,0,127,0,0,0,0,0,0,0,0,0,0,0,0,0,127,0,0,0,0,0,0,0,0,0,0
0,0,0,0,0,0,0,0,0,11,0,0,0,0,0,0,0,0,0,0,0,0,0,11,0,0,0,0,0,0,0,0,0,0
0,0,0,0,0,0,0,0,0,17,0,0,0,0,0,0,0,0,0,0,0,0,0,17,0,0,0,0,0,0,0,0,0,0
0,0,0,0,0,0,0,0,0,0,0,0,0,0,0,0,0,0,0,0,0,0,0,0,0,0,0,0,0,0,0,0,0,0
0,0,0,0,0,0,0,0,0,0,0,0,0,0,0,0,0,0,0,0,0,0,0,0,0,0,0,0,0,0,0,0,0,0
0,0,0,0,0,0,0,0,0,0,0,0,0,0,0,0,0,0,0,0,0,0,0,0,0,0,0,0,0,0,0,0,0,0
:endlayer
layer: 36
127,0,0,0,0,0,0,0,0,0,0,0,0,0,0,0,0,0,0,0,0,0,0,0,0,0,0,0,0,0,0,0,0,0
0,0,0,0,0,0,0,0,0,0,0,0,0,0,0,0,0,0,0,0,0,0,0,0,0,0,0,0,0,0,0,0,0,0
0,0,0,0,0,0,0,0,0,11,0,0,0,0,0,0,0,0,0,0,0,0,0,11,0,0,0,0,0,0,0,0,0,0
0,0,0,0,0,0,0,0,0,0,0,0,0,0,0,0,0,0,0,0,0,0,0,0,0,0,0,0,0,0,0,0,0,0
0,0,0,0,0,0,0,0,0,0,0,0,0,0,0,0,0,0,0,0,0,0,0,0,0,0,0,0,0,0,0,0,0,0
0,0,0,0,0,0,0,0,0,127,0,0,0,0,0,0,0,0,0,0,0,0,0,127,0,0,0,0,0,0,0,0,0,0
0,0,0,0,0,0,0,0,127,127,127,0,0,0,0,0,0,0,0,0,0,0,127,127,127,0,0,0,0,0,0,0,0,0
0,0,0,0,0,0,0,127,127,127,127,127,0,11,0,3,0,3,0,11,0,127,127,127,127,127,0,0,0,0,0,0,0,0
0,0,0,0,0,0,127,127,127,127,127,127,127,127,127,127,127,127,127,127,127,127,127,127,127,127,127,0,0,0,0,0,0,0
0,0,14,0,0,127,127,127,127,127,127,127,127,127,5,5,5,5,5,127,127,127,127,127,127,127,127,127,0,0,10,0,0,0
0,0,0,0,0,0,127,127,127,127,127,127,5,5,215,215,239,238,0,5,5,127,127,127,127,127,127,0,0,0,0,0,0,0
0,0,0,0,0,0,0,127,127,127,127,5,0,0,0,0,0,0,0,117,235,5,127,127,127,127,0,0,0,0,0,0,0,0
0,0,0,0,0,0,0,0,127,127,5,0,0,0,0,0,0,0,0,0,0,0,5,127,127,0,0,0,0,0,0,0,0,0
0,0,0,0,0,0,0,14,127,127,5,0,231,0,0,0,0,0,0,0,0,0,5,127,127,10,0,0,0,0,0,0,0,0
0,0,0,0,0,0,0,0,127,5,231,231,231,0,0,0,0,0,0,0,0,0,0,5,127,0,0,0,0,0,0,0,0,0
0,0,0,0,0,0,0,3,127,5,231,0,0,0,0,0,0,0,0,0,0,0,0,5,127,3,0,0,0,0,0,0,0,0
0,0,0,0,0,0,0,0,127,5,231,0,0,0,0,0,0,0,0,0,236,0,0,5,127,0,0,0,0,0,0,0,0,0
0,0,0,0,0,0,0,3,127,5,231,0,0,0,103,103,0,0,0,0,0,0,0,5,127,3,0,0,0,0,0,0,0,0
0,0,0,0,0,0,0,0,127,5,231,231,231,0,103,103,0,0,0,0,0,0,234,5,127,0,0,0,0,0,0,0,0,0
0,0,0,0,0,0,0,14,127,127,5,0,231,0,0,0,0,0,0,0,0,0,5,127,127,10,0,0,0,0,0,0,0,0
0,0,0,0,0,0,0,0,127,127,5,0,0,0,0,0,0,0,0,0,0,0,5,127,127,0,0,0,0,0,0,0,0,0
0,0,0,0,0,0,0,127,127,127,127,5,0,0,0,0,0,0,0,0,0,5,127,127,127,127,0,0,0,0,0,0,0,0
0,0,0,0,0,0,127,127,127,127,127,127,5,5,237,237,237,237,237,5,5,127,127,127,127,127,127,0,0,0,0,0,0,0
0,0,14,0,0,127,127,127,127,127,127,127,127,127,5,5,5,5,5,127,127,127,127,127,127,127,127,127,0,0,10,0,0,0
0,0,0,0,0,0,127,127,127,127,127,127,127,127,127,127,127,127,127,127,127,127,127,127,127,127,127,0,0,0,0,0,0,0
0,0,0,0,0,0,0,127,127,127,127,127,0,12,0,3,0,3,0,12,0,127,127,127,127,127,0,0,0,0,0,0,0,0
0,0,0,0,0,0,0,0,127,127,127,0,0,0,0,0,0,0,0,0,0,0,127,127,127,0,0,0,0,0,0,0,0,0
0,0,0,0,0,0,0,0,0,127,0,0,0,0,0,0,0,0,0,0,0,0,0,127,0,0,0,0,0,0,0,0,0,0
0,0,0,0,0,0,0,0,0,0,0,0,0,0,0,0,0,0,0,0,0,0,0,0,0,0,0,0,0,0,0,0,0,0
0,0,0,0,0,0,0,0,0,0,0,0,0,0,0,0,0,0,0,0,0,0,0,0,0,0,0,0,0,0,0,0,0,0
0,0,0,0,0,0,0,0,0,12,0,0,0,0,0,0,0,0,0,0,0,0,0,12,0,0,0,0,0,0,0,0,0,0
0,0,0,0,0,0,0,0,0,0,0,0,0,0,0,0,0,0,0,0,0,0,0,0,0,0,0,0,0,0,0,0,0,0
0,0,0,0,0,0,0,0,0,0,0,0,0,0,0,0,0,0,0,0,0,0,0,0,0,0,0,0,0,0,0,0,0,0
0,0,0,0,0,0,0,0,0,0,0,0,0,0,0,0,0,0,0,0,0,0,0,0,0,0,0,0,0,0,0,0,0,0
:endlayer
layer: 37
127,0,0,0,0,0,0,0,0,0,0,0,0,0,0,0,0,0,0,0,0,0,0,0,0,0,0,0,0,0,0,0,0,0
0,0,0,0,0,0,0,0,0,0,0,0,0,0,0,0,0,0,0,0,0,0,0,0,0,0,0,0,0,0,0,0,0,0
0,0,0,0,0,0,0,0,0,0,0,0,0,0,0,0,0,0,0,0,0,0,0,0,0,0,0,0,0,0,0,0,0,0
0,0,0,0,0,0,0,0,0,17,0,0,0,0,0,0,0,0,0,0,0,0,0,17,0,0,0,0,0,0,0,0,0,0
0,0,0,0,0,0,0,0,0,0,0,0,0,0,0,0,0,0,0,0,0,0,0,0,0,0,0,0,0,0,0,0,0,0
0,0,0,0,0,0,0,0,0,0,0,0,0,0,0,0,0,0,0,0,0,0,0,0,0,0,0,0,0,0,0,0,0,0
0,0,0,0,0,0,0,0,0,127,0,0,0,0,0,0,0,0,0,0,0,0,0,127,0,0,0,0,0,0,0,0,0,0
0,0,0,0,0,0,0,0,127,127,127,0,0,0,0,3,0,3,0,0,0,0,127,127,127,0,0,0,0,0,0,0,0,0
0,0,0,0,0,0,0,127,127,127,127,127,0,11,0,3,0,3,0,11,0,127,127,127,127,127,0,0,0,0,0,0,0,0
0,0,0,19,0,0,127,127,127,127,127,127,127,127,5,5,5,5,5,127,127,127,127,127,127,127,127,0,0,18,0,0,0,0
0,0,0,0,0,0,0,127,127,127,127,127,5,5,241,240,0,0,0,5,5,127,127,127,127,127,0,0,0,0,0,0,0,0
0,0,0,0,0,0,0,0,127,127,127,5,0,0,0,0,0,0,0,0,0,5,127,127,127,0,0,0,0,0,0,0,0,0
0,0,0,0,0,0,0,0,0,127,5,0,0,0,0,0,0,0,0,0,0,0,5,127,0,0,0,0,0,0,0,0,0,0
0,0,0,0,0,0,0,0,14,127,5,0,0,0,0,0,0,0,0,0,0,0,5,127,10,0,0,0,0,0,0,0,0,0
0,0,0,0,0,0,0,0,0,5,231,231,231,0,0,0,0,0,0,0,0,0,0,5,0,0,0,0,0,0,0,0,0,0
0,0,0,0,0,0,0,3,3,5,231,0,0,0,0,0,0,0,0,0,0,0,0,5,3,3,0,0,0,0,0,0,0,0
0,0,0,0,0,0,0,0,0,5,231,0,0,0,103,103,0,0,0,0,0,0,0,5,0,0,0,0,0,0,0,0,0,0
0,0,0,0,0,0,0,3,3,5,231,0,0,0,0,0,0,0,0,0,0,0,0,5,3,3,0,0,0,0,0,0,0,0
0,0,0,0,0,0,0,0,0,5,231,231,231,0,0,0,0,0,0,0,0,0,0,5,0,0,0,0,0,0,0,0,0,0
0,0,0,0,0,0,0,0,14,127,5,0,0,0,0,0,0,0,0,0,0,0,5,127,10,0,0,0,0,0,0,0,0,0
0,0,0,0,0,0,0,0,0,127,5,0,0,0,0,0,0,0,0,0,0,0,5,127,0,0,0,0,0,0,0,0,0,0
0,0,0,0,0,0,0,0,127,127,127,5,0,0,0,0,0,0,0,0,0,5,127,127,127,0,0,0,0,0,0,0,0,0
0,0,0,0,0,0,0,127,127,127,127,127,5,5,0,0,0,0,0,5,5,127,127,127,127,127,0,0,0,0,0,0,0,0
0,0,0,19,0,0,127,127,127,127,127,127,127,127,5,5,5,5,5,127,127,127,127,127,127,127,127,0,0,18,0,0,0,0
0,0,0,0,0,0,0,127,127,127,127,127,0,12,0,3,0,3,0,12,0,127,127,127,127,127,0,0,0,0,0,0,0,0
0,0,0,0,0,0,0,0,127,127,127,0,0,0,0,3,0,3,0,0,0,0,127,127,127,0,0,0,0,0,0,0,0,0
0,0,0,0,0,0,0,0,0,127,0,0,0,0,0,0,0,0,0,0,0,0,0,127,0,0,0,0,0,0,0,0,0,0
0,0,0,0,0,0,0,0,0,0,0,0,0,0,0,0,0,0,0,0,0,0,0,0,0,0,0,0,0,0,0,0,0,0
0,0,0,0,0,0,0,0,0,0,0,0,0,0,0,0,0,0,0,0,0,0,0,0,0,0,0,0,0,0,0,0,0,0
0,0,0,0,0,0,0,0,0,16,0,0,0,0,0,0,0,0,0,0,0,0,0,16,0,0,0,0,0,0,0,0,0,0
0,0,0,0,0,0,0,0,0,0,0,0,0,0,0,0,0,0,0,0,0,0,0,0,0,0,0,0,0,0,0,0,0,0
0,0,0,0,0,0,0,0,0,0,0,0,0,0,0,0,0,0,0,0,0,0,0,0,0,0,0,0,0,0,0,0,0,0
0,0,0,0,0,0,0,0,0,0,0,0,0,0,0,0,0,0,0,0,0,0,0,0,0,0,0,0,0,0,0,0,0,0
0,0,0,0,0,0,0,0,0,0,0,0,0,0,0,0,0,0,0,0,0,0,0,0,0,0,0,0,0,0,0,0,0,0
:endlayer
layer: 38
127,0,0,0,0,0,0,0,0,0,0,0,0,0,0,0,0,0,0,0,0,0,0,0,0,0,0,0,0,0,0,0,0,0
0,0,0,0,0,0,0,0,0,0,0,0,0,0,0,0,0,0,0,0,0,0,0,0,0,0,0,0,0,0,0,0,0,0
0,0,0,0,0,0,0,0,0,0,0,0,0,0,0,0,0,0,0,0,0,0,0,0,0,0,0,0,0,0,0,0,0,0
0,0,0,0,0,0,0,0,0,0,0,0,0,0,0,0,0,0,0,0,0,0,0,0,0,0,0,0,0,0,0,0,0,0
0,0,0,0,0,0,0,0,0,0,0,0,0,0,0,0,0,0,0,0,0,0,0,0,0,0,0,0,0,0,0,0,0,0
0,0,0,0,0,0,0,0,0,0,0,0,0,0,0,0,0,0,0,0,0,0,0,0,0,0,0,0,0,0,0,0,0,0
0,0,0,0,0,0,0,0,0,0,0,0,0,0,0,0,0,0,0,0,0,0,0,0,0,0,0,0,0,0,0,0,0,0
0,0,0,0,0,0,0,0,0,127,0,0,0,0,0,3,0,3,0,0,0,0,0,127,0,0,0,0,0,0,0,0,0,0
0,0,0,0,0,0,0,0,127,127,127,0,0,0,0,3,0,3,0,0,0,0,127,127,127,0,0,0,0,0,0,0,0,0
0,0,0,0,0,0,0,127,127,127,127,127,0,11,5,5,5,5,5,11,0,127,127,127,127,127,0,0,0,0,0,0,0,0
0,0,0,0,0,0,0,0,127,127,127,127,5,5,0,0,0,0,0,5,5,127,127,127,127,0,0,0,0,0,0,0,0,0
0,0,0,0,0,0,0,0,0,127,127,5,0,0,0,0,0,0,0,0,0,5,127,127,0,0,0,0,0,0,0,0,0,0
0,0,0,0,0,0,0,0,0,0,5,0,0,0,0,0,0,0,0,0,0,0,5,0,0,0,0,0,0,0,0,0,0,0
0,0,0,0,0,0,0,0,0,14,5,0,0,0,0,0,0,0,0,0,0,0,5,10,0,0,0,0,0,0,0,0,0,0
0,0,0,0,0,0,0,0,0,5,231,0,242,0,103,103,0,0,0,0,0,0,0,5,0,0,0,0,0,0,0,0,0,0
0,0,0,0,0,0,0,3,3,5,231,0,0,0,103,103,0,0,0,0,0,0,0,5,3,3,0,0,0,0,0,0,0,0
0,0,0,0,0,0,0,0,0,5,231,0,0,0,0,0,0,0,0,0,0,0,0,5,0,0,0,0,0,0,0,0,0,0
0,0,0,0,0,0,0,3,3,5,231,0,0,0,0,0,0,0,0,0,0,0,0,5,3,3,0,0,0,0,0,0,0,0
0,0,0,0,0,0,0,0,0,5,231,0,243,0,0,0,0,0,0,0,0,0,0,5,0,0,0,0,0,0,0,0,0,0
0,0,0,0,0,0,0,0,0,14,5,0,0,0,0,0,0,0,0,0,0,0,5,10,0,0,0,0,0,0,0,0,0,0
0,0,0,0,0,0,0,0,0,0,5,0,0,0,0,0,0,0,0,0,0,0,5,0,0,0,0,0,0,0,0,0,0,0
0,0,0,0,0,0,0,0,0,127,127,5,0,0,0,0,0,0,0,0,0,5,127,127,0,0,0,0,0,0,0,0,0,0
0,0,0,0,0,0,0,0,127,127,127,127,5,5,0,0,0,0,0,5,5,127,127,127,127,0,0,0,0,0,0,0,0,0
0,0,0,0,0,0,0,127,127,127,127,127,0,12,5,5,5,5,5,12,0,127,127,127,127,127,0,0,0,0,0,0,0,0
0,0,0,0,0,0,0,0,127,127,127,0,0,0,0,3,0,3,0,0,0,0,127,127,127,0,0,0,0,0,0,0,0,0
0,0,0,0,0,0,0,0,0,127,0,0,0,0,0,3,0,3,0,0,0,0,0,127,0,0,0,0,0,0,0,0,0,0
0,0,0,0,0,0,0,0,0,0,0,0,0,0,0,0,0,0,0,0,0,0,0,0,0,0,0,0,0,0,0,0,0,0
0,0,0,0,0,0,0,0,0,0,0,0,0,0,0,0,0,0,0,0,0,0,0,0,0,0,0,0,0,0,0,0,0,0
0,0,0,0,0,0,0,0,0,0,0,0,0,0,0,0,0,0,0,0,0,0,0,0,0,0,0,0,0,0,0,0,0,0
0,0,0,0,0,0,0,0,0,0,0,0,0,0,0,0,0,0,0,0,0,0,0,0,0,0,0,0,0,0,0,0,0,0
0,0,0,0,0,0,0,0,0,0,0,0,0,0,0,0,0,0,0,0,0,0,0,0,0,0,0,0,0,0,0,0,0,0
0,0,0,0,0,0,0,0,0,0,0,0,0,0,0,0,0,0,0,0,0,0,0,0,0,0,0,0,0,0,0,0,0,0
0,0,0,0,0,0,0,0,0,0,0,0,0,0,0,0,0,0,0,0,0,0,0,0,0,0,0,0,0,0,0,0,0,0
0,0,0,0,0,0,0,0,0,0,0,0,0,0,0,0,0,0,0,0,0,0,0,0,0,0,0,0,0,0,0,0,0,0
:endlayer
layer: 39
127,0,0,0,0,0,0,0,0,0,0,0,0,0,0,0,0,0,0,0,0,0,0,0,0,0,0,0,0,0,0,0,0,0
0,0,0,0,0,0,0,0,0,0,0,0,0,0,0,0,0,0,0,0,0,0,0,0,0,0,0,0,0,0,0,0,0,0
0,0,0,0,0,0,0,0,0,0,0,0,0,0,0,0,0,0,0,0,0,0,0,0,0,0,0,0,0,0,0,0,0,0
0,0,0,0,0,0,0,0,0,0,0,0,0,0,0,0,0,0,0,0,0,0,0,0,0,0,0,0,0,0,0,0,0,0
0,0,0,0,0,0,0,0,0,0,0,0,0,0,0,0,0,0,0,0,0,0,0,0,0,0,0,0,0,0,0,0,0,0
0,0,0,0,0,0,0,0,0,0,0,0,0,0,0,0,0,0,0,0,0,0,0,0,0,0,0,0,0,0,0,0,0,0
0,0,0,0,0,0,0,0,0,0,0,0,0,0,0,0,0,0,0,0,0,0,0,0,0,0,0,0,0,0,0,0,0,0
0,0,0,0,0,0,0,0,0,0,0,0,0,0,0,3,0,3,0,0,0,0,0,0,0,0,0,0,0,0,0,0,0,0
0,0,0,0,0,0,0,0,0,0,0,0,0,0,0,3,0,3,0,0,0,0,0,0,0,0,0,0,0,0,0,0,0,0
0,0,0,0,0,0,0,0,0,0,0,0,0,16,5,5,5,5,5,16,0,0,0,0,0,0,0,0,0,0,0,0,0,0
0,0,0,0,0,0,0,0,0,0,0,0,5,5,0,0,0,0,0,5,5,0,0,0,0,0,0,0,0,0,0,0,0,0
0,0,0,0,0,0,0,0,0,0,0,5,0,0,0,0,0,0,0,0,0,5,0,0,0,0,0,0,0,0,0,0,0,0
0,0,0,0,0,0,0,0,0,0,5,0,0,0,0,0,0,0,0,0,0,0,5,0,0,0,0,0,0,0,0,0,0,0
0,0,0,0,0,0,0,0,0,18,5,0,0,0,0,0,0,0,0,0,0,0,5,19,0,0,0,0,0,0,0,0,0,0
0,0,0,0,0,0,0,0,0,5,0,0,0,0,0,0,103,0,0,0,0,0,0,5,0,0,0,0,0,0,0,0,0,0
0,0,0,0,0,0,0,3,3,5,0,0,0,0,0,0,103,0,0,0,0,0,0,5,3,3,0,0,0,0,0,0,0,0
0,0,0,0,0,0,0,0,0,5,0,0,0,0,0,0,0,0,0,0,0,0,0,5,0,0,0,0,0,0,0,0,0,0
